Workbook

Sheet Resumen
A1: Rootflow Hydroponics, S.L. — Información para la solicitud ENISA
A2: Proveedores, clientes y facturación real, y pipeline comercial. Datos del ERP de la empresa a 07/10/2026.
A4: 1 · FACTURACIÓN REAL (desde el inicio de la actividad hasta hoy)
A5: Facturado y vendido (base imponible, sin IVA) | B5: =Clientes!$F$12 -> 1924.72 | C5: Facturas emitidas + tickets de venta directa
A6: Facturado y vendido (IVA incluido) | B6: =Clientes!$G$12 -> 2001.72
A7: Cobrado | B7: =Clientes!$H$12 -> 1969.06
A8: Pendiente de cobro | B8: =Clientes!$I$12 -> 32.66
A9: Entregado pendiente de facturar (base) | B9: =Clientes!$J$12 -> 279.2 | C9: Se factura en octubre
A10: Clientes que ya han comprado (sin contar la venta directa) | B10: =COUNTA(Clientes!$A$5:$A$11)-1 -> 6
A11: Entregas realizadas | B11: =Clientes!$E$12 -> 27 | C11: Incluye 5 tickets de venta directa
A13: Ventas por mes de entrega (base imponible) | B13: Facturado | C13: Entregado pendiente de facturar
A14: Mayo 2026 | B14: =SUMIFS('Ventas detalle'!$G$5:$G$19,'Ventas detalle'!$E$5:$E$19,"2026-05",'Ventas detalle'!$F$5:$F$19,"Factura")+SUMIFS('Ventas detalle'!$G$5:$G$19,'Ventas detalle'!$E$5:$E$19,"2026-05",'Ventas detalle'!$F$5:$F$19,"Ticket") -> 4.81 | C14: =SUMIFS('Ventas detalle'!$G$5:$G$19,'Ventas detalle'!$E$5:$E$19,"2026-05",'Ventas detalle'!$F$5:$F$19,"Entregado, pendiente de facturar") -> 0
A15: Junio 2026 | B15: =SUMIFS('Ventas detalle'!$G$5:$G$19,'Ventas detalle'!$E$5:$E$19,"2026-06",'Ventas detalle'!$F$5:$F$19,"Factura")+SUMIFS('Ventas detalle'!$G$5:$G$19,'Ventas detalle'!$E$5:$E$19,"2026-06",'Ventas detalle'!$F$5:$F$19,"Ticket") -> 619.6 | C15: =SUMIFS('Ventas detalle'!$G$5:$G$19,'Ventas detalle'!$E$5:$E$19,"2026-06",'Ventas detalle'!$F$5:$F$19,"Entregado, pendiente de facturar") -> 0
A16: Julio 2026 | B16: =SUMIFS('Ventas detalle'!$G$5:$G$19,'Ventas detalle'!$E$5:$E$19,"2026-07",'Ventas detalle'!$F$5:$F$19,"Factura")+SUMIFS('Ventas detalle'!$G$5:$G$19,'Ventas detalle'!$E$5:$E$19,"2026-07",'Ventas detalle'!$F$5:$F$19,"Ticket") -> 350.4 | C16: =SUMIFS('Ventas detalle'!$G$5:$G$19,'Ventas detalle'!$E$5:$E$19,"2026-07",'Ventas detalle'!$F$5:$F$19,"Entregado, pendiente de facturar") -> 0
A17: Agosto 2026 (producción parada) | B17: =SUMIFS('Ventas detalle'!$G$5:$G$19,'Ventas detalle'!$E$5:$E$19,"2026-08",'Ventas detalle'!$F$5:$F$19,"Factura")+SUMIFS('Ventas detalle'!$G$5:$G$19,'Ventas detalle'!$E$5:$E$19,"2026-08",'Ventas detalle'!$F$5:$F$19,"Ticket") -> 0 | C17: =SUMIFS('Ventas detalle'!$G$5:$G$19,'Ventas detalle'!$E$5:$E$19,"2026-08",'Ventas detalle'!$F$5:$F$19,"Entregado, pendiente de facturar") -> 0
A18: Septiembre 2026 | B18: =SUMIFS('Ventas detalle'!$G$5:$G$19,'Ventas detalle'!$E$5:$E$19,"2026-09",'Ventas detalle'!$F$5:$F$19,"Factura")+SUMIFS('Ventas detalle'!$G$5:$G$19,'Ventas detalle'!$E$5:$E$19,"2026-09",'Ventas detalle'!$F$5:$F$19,"Ticket") -> 899.76 | C18: =SUMIFS('Ventas detalle'!$G$5:$G$19,'Ventas detalle'!$E$5:$E$19,"2026-09",'Ventas detalle'!$F$5:$F$19,"Entregado, pendiente de facturar") -> 124.2
A19: Octubre 2026 (hasta el día 7) | B19: =SUMIFS('Ventas detalle'!$G$5:$G$19,'Ventas detalle'!$E$5:$E$19,"2026-10",'Ventas detalle'!$F$5:$F$19,"Factura")+SUMIFS('Ventas detalle'!$G$5:$G$19,'Ventas detalle'!$E$5:$E$19,"2026-10",'Ventas detalle'!$F$5:$F$19,"Ticket") -> 50.15 | C19: =SUMIFS('Ventas detalle'!$G$5:$G$19,'Ventas detalle'!$E$5:$E$19,"2026-10",'Ventas detalle'!$F$5:$F$19,"Entregado, pendiente de facturar") -> 155
A20: Total | B20: =SUM(B14:B19) -> 1924.72 | C20: =SUM(C14:C19) -> 279.2
A22: 2 · PROVEEDORES
A23: Compras registradas desde la constitución (IVA incluido) | B23: =Proveedores!$G$35 -> 11752.72 | C23: Incluye el equipamiento del local actual y la constitución de la sociedad
A24: Semilla: MP Seeds (Łódź, Polonia) · Sustrato: Organic Growshop (Madrid) · Envases: Envases del Mediterráneo (Murcia)
A25: Sistema de cultivo: Leroy Merlin, Plases Grow Shop, Green Ice, LEDBOX · Gestión: ERP propio
A27: 3 · PIPELINE COMERCIAL
A28: Oportunidades abiertas en el CRM (restaurantes, tiendas y distribuidores) | B28: =COUNTA('Pipeline restaurantes'!$B$5:$B$42) -> 38 | C28: Hoja «Pipeline restaurantes»
A29: · de ellas, en negociación o con interés confirmado | B29: =COUNTIF('Pipeline restaurantes'!$E$5:$E$42,"Negociando")+COUNTIF('Pipeline restaurantes'!$E$5:$E$42,"Interesado")+COUNTIF('Pipeline restaurantes'!$E$5:$E$42,"Acuerdo sin pedido") -> 10
A30: Cuentas de distribución identificadas en el plan financiero | B30: =COUNTA('Pipeline distribución'!$A$5:$A$10) -> 6 | C30: Hoja «Pipeline distribución»
A31: Ingreso ponderado de esas cuentas a régimen (€/mes) | B31: ='Pipeline distribución'!$H$11 -> 32131.275
A33: Hojas: Clientes · Ventas detalle · Proveedores · Pipeline restaurantes · Pipeline distribución.

Sheet Proveedores
A1: Rootflow Hydroponics — Proveedores y servicios
A2: Datos del ERP a 07/10/2026. Importe acumulado = suma de las compras registradas, IVA incluido. No incluye impuestos ni cuotas de la Seguridad Social.
A4: Categoría | B4: Proveedor | C4: Razón social / ubicación | D4: Qué suministra | E4: Relación | F4: Nº de compras | G4: Importe acumulado (IVA incl.) | H4: Primera compra | I4: Última compra
A5: Semillas | B5: MP Seeds | C5: HYDRO Mateusz Przybiński · Łódź (Polonia) | D5: Semilla para microbrotes: cilantro, albahaca, rábano daikon y rojo, amaranto, brócoli, rúcula | E5: Recurrente · principal | F5: 4 | G5: 993.23 | H5: 46162 | I5: 46296
A6: Sustrato | B6: Organic Growshop | C6: Organik Green Zone, S.L. · Madrid | D6: Sustrato de fibra de coco (Atami, sacos de 100 L) | E6: Recurrente · principal | F6: 3 | G6: 218 | H6: 46161 | I6: 46287
A7: Envases y etiquetado | B7: Envases del Mediterráneo | C7: San Ginés (Murcia) | D7: Tarrinas de PET con bisagra para los formatos de 30 g | E7: Recurrente · principal | F7: 3 | G7: 376.12 | H7: 46157 | I7: 46253
A8: Envases y etiquetado | B8: Envanature | C8: Tecnopacking, S.L.U. · Onda (Castellón) | D8: Tarrinas de 150 y 250 cc | E8: Puntual | F8: 1 | G8: 142.46 | H8: 46122 | I8: 46122
A9: Envases y etiquetado | B9: Amazon Business | C9: — | D9: Etiquetas térmicas, pegatinas y consumibles de impresora | E9: Recurrente | F9: 4 | G9: 54.27 | H9: 46146 | I9: 46187
A10: Envases y etiquetado | B10: 360imprimir | C10: — | D10: Etiquetas frontales impresas | E10: Puntual | F10: 1 | G10: 28.85 | H10: 46162 | I10: 46162
A11: Sistema de cultivo | B11: Green Ice | C11: Green Ice, S.L. · Toledo | D11: Luminarias LED T5 de cultivo | E11: Puntual (equipamiento) | F11: 1 | G11: 203.44 | H11: 46168 | I11: 46168
A12: Sistema de cultivo | B12: LEDBOX | C12: Salamanca | D12: Conectores y material de iluminación LED | E12: Puntual (equipamiento) | F12: 1 | G12: 78.1 | H12: 46174 | I12: 46174
A13: Sistema de cultivo | B13: AliExpress | C13: — | D13: Luces LED y conectores | E13: Puntual (equipamiento) | F13: 4 | G13: 328.72 | H13: 46121 | I13: 46149
A14: Sistema de cultivo | B14: Plases Grow Shop | C14: Plases Internacional 2020, S.L.U. · Yuncos (Toledo) | D14: Mesas de cultivo de 100 × 110 cm (bandejas de inundación) | E14: Puntual (equipamiento) | F14: 1 | G14: 116 | H14: 46164 | I14: 46164
A15: Sistema de cultivo | B15: Leroy Merlin | C15: — | D15: Estanterías, tubería, bomba y material de riego, sensores de temperatura y humedad | E15: Recurrente (equipamiento) | F15: 15 | G15: 1226.64 | H15: 46095 | I15: 46279
A16: Sistema de cultivo | B16: FYMALSA | C16: Las Rozas (Madrid) | D16: Material eléctrico y de riego | E16: Puntual (equipamiento) | F16: 1 | G16: 38.43 | H16: 46182 | I16: 46182
... A18: Sistema de cultivo | B18: Cash Converters | C18: — | D18: Impresora de etiquetas (segunda mano) | E18: Puntual (equipamiento) | F18: 1 | G18: 99.95 | H18: 46137 | I18: 46137
A19: Sistema de gestión | B19: ERP propio | C19: Desarrollo interno | D19: Pedidos, producción y trazabilidad por lote, albaranes y facturación (React + Supabase) | E19: Propio · sin coste de licencia
A20: Sistema de gestión | B20: Anthropic (Claude) | C20: — | D20: Herramienta de IA para el desarrollo del ERP propio | E20: Mensual | F20: 26 | G20: 223 | H20: 46119 | I20: 46292
A21: Local | B21: Bellbro Renting and Development | C21: Bellbro Renting and Development, S.L. · Las Rozas (Madrid) | D21: Arrendador del local de producción (alquiler, luz y agua repercutidas, tasa de basura) | E21: Mensual | F21: 13 | G21: 4174.32 | H21: 46087 | I21: 46295
A22: Local | B22: Inmobiliaria MBlanco | C22: — | D22: Honorarios de intermediación del alquiler | E22: Puntual | F22: 1 | G22: 635.25 | H22: 46147 | I22: 46147
A23: Servicios profesionales | B23: Ayuda-T Soluciones Profesionales | C23: Ayuda-T Soluciones Profesionales, S.L. | D23: Asesoría y gestoría | E23: Mensual | F23: 3 | G23: 446.49 | H23: 46142 | I23: 46178
A24: Servicios profesionales | B24: Ortega y del Río Notarios | C24: Ortega y del Río Notarios, C.B. | D24: Notaría (constitución de la sociedad) | E24: Puntual | F24: 5 | G24: 910.82 | H24: 46100 | I24: 46100
A25: Servicios profesionales | B25: FNMT-RCM | C25: — | D25: Certificado digital de la sociedad | E25: Puntual | F25: 1 | G25: 15.98 | H25: 46169 | I25: 46169
A26: Servicios profesionales | B26: Registro de la Propiedad | C26: — | D26: Certificado registral | E26: Puntual | F26: 1 | G26: 34.18 | H26: 46155 | I26: 46155
A27: Comunicaciones | B27: Finetwork | C27: WEWI Mobile, S.L. | D27: Fibra y telefonía móvil | E27: Mensual | F27: 5 | G27: 100.46 | H27: 46143 | I27: 46286
A28: Comunicaciones | B28: IONOS | C28: — | D28: Dominio y web | E28: Mensual | F28: 3 | G28: 3.63 | H28: 46021 | I28: 46082
A29: Marketing | B29: Vistaprint | C29: Vistaprint B.V. | D29: Tarjetas de visita | E29: Puntual | F29: 1 | G29: 104.96 | H29: 46119 | I29: 46119
A30: Otros | B30: Fronda | C30: Fronda Centros de Jardinería, S.L. · Majadahonda (Madrid) | D30: Brotes de cilantro (compra puntual de producto, junio 2026) | E30: Puntual | F30: 1 | G30: 104.83 | H30: 46200 | I30: 46200
A31: Otros | B31: DIA | C31: — | D31: Productos de limpieza | E31: Puntual | F31: 1 | G31: 18.93 | H31: 46121 | I31: 46121
... A33: Otros | B33: Compras menores sin proveedor identificado | C33: — | D33: Material de segunda mano (cubetas, nevera, cortadora), ferretería, utensilios y teléfono de empresa | E33: Puntual | F33: 22 | G33: 709.71 | H33: 46108 | I33: 46174
B35: TOTAL COMPRAS REGISTRADAS | F35: =SUM(F5:F33) -> 125 | G35: =SUM(G5:G33) -> 11752.72
A37: Proveedores principales de la producción: MP Seeds (semilla), Organic Growshop (sustrato) y Envases del Mediterráneo (tarrinas). El sistema de cultivo (estanterías, mesas de inundación, iluminación LED y riego) se ha montado con compras de equipamiento; la gestión va sobre un ERP propio.

Sheet Clientes
A1: Rootflow Hydroponics — Clientes y facturación real
A2: Datos del ERP a 07/10/2026. Base imponible sin IVA; el detalle de cada factura está en la hoja «Ventas detalle».
A4: Cliente | B4: Canal | C4: Alta como cliente | D4: Primera entrega | E4: Nº de entregas | F4: Facturado (base) | G4: Facturado (IVA incl.) | H4: Cobrado | I4: Pendiente de cobro | J4: Entregado pendiente de facturar | K4: Observaciones
A5: La Huerta Hermanos Nieto, S.L. | B5: Mayorista / frutería (Mercamadrid) | C5: 46174 | D5: 46187 | E5: 14 | F5: =SUMIFS('Ventas detalle'!$G$5:$G$19,'Ventas detalle'!$C$5:$C$19,$A5,'Ventas detalle'!$F$5:$F$19,"Factura")+SUMIFS('Ventas detalle'!$G$5:$G$19,'Ventas detalle'!$C$5:$C$19,$A5,'Ventas detalle'!$F$5:$F$19,"Ticket") -> 1609.7 | G5: =SUMIFS('Ventas detalle'!$I$5:$I$19,'Ventas detalle'!$C$5:$C$19,$A5,'Ventas detalle'!$F$5:$F$19,"Factura")+SUMIFS('Ventas detalle'!$I$5:$I$19,'Ventas detalle'!$C$5:$C$19,$A5,'Ventas detalle'!$F$5:$F$19,"Ticket") -> 1674.09 | H5: =SUMIFS('Ventas detalle'!$I$5:$I$19,'Ventas detalle'!$C$5:$C$19,$A5,'Ventas detalle'!$J$5:$J$19,"Cobrada") -> 1674.09 | I5: =SUMIFS('Ventas detalle'!$I$5:$I$19,'Ventas detalle'!$C$5:$C$19,$A5,'Ventas detalle'!$J$5:$J$19,"Pendiente") -> 0 | J5: =SUMIFS('Ventas detalle'!$G$5:$G$19,'Ventas detalle'!$C$5:$C$19,$A5,'Ventas detalle'!$F$5:$F$19,"Entregado, pendiente de facturar") -> 155 | K5: Pedido semanal: ~60 tarrinas de 30 g (cilantro y albahaca). Facturación mensual.
A6: Frutas Félix Vázquez, S.L. | B6: Frutería | C6: 46270 | D6: 46270 | E6: 4 | F6: =SUMIFS('Ventas detalle'!$G$5:$G$19,'Ventas detalle'!$C$5:$C$19,$A6,'Ventas detalle'!$F$5:$F$19,"Factura")+SUMIFS('Ventas detalle'!$G$5:$G$19,'Ventas detalle'!$C$5:$C$19,$A6,'Ventas detalle'!$F$5:$F$19,"Ticket") -> 189.5 | G6: =SUMIFS('Ventas detalle'!$I$5:$I$19,'Ventas detalle'!$C$5:$C$19,$A6,'Ventas detalle'!$F$5:$F$19,"Factura")+SUMIFS('Ventas detalle'!$I$5:$I$19,'Ventas detalle'!$C$5:$C$19,$A6,'Ventas detalle'!$F$5:$F$19,"Ticket") -> 197.08 | H6: =SUMIFS('Ventas detalle'!$I$5:$I$19,'Ventas detalle'!$C$5:$C$19,$A6,'Ventas detalle'!$J$5:$J$19,"Cobrada") -> 197.08 | I6: =SUMIFS('Ventas detalle'!$I$5:$I$19,'Ventas detalle'!$C$5:$C$19,$A6,'Ventas detalle'!$J$5:$J$19,"Pendiente") -> 0 | J6: =SUMIFS('Ventas detalle'!$G$5:$G$19,'Ventas detalle'!$C$5:$C$19,$A6,'Ventas detalle'!$F$5:$F$19,"Entregado, pendiente de facturar") -> 0 | K6: Pedido semanal desde septiembre, surtido de variedades.
A7: Albahaca Ecotienda | B7: Tienda ecológica | C7: 46174 | D7: 46268 | E7: 1 | F7: =SUMIFS('Ventas detalle'!$G$5:$G$19,'Ventas detalle'!$C$5:$C$19,$A7,'Ventas detalle'!$F$5:$F$19,"Factura")+SUMIFS('Ventas detalle'!$G$5:$G$19,'Ventas detalle'!$C$5:$C$19,$A7,'Ventas detalle'!$F$5:$F$19,"Ticket") -> 48.45 | G7: =SUMIFS('Ventas detalle'!$I$5:$I$19,'Ventas detalle'!$C$5:$C$19,$A7,'Ventas detalle'!$F$5:$F$19,"Factura")+SUMIFS('Ventas detalle'!$I$5:$I$19,'Ventas detalle'!$C$5:$C$19,$A7,'Ventas detalle'!$F$5:$F$19,"Ticket") -> 50.39 | H7: =SUMIFS('Ventas detalle'!$I$5:$I$19,'Ventas detalle'!$C$5:$C$19,$A7,'Ventas detalle'!$J$5:$J$19,"Cobrada") -> 50.39 | I7: =SUMIFS('Ventas detalle'!$I$5:$I$19,'Ventas detalle'!$C$5:$C$19,$A7,'Ventas detalle'!$J$5:$J$19,"Pendiente") -> 0 | J7: =SUMIFS('Ventas detalle'!$G$5:$G$19,'Ventas detalle'!$C$5:$C$19,$A7,'Ventas detalle'!$F$5:$F$19,"Entregado, pendiente de facturar") -> 0 | K7: Surtido de 8 variedades en formato de 15 g.
A8: El Abuelo Pedro | B8: Mayorista (Mercamadrid) | C8: 46270 | D8: 46272 | E8: 1 | F8: =SUMIFS('Ventas detalle'!$G$5:$G$19,'Ventas detalle'!$C$5:$C$19,$A8,'Ventas detalle'!$F$5:$F$19,"Factura")+SUMIFS('Ventas detalle'!$G$5:$G$19,'Ventas detalle'!$C$5:$C$19,$A8,'Ventas detalle'!$F$5:$F$19,"Ticket") -> 0 | G8: =SUMIFS('Ventas detalle'!$I$5:$I$19,'Ventas detalle'!$C$5:$C$19,$A8,'Ventas detalle'!$F$5:$F$19,"Factura")+SUMIFS('Ventas detalle'!$I$5:$I$19,'Ventas detalle'!$C$5:$C$19,$A8,'Ventas detalle'!$F$5:$F$19,"Ticket") -> 0 | H8: =SUMIFS('Ventas detalle'!$I$5:$I$19,'Ventas detalle'!$C$5:$C$19,$A8,'Ventas detalle'!$J$5:$J$19,"Cobrada") -> 0 | I8: =SUMIFS('Ventas detalle'!$I$5:$I$19,'Ventas detalle'!$C$5:$C$19,$A8,'Ventas detalle'!$J$5:$J$19,"Pendiente") -> 0 | J8: =SUMIFS('Ventas detalle'!$G$5:$G$19,'Ventas detalle'!$C$5:$C$19,$A8,'Ventas detalle'!$F$5:$F$19,"Entregado, pendiente de facturar") -> 124.2 | K8: Puesto en Mercamadrid. Primera entrega pendiente de facturar.
A9: Tequendama | B9: Restaurante | C9: 46286 | D9: 46301 | E9: 1 | F9: =SUMIFS('Ventas detalle'!$G$5:$G$19,'Ventas detalle'!$C$5:$C$19,$A9,'Ventas detalle'!$F$5:$F$19,"Factura")+SUMIFS('Ventas detalle'!$G$5:$G$19,'Ventas detalle'!$C$5:$C$19,$A9,'Ventas detalle'!$F$5:$F$19,"Ticket") -> 31.4 | G9: =SUMIFS('Ventas detalle'!$I$5:$I$19,'Ventas detalle'!$C$5:$C$19,$A9,'Ventas detalle'!$F$5:$F$19,"Factura")+SUMIFS('Ventas detalle'!$I$5:$I$19,'Ventas detalle'!$C$5:$C$19,$A9,'Ventas detalle'!$F$5:$F$19,"Ticket") -> 32.66 | H9: =SUMIFS('Ventas detalle'!$I$5:$I$19,'Ventas detalle'!$C$5:$C$19,$A9,'Ventas detalle'!$J$5:$J$19,"Cobrada") -> 0 | I9: =SUMIFS('Ventas detalle'!$I$5:$I$19,'Ventas detalle'!$C$5:$C$19,$A9,'Ventas detalle'!$J$5:$J$19,"Pendiente") -> 32.66 | J9: =SUMIFS('Ventas detalle'!$G$5:$G$19,'Ventas detalle'!$C$5:$C$19,$A9,'Ventas detalle'!$F$5:$F$19,"Entregado, pendiente de facturar") -> 0 | K9: Primer pedido (evento).
A10: Café El Padrino, S.L. | B10: Restaurante / cafetería | C10: 46272 | D10: 46296 | E10: 1 | F10: =SUMIFS('Ventas detalle'!$G$5:$G$19,'Ventas detalle'!$C$5:$C$19,$A10,'Ventas detalle'!$F$5:$F$19,"Factura")+SUMIFS('Ventas detalle'!$G$5:$G$19,'Ventas detalle'!$C$5:$C$19,$A10,'Ventas detalle'!$F$5:$F$19,"Ticket") -> 10.1 | G10: =SUMIFS('Ventas detalle'!$I$5:$I$19,'Ventas detalle'!$C$5:$C$19,$A10,'Ventas detalle'!$F$5:$F$19,"Factura")+SUMIFS('Ventas detalle'!$I$5:$I$19,'Ventas detalle'!$C$5:$C$19,$A10,'Ventas detalle'!$F$5:$F$19,"Ticket") -> 10.5 | H10: =SUMIFS('Ventas detalle'!$I$5:$I$19,'Ventas detalle'!$C$5:$C$19,$A10,'Ventas detalle'!$J$5:$J$19,"Cobrada") -> 10.5 | I10: =SUMIFS('Ventas detalle'!$I$5:$I$19,'Ventas detalle'!$C$5:$C$19,$A10,'Ventas detalle'!$J$5:$J$19,"Pendiente") -> 0 | J10: =SUMIFS('Ventas detalle'!$G$5:$G$19,'Ventas detalle'!$C$5:$C$19,$A10,'Ventas detalle'!$F$5:$F$19,"Entregado, pendiente de facturar") -> 0 | K10: Primer pedido.
A11: Venta directa (particulares) | B11: Venta directa | D11: 46166 | E11: 5 | F11: =SUMIFS('Ventas detalle'!$G$5:$G$19,'Ventas detalle'!$C$5:$C$19,$A11,'Ventas detalle'!$F$5:$F$19,"Factura")+SUMIFS('Ventas detalle'!$G$5:$G$19,'Ventas detalle'!$C$5:$C$19,$A11,'Ventas detalle'!$F$5:$F$19,"Ticket") -> 35.57 | G11: =SUMIFS('Ventas detalle'!$I$5:$I$19,'Ventas detalle'!$C$5:$C$19,$A11,'Ventas detalle'!$F$5:$F$19,"Factura")+SUMIFS('Ventas detalle'!$I$5:$I$19,'Ventas detalle'!$C$5:$C$19,$A11,'Ventas detalle'!$F$5:$F$19,"Ticket") -> 37 | H11: =SUMIFS('Ventas detalle'!$I$5:$I$19,'Ventas detalle'!$C$5:$C$19,$A11,'Ventas detalle'!$J$5:$J$19,"Cobrada") -> 37 | I11: =SUMIFS('Ventas detalle'!$I$5:$I$19,'Ventas detalle'!$C$5:$C$19,$A11,'Ventas detalle'!$J$5:$J$19,"Pendiente") -> 0 | J11: =SUMIFS('Ventas detalle'!$G$5:$G$19,'Ventas detalle'!$C$5:$C$19,$A11,'Ventas detalle'!$F$5:$F$19,"Entregado, pendiente de facturar") -> 0 | K11: Ventas con tarjeta en el local (5 tickets).
A12: TOTAL | E12: =SUM(E5:E11) -> 27 | F12: =SUM(F5:F11) -> 1924.72 | G12: =SUM(G5:G11) -> 2001.72 | H12: =SUM(H5:H11) -> 1969.06 | I12: =SUM(I5:I11) -> 32.66 | J12: =SUM(J5:J11) -> 279.2
A15: CLIENTES DADOS DE ALTA, AÚN SIN PEDIDOS
A16: Cliente | B16: Canal | C16: Alta como cliente | K16: Situación
A17: Frutas Eloy Ruano, S.L. | B17: Mayorista (Mercamadrid) | C17: 46110 | K17: Cliente en el plan de distribución; sin pedidos todavía.
A18: Tatin Catering | B18: Catering | C18: 46272 | K18: Alta en septiembre; sin pedidos facturados todavía.
A19: La Fresquera del Gourmet | B19: Tienda gourmet / restauración | C19: 46272 | K19: Alta en septiembre; sin pedidos todavía.
A20: Tucosechaonline | B20: Tienda online | C20: 46302 | K20: Alta el 07/10/2026.

Sheet Ventas detalle
A1: Rootflow Hydroponics — Facturación real (detalle)
A2: Facturas emitidas, tickets de venta directa y entregas pendientes de facturar, según el ERP a 07/10/2026. Mes de entrega = mes en que se entregó el producto.
A4: Documento | B4: Fecha | C4: Cliente | D4: Canal | E4: Mes de entrega | F4: Tipo | G4: Base imponible | H4: IVA | I4: Total | J4: Estado de cobro | K4: Fecha de cobro
A5: F-2026-0001 | B5: 46203 | C5: La Huerta Hermanos Nieto, S.L. | D5: Mayorista / frutería (Mercamadrid) | E5: 2026-06 | F5: Factura | G5: 619.6 | H5: 24.78 | I5: =G5+H5 -> 644.38 | J5: Cobrada | K5: 46237
A6: F-2026-0002 | B6: 46224 | C6: La Huerta Hermanos Nieto, S.L. | D6: Mayorista / frutería (Mercamadrid) | E6: 2026-07 | F6: Factura | G6: 350.4 | H6: 14.02 | I6: =G6+H6 -> 364.42 | J6: Cobrada | K6: 46300
A7: F-2026-0003 | B7: 46255 | C7: Albahaca Ecotienda | D7: Tienda ecológica | E7: 2026-09 | F7: Factura | G7: 48.45 | H7: 1.94 | I7: =G7+H7 -> 50.39 | J7: Cobrada | K7: 46286
A8: F-2026-0009 | B8: 46279 | C8: Frutas Félix Vázquez, S.L. | D8: Frutería | E8: 2026-09 | F8: Factura | G8: 74.25 | H8: 2.97 | I8: =G8+H8 -> 77.22 | J8: Cobrada | K8: 46286
A9: F-2026-0010 | B9: 46293 | C9: La Huerta Hermanos Nieto, S.L. | D9: Mayorista / frutería (Mercamadrid) | E9: 2026-09 | F9: Factura | G9: 639.7 | H9: 25.59 | I9: =G9+H9 -> 665.29 | J9: Cobrada | K9: 46297
A10: F-2026-0011 | B10: 46294 | C10: Tequendama | D10: Restaurante | E10: 2026-10 | F10: Factura | G10: 31.4 | H10: 1.26 | I10: =G10+H10 -> 32.66 | J10: Pendiente
A11: F-2026-0014 | B11: 46296 | C11: Frutas Félix Vázquez, S.L. | D11: Frutería | E11: 2026-09 | F11: Factura | G11: 115.25 | H11: 4.61 | I11: =G11+H11 -> 119.86 | J11: Cobrada | K11: 46302
A12: F-2026-0015 | B12: 46297 | C12: Café El Padrino, S.L. | D12: Restaurante / cafetería | E12: 2026-10 | F12: Factura | G12: 10.1 | H12: 0.4 | I12: =G12+H12 -> 10.5 | J12: Cobrada | K12: 46301
A13: Ticket TPV | B13: 46166 | C13: Venta directa (particulares) | D13: Venta directa | E13: 2026-05 | F13: Ticket | G13: 4.81 | H13: 0.19 | I13: =G13+H13 -> 5 | J13: Cobrada | K13: 46166
A14: Ticket TPV | B14: 46280 | C14: Venta directa (particulares) | D14: Venta directa | E14: 2026-09 | F14: Ticket | G14: 4.81 | H14: 0.19 | I14: =G14+H14 -> 5 | J14: Cobrada | K14: 46280
A15: Ticket TPV | B15: 46281 | C15: Venta directa (particulares) | D15: Venta directa | E15: 2026-09 | F15: Ticket | G15: 8.65 | H15: 0.35 | I15: =G15+H15 -> 9 | J15: Cobrada | K15: 46281
A16: Ticket TPV | B16: 46289 | C16: Venta directa (particulares) | D16: Venta directa | E16: 2026-09 | F16: Ticket | G16: 8.65 | H16: 0.35 | I16: =G16+H16 -> 9 | J16: Cobrada | K16: 46289
A17: Ticket TPV | B17: 46296 | C17: Venta directa (particulares) | D17: Venta directa | E17: 2026-10 | F17: Ticket | G17: 8.65 | H17: 0.35 | I17: =G17+H17 -> 9 | J17: Cobrada | K17: 46296
A18: A-2026-0011 | B18: 46272 | C18: El Abuelo Pedro | D18: Mayorista (Mercamadrid) | E18: 2026-09 | F18: Entregado, pendiente de facturar | G18: 124.2 | H18: 4.97 | I18: =G18+H18 -> 129.17 | J18: —
A19: A-2026-0023 | B19: 46300 | C19: La Huerta Hermanos Nieto, S.L. | D19: Mayorista / frutería (Mercamadrid) | E19: 2026-10 | F19: Entregado, pendiente de facturar | G19: 155 | H19: 6.2 | I19: =G19+H19 -> 161.2 | J19: —
C21: TOTAL FACTURADO Y COBRADO EN CAJA (facturas + tickets) | G21: =SUMIFS(G5:G19,$F$5:$F$19,"Factura")+SUMIFS(G5:G19,$F$5:$F$19,"Ticket") -> 1924.72 | H21: =SUMIFS(H5:H19,$F$5:$F$19,"Factura")+SUMIFS(H5:H19,$F$5:$F$19,"Ticket") -> 77 | I21: =SUMIFS(I5:I19,$F$5:$F$19,"Factura")+SUMIFS(I5:I19,$F$5:$F$19,"Ticket") -> 2001.72
C22: Entregado pendiente de facturar | G22: =SUMIFS(G5:G19,$F$5:$F$19,"Entregado, pendiente de facturar") -> 279.2 | H22: =SUMIFS(H5:H19,$F$5:$F$19,"Entregado, pendiente de facturar") -> 11.17 | I22: =SUMIFS(I5:I19,$F$5:$F$19,"Entregado, pendiente de facturar") -> 290.37
C23: Pendiente de cobro (facturas emitidas) | I23: =SUMIFS(I5:I19,$J$5:$J$19,"Pendiente") -> 32.66
A25: Agosto sin ventas: parada de producción en verano.

Sheet Pipeline restaurantes
A1: Rootflow Hydroponics — Pipeline comercial: restaurantes, tiendas y distribuidores
A2: Oportunidades abiertas en el CRM del ERP a 07/10/2026. Etapa y última actividad según el CRM; la situación está resumida.
A4: # | B4: Cuenta | C4: Tipo | D4: Zona | E4: Etapa | F4: Prioridad | G4: Valor estimado (€) | H4: Última actividad | I4: Situación / próximo paso
A5: 1 | B5: Club Puerta de Hierro | C5: Restaurante | D5: Madrid | E5: Negociando | F5: Alta | G5: 299 | H5: 46282 | I5: Visita con muestras al equipo de cocina; pendiente de su valoración.
A6: 2 | B6: Restaurante De María | C6: Restaurante | D6: Madrid noroeste (Pozuelo, Majadahonda) | E6: Negociando | F6: Alta | H6: 46265 | I6: En negociación de condiciones.
A7: 3 | B7: Restaurante Jesús – AIME Ostras | C7: Restaurante | D7: Madrid | E7: Negociando | F7: Alta | H7: 46274 | I7: Pendiente de cerrar fecha con el chef para llevar muestras.
A8: 4 | B8: Sushita | C8: Grupo / cadena de restauración | D8: Madrid | E8: Interesado | F8: Alta | G8: 1000 | H8: 46269 | I8: Interesados; falta definir el punto de entrega para sus locales.
A9: 5 | B9: Chef Fruit | C9: Distribuidor / mayorista (Mercamadrid) | D9: Madrid | E9: Interesado | F9: Alta | H9: 46265 | I9: Están creando una sección de microbrotes; propuesta de acompañarles en el lanzamiento.
A10: 6 | B10: Fruotero | C10: Tienda / frutería (abastece a chefs) | D10: Madrid | E10: Interesado | F10: Media | H10: 46265 | I10: El producto gustó a los chefs a los que abastece; retomar tras la apertura de su nuevo local.
A11: 7 | B11: Tacos La 28 | C11: Restaurante | D11: Madrid | E11: Interesado | F11: Media | H11: 46272 | I11: Interesados; están abriendo un segundo local.
A12: 8 | B12: Grupo Sibuya | C12: Grupo / cadena de restauración | D12: Madrid | E12: Interesado | F12: Media | H12: 46272 | I12: Interesados; seguimiento en curso.
A13: 9 | B13: Faszina Selected | C13: Distribuidor / mayorista gourmet | D13: Barcelona (clientes en Madrid) | E13: Interesado | F13: Media | H13: 46258 | I13: Interés en servir a sus clientes de Madrid; pendiente de nuevo contacto.
A14: 10 | B14: Frutas Iberika | C14: Distribuidor / mayorista (Mercamadrid) | D14: Madrid | E14: Acuerdo sin pedido | F14: Media | G14: 50 | H14: 46268 | I14: Acuerdo para comprarnos lo que hoy venden (1-2 bandejas/semana de micromezcla, cilantro y guisante); sin pedido todavía.
A15: 11 | B15: Bidfood Iberia | C15: Distribuidor / mayorista de foodservice (Mercamadrid) | D15: Madrid | E15: Contactado | F15: Alta | G15: 2000 | H15: 46210 | I15: Propuesta enviada por email; pendiente de respuesta.
A16: 12 | B16: GoldGourmet | C16: Distribuidor / mayorista gourmet (Mercamadrid) | D16: Madrid | E16: Contactado | F16: Alta | H16: 46269 | I16: Interés en el modelo de venta en Mercamadrid; presentación a sus clientes el 14/09.
A17: 13 | B17: Doeat | C17: Restaurante | D17: Madrid | E17: Contactado | F17: Alta | G17: 300 | H17: 46268 | I17: Presentado al equipo de cocina con valoración positiva; pendiente de pedido.
A18: 14 | B18: Honest Greens | C18: Grupo / cadena de restauración | D18: Madrid | E18: Contactado | F18: Media | G18: 500 | H18: 46211 | I18: Propuesta enviada al canal de proveedores; pendiente de respuesta.
A19: 15 | B19: Grupo Oter | C19: Grupo / cadena de restauración | D19: Madrid | E19: Contactado | F19: Media | H19: 46259 | I19: Primer contacto; seguimiento telefónico.
A20: 16 | B20: El Supertomate | C20: Restaurante | D20: Madrid | E20: Contactado | F20: Baja | H20: 46259 | I20: Primer contacto realizado.
A21: 17 | B21: Georgánico | C21: Tienda / frutería ecológica | D21: Madrid | E21: Contactado | F21: Baja | I21: Solo compra producto con certificación ecológica.
A22: 18 | B22: Frutería Silvestre | C22: Tienda / frutería ecológica | D22: Madrid | E22: Contactado | F22: Baja | H22: 46258 | I22: Consumo muy reducido y solo ecológico.
A23: 19 | B23: Faborit | C23: Grupo / cadena de restauración (cafeterías) | D23: Madrid | E23: Nuevo | F23: Media | G23: 400 | H23: 46262 | I23: Sin respuesta todavía; insistir.
A24: 20 | B24: Cristina Oria | C24: Gourmet / catering | D24: Madrid | E24: Nuevo | F24: Media | G24: 100 | H24: 46265 | I24: Propuesta enviada por email.
A25: 21 | B25: Grupo La Fábrica | C25: Grupo / cadena de restauración | D25: Madrid | E25: Nuevo | F25: Media | H25: 46269 | I25: Prefieren el contacto por email; propuesta en curso.
A26: 22 | B26: Grupo Quispe | C26: Grupo / cadena de restauración | D26: Madrid | E26: Nuevo | F26: Media | H26: 46272 | I26: Contacto con la dirección a través de una referencia; pendiente de respuesta.
A27: 23 | B27: GLH | C27: Grupo / cadena de restauración | D27: Madrid | E27: Nuevo | F27: Media | I27: Pendiente de primer contacto para presentar el producto al grupo.
A28: 24 | B28: Grupo Mentidero | C28: Grupo / cadena de restauración | D28: Madrid | E28: Nuevo | F28: Media | I28: Pendiente de primer contacto.
A29: 25 | B29: La Lonja de Pozuelo | C29: Restaurante | D29: Madrid noroeste (Pozuelo, Majadahonda) | E29: Nuevo | F29: Baja | H29: 46265 | I29: Pendiente de contacto con el responsable de compras.
A30: 26 | B30: Taberna de Elia | C30: Restaurante | D30: Madrid noroeste (Pozuelo, Majadahonda) | E30: Nuevo | F30: Baja | H30: 46262 | I30: Responsable de compras identificado; llamar.
A31: 27 | B31: El Cielo de Urrechu | C31: Restaurante | D31: Madrid | E31: Nuevo | F31: Baja | H31: 46262 | I31: Responsables de compras identificados; llamar.
A32: 28 | B32: Vespok | C32: Restaurante | D32: Madrid | E32: Nuevo | F32: Baja | H32: 46272 | I32: Contacto identificado; llamar.
A33: 29 | B33: Bistec Boutique & Bar de Carnes | C33: Restaurante | D33: Madrid noroeste (Pozuelo, Majadahonda) | E33: Nuevo | F33: Baja | I33: Pendiente de primer contacto.
A34: 30 | B34: Paschi Cocina Peruana | C34: Restaurante | D34: Madrid noroeste (Pozuelo, Majadahonda) | E34: Nuevo | F34: Baja | G34: 50 | I34: Pendiente de primer contacto.
A35: 31 | B35: SUMO | C35: Restaurante | D35: Madrid | E35: Nuevo | F35: Baja | I35: Pendiente de primer contacto.
A36: 32 | B36: Nectarfruit | C36: Restaurante | D36: Madrid | E36: Nuevo | F36: Baja | I36: Pendiente de primer contacto.
A37: 33 | B37: Frutas Maricarmen | C37: Tienda / frutería | D37: Madrid | E37: Nuevo | F37: Baja | H37: 46269 | I37: Contacto identificado; llamar.
A38: 34 | B38: Vanfresh | C38: Tienda / frutería | D38: Madrid | E38: Nuevo | F38: Baja | I38: Pendiente de primer contacto.
A39: 35 | B39: Hnos. Delgado | C39: Tienda / frutería | D39: Madrid | E39: Nuevo | F39: Baja | I39: Pendiente de primer contacto.
A40: 36 | B40: Gemüsering | C40: Tienda / frutería | D40: Madrid | E40: Nuevo | F40: Baja | I40: Pendiente de primer contacto.
A41: 37 | B41: Madosa | C41: Tienda / frutería | D41: Madrid | E41: Nuevo | F41: Baja | I41: Pendiente de primer contacto.
...

Sheet Pipeline distribución
A1: Rootflow Hydroponics — Pipeline de distribución del plan financiero
A2: Cuentas identificadas en el modelo financiero V17 (hoja Pipeline), que alimentan la demanda de la línea de distribución, con su situación real en el ERP a 07/10/2026. Volúmenes a régimen, tras la rampa de cada cuenta.
A4: Cuenta | B4: Estado en el plan | C4: Probabilidad | D4: Mes de inicio (mes del plan) | E4: Rampa (meses) | F4: Tarrinas al mes | G4: Ingreso potencial (€/mes) | H4: Ingreso ponderado (€/mes) | I4: Situación real (ERP)
A5: La Huerta Hermanos Nieto (La Huerta de Aranjuez) | B5: Activo | C5: 0.95 | D5: 1 | E5: 3 | F5: 1305 | G5: 3262.5 | H5: =G5*C5 -> 3099.375 | I5: Cliente activo desde junio 2026: pedido semanal de ~60 tarrinas; 1.609,70 € facturados (base) a 07/10.
A6: Sushita | B6: En conversación | C6: 0.6 | D6: 2 | E6: 3 | F6: 130.5 | G6: 391.5 | H6: =G6*C6 -> 234.9 | I6: Oportunidad abierta (interesados); sin pedidos todavía.
A7: Frutas Eloy Ruano | B7: En conversación | C7: 0.85 | D7: 3 | E7: 8 | F7: 4350 | G7: 11310 | H7: =G7*C7 -> 9613.5 | I7: Dado de alta como cliente en marzo; sin pedidos todavía.
A8: Mercamadrid (asentadores) | B8: Por abrir | C8: 0.55 | D8: 6 | E8: 8 | F8: 4350 | G8: 10440 | H8: =G8*C8 -> 5742 | I8: Contactos abiertos: Chef Fruit, GoldGourmet, Frutas Iberika y Bidfood Iberia; El Abuelo Pedro ya es cliente.
A9: Makro (cash & carry) | B9: En conversación | C9: 0.25 | D9: 12 | E9: 10 | F9: 17400 | G9: 39150 | H9: =G9*C9 -> 9787.5 | I9: Sin actividad registrada en el CRM.
A10: Primaflor | B10: En conversación | C10: 0.2 | D10: 14 | E10: 10 | F10: 8700 | G10: 18270 | H10: =G10*C10 -> 3654 | I10: Sin actividad registrada en el CRM.
A11: TOTAL | F11: =SUM(F5:F10) -> 36235.5 | G11: =SUM(G5:G10) -> 82824 | H11: =SUM(H5:H10) -> 32131.275
A13: Probabilidad, mes de inicio, rampa y volúmenes: supuestos del modelo financiero V17 (escenario base). Los descuentos de canal (Mercamadrid 20 %, Makro 25 %, Primaflor 30 %) ya están aplicados en el ingreso potencial.
