Workbook

Sheet Resumen
A1: Rootflow Hydroponics, S.L. — Deuda actual
A2: Situación a 07/10/2026 según los registros de la empresa (ERP). Importes en euros.
A4: ¿Las aportaciones en efectivo de los socios son un préstamo a la sociedad? | B4: No | C4: «No» = aportaciones a fondos propios (cuenta 118), que no son deuda. «Sí» = préstamo de socios. Confirmar con la gestoría cómo están contabilizadas.
A6: 1 · DEUDA FINANCIERA CON ENTIDADES DE CRÉDITO
A7: Préstamos, pólizas de crédito, leasing o renting financiero | B7: 0 | C7: No hay ninguno registrado en el ERP.
A9: 2 · DEUDA CON SOCIOS
A10: Gastos de la sociedad pagados por los socios, pendientes de reembolso | B10: ='Deuda socios (detalle)'!$F$82 -> 5934.45 | C10: Detalle en la hoja «Deuda socios (detalle)». Sin intereses ni vencimiento pactado.
A11: · Pedro Domecq | B11: ='Deuda socios (detalle)'!$G$82 -> 1132.31
A12: · Nicolás Bustamante | B12: ='Deuda socios (detalle)'!$H$82 -> 3548.06
A13: · Domingo de Guzmán | B13: ='Deuda socios (detalle)'!$I$82 -> 1254.08
A14: · de los cuales, cuotas de autónomo del socio asumidas por la sociedad | B14: =SUMIFS('Deuda socios (detalle)'!$F$5:$F$81,'Deuda socios (detalle)'!$C$5:$C$81,"Cuota de autónomo del socio") -> 445.75 | C14: Confirmar con la gestoría su tratamiento.
A15: Aportaciones en efectivo de los socios (si se tratan como préstamo) | B15: =IF($B$4="Sí",'Aportaciones socios'!$C$23,0) -> 0 | C15: Con «No» en B4 cuentan como fondos propios y no suman aquí.
A16: TOTAL DEUDA CON SOCIOS | B16: =B10+B15 -> 5934.45
A18: 3 · PROVEEDORES Y ACREEDORES COMERCIALES
A19: Facturas recibidas pendientes de pago | B19: ='Proveedores y Hacienda'!$D$8 -> 703.72 | C19: Alquiler de octubre, luz y agua del arrendador (30/09).
A21: 4 · ADMINISTRACIONES PÚBLICAS
A22: Retenciones de IRPF del alquiler pendientes de ingresar (modelo 115, estimado) | B22: ='Proveedores y Hacienda'!$D$17 -> 324.87 | C22: 199,50 € del 3T, a ingresar hasta el 20/10/2026; el resto, de las facturas del 30/09, va al 4T. IVA con saldo a favor; sin deuda con la Seguridad Social.
A24: DEUDA TOTAL | B24: =B7+B16+B19+B22 -> 6963.04
A25: · de la cual, con socios | B25: =B16 -> 5934.45
A26: · de la cual, con terceros | B26: =B7+B19+B22 -> 1028.59
A28: PARA REFERENCIA — FINANCIACIÓN APORTADA POR LOS SOCIOS
A29: Aportaciones en efectivo a la cuenta de la sociedad | B29: ='Aportaciones socios'!$C$23 -> 6526 | C29: Hoja «Aportaciones socios».
A30: · Pedro Domecq | B30: ='Aportaciones socios'!$C$25 -> 2776
A31: · Nicolás Bustamante | B31: ='Aportaciones socios'!$C$26 -> 1400
A32: · Domingo de Guzmán | B32: ='Aportaciones socios'!$C$27 -> 2350
A33: Gastos pagados directamente por los socios | B33: =B10 -> 5934.45
A34: TOTAL FINANCIADO POR LOS SOCIOS | B34: =B29+B33 -> 12460.45 | C34: Entre la deuda con socios y las aportaciones, los socios han financiado toda la actividad hasta hoy.
A36: Hojas: Deuda socios (detalle) · Aportaciones socios · Proveedores y Hacienda. No incluye el capital social escriturado.

Sheet Deuda socios (detalle)
A1: Rootflow Hydroponics — Gastos de la sociedad pagados por los socios
A2: Pendientes de reembolso a 07/10/2026: el ERP no registra ningún reembolso. Importes pagados, IVA incluido. Los gastos de constitución y alquiler que se repartieron a partes iguales figuran a nombre de los tres socios.
A4: Fecha | B4: Concepto | C4: Tipo | D4: Pagado por | E4: Justificante | F4: Importe | G4: Pedro Domecq | H4: Nicolás Bustamante | I4: Domingo de Guzmán
A5: 46021 | B5: IONOS (web y dominio) | C5: Software y web | D5: Pedro Domecq | E5: Factura o ticket | F5: 1.21 | G5: =IF($D5="Pedro Domecq",$F5,0) -> 1.21 | H5: =IF($D5="Nicolás Bustamante",$F5,0) -> 0 | I5: =IF($D5="Domingo de Guzmán",$F5,0) -> 0
A6: 46052 | B6: IONOS (web y dominio) | C6: Software y web | D6: Pedro Domecq | E6: Factura o ticket | F6: 1.21 | G6: =IF($D6="Pedro Domecq",$F6,0) -> 1.21 | H6: =IF($D6="Nicolás Bustamante",$F6,0) -> 0 | I6: =IF($D6="Domingo de Guzmán",$F6,0) -> 0
A7: 46082 | B7: IONOS (web y dominio) | C7: Software y web | D7: Pedro Domecq | E7: Factura o ticket | F7: 1.21 | G7: =IF($D7="Pedro Domecq",$F7,0) -> 1.21 | H7: =IF($D7="Nicolás Bustamante",$F7,0) -> 0 | I7: =IF($D7="Domingo de Guzmán",$F7,0) -> 0
A8: 46087 | B8: Alquiler del local, abril | C8: Constitución y local | D8: Pedro Domecq (repartido entre los tres) | E8: Factura o ticket | F8: 535.5 | G8: 178.5 | H8: 178.5 | I8: 178.5
A9: 46095 | B9: Medidor de temperatura y humedad | C9: Equipamiento y material | D9: Domingo de Guzmán | E9: Factura o ticket | F9: 21.99 | G9: =IF($D9="Pedro Domecq",$F9,0) -> 0 | H9: =IF($D9="Nicolás Bustamante",$F9,0) -> 0 | I9: =IF($D9="Domingo de Guzmán",$F9,0) -> 21.99
A10: 46096 | B10: Bandejas leroy merlin | C10: Equipamiento y material | D10: Domingo de Guzmán | E10: Factura o ticket | F10: 34.86 | G10: =IF($D10="Pedro Domecq",$F10,0) -> 0 | H10: =IF($D10="Nicolás Bustamante",$F10,0) -> 0 | I10: =IF($D10="Domingo de Guzmán",$F10,0) -> 34.86
A11: 46100 | B11: Notaría (constitución de la sociedad) | C11: Constitución y local | D11: Pedro Domecq (repartido entre los tres) | E11: Factura o ticket | F11: 181.5 | G11: 60.5 | H11: 60.5 | I11: 60.5
A12: 46100 | B12: Notaría (constitución de la sociedad) | C12: Constitución y local | D12: Pedro Domecq (repartido entre los tres) | E12: Factura o ticket | F12: 504.4 | G12: 168.13 | H12: 168.13 | I12: 168.14
A13: 46100 | B13: Notaría (constitución de la sociedad) | C13: Constitución y local | D13: Pedro Domecq (repartido entre los tres) | E13: Factura o ticket | F13: 98.75 | G13: 32.91 | H13: 32.91 | I13: 32.93
A14: 46100 | B14: Notaría (constitución de la sociedad) | C14: Constitución y local | D14: Pedro Domecq (repartido entre los tres) | E14: Factura o ticket | F14: 60.83 | G14: 20.27 | H14: 20.27 | I14: 20.29
A15: 46100 | B15: Notaría (constitución de la sociedad) | C15: Constitución y local | D15: Pedro Domecq (repartido entre los tres) | E15: Factura o ticket | F15: 65.34 | G15: 21.78 | H15: 21.78 | I15: 21.78
A16: 46108 | B16: Cables (ferretería) | C16: Equipamiento y material | D16: Domingo de Guzmán | E16: Factura o ticket | F16: 16.3 | G16: =IF($D16="Pedro Domecq",$F16,0) -> 0 | H16: =IF($D16="Nicolás Bustamante",$F16,0) -> 0 | I16: =IF($D16="Domingo de Guzmán",$F16,0) -> 16.3
A17: 46111 | B17: Pegamento (ferretería) | C17: Equipamiento y material | D17: Domingo de Guzmán | E17: Factura o ticket | F17: 15.6 | G17: =IF($D17="Pedro Domecq",$F17,0) -> 0 | H17: =IF($D17="Nicolás Bustamante",$F17,0) -> 0 | I17: =IF($D17="Domingo de Guzmán",$F17,0) -> 15.6
A18: 46119 | B18: Anthropic (Claude) | C18: Software y web | D18: Pedro Domecq | E18: Factura o ticket | F18: 18 | G18: =IF($D18="Pedro Domecq",$F18,0) -> 18 | H18: =IF($D18="Nicolás Bustamante",$F18,0) -> 0 | I18: =IF($D18="Domingo de Guzmán",$F18,0) -> 0
A19: 46119 | B19: Tarjetas de visita | C19: Equipamiento y material | D19: Pedro Domecq | E19: Factura o ticket | F19: 104.96 | G19: =IF($D19="Pedro Domecq",$F19,0) -> 104.96 | H19: =IF($D19="Nicolás Bustamante",$F19,0) -> 0 | I19: =IF($D19="Domingo de Guzmán",$F19,0) -> 0
A20: 46120 | B20: Anthropic (Claude) | C20: Software y web | D20: Pedro Domecq | E20: Factura o ticket | F20: 5 | G20: =IF($D20="Pedro Domecq",$F20,0) -> 5 | H20: =IF($D20="Nicolás Bustamante",$F20,0) -> 0 | I20: =IF($D20="Domingo de Guzmán",$F20,0) -> 0
A21: 46121 | B21: Anthropic (Claude) | C21: Software y web | D21: Pedro Domecq | E21: Factura o ticket | F21: 5 | G21: =IF($D21="Pedro Domecq",$F21,0) -> 5 | H21: =IF($D21="Nicolás Bustamante",$F21,0) -> 0 | I21: =IF($D21="Domingo de Guzmán",$F21,0) -> 0
A22: 46121 | B22: Mesa, sillas, enchufes | C22: Equipamiento y material | D22: Nicolás Bustamante | E22: Factura o ticket | F22: 144.95 | G22: =IF($D22="Pedro Domecq",$F22,0) -> 0 | H22: =IF($D22="Nicolás Bustamante",$F22,0) -> 144.95 | I22: =IF($D22="Domingo de Guzmán",$F22,0) -> 0
A23: 46121 | B23: Productos de limpieza | C23: Equipamiento y material | D23: Nicolás Bustamante | E23: Factura o ticket | F23: 18.93 | G23: =IF($D23="Pedro Domecq",$F23,0) -> 0 | H23: =IF($D23="Nicolás Bustamante",$F23,0) -> 18.93 | I23: =IF($D23="Domingo de Guzmán",$F23,0) -> 0
A24: 46121 | B24: Candado y utensilios de siembra | C24: Equipamiento y material | D24: Nicolás Bustamante | E24: Factura o ticket | F24: 103.88 | G24: =IF($D24="Pedro Domecq",$F24,0) -> 0 | H24: =IF($D24="Nicolás Bustamante",$F24,0) -> 103.88 | I24: =IF($D24="Domingo de Guzmán",$F24,0) -> 0
A25: 46121 | B25: Temporizador enchufe | C25: Equipamiento y material | D25: Nicolás Bustamante | E25: Factura o ticket | F25: 30.48 | G25: =IF($D25="Pedro Domecq",$F25,0) -> 0 | H25: =IF($D25="Nicolás Bustamante",$F25,0) -> 30.48 | I25: =IF($D25="Domingo de Guzmán",$F25,0) -> 0
A26: 46121 | B26: Inkbird | C26: Equipamiento y material | D26: Nicolás Bustamante | E26: Factura o ticket | F26: 42.48 | G26: =IF($D26="Pedro Domecq",$F26,0) -> 0 | H26: =IF($D26="Nicolás Bustamante",$F26,0) -> 42.48 | I26: =IF($D26="Domingo de Guzmán",$F26,0) -> 0
A27: 46121 | B27: Calentador Cable | C27: Equipamiento y material | D27: Nicolás Bustamante | E27: Factura o ticket | F27: 20.75 | G27: =IF($D27="Pedro Domecq",$F27,0) -> 0 | H27: =IF($D27="Nicolás Bustamante",$F27,0) -> 20.75 | I27: =IF($D27="Domingo de Guzmán",$F27,0) -> 0
... A52: 46145 | B52: Cuota de autónomo del socio | C52: Cuota de autónomo del socio | D52: Nicolás Bustamante | E52: Factura o ticket | F52: 88.56 | G52: =IF($D52="Pedro Domecq",$F52,0) -> 0 | H52: =IF($D52="Nicolás Bustamante",$F52,0) -> 88.56 | I52: =IF($D52="Domingo de Guzmán",$F52,0) -> 0
A53: 46146 | B53: Alquiler del local, mayo | C53: Constitución y local | D53: Pedro Domecq (repartido entre los tres) | E53: Factura o ticket | F53: 547.61 | G53: 182.53 | H53: 182.53 | I53: 182.55
A54: 46146 | B54: Anthropic (Claude), desarrollo del ERP | C54: Software y web | D54: Pedro Domecq | E54: Factura o ticket | F54: 5 | G54: =IF($D54="Pedro Domecq",$F54,0) -> 5 | H54: =IF($D54="Nicolás Bustamante",$F54,0) -> 0 | I54: =IF($D54="Domingo de Guzmán",$F54,0) -> 0
A55: 46146 | B55: MD Labels Etiquetas térmicas | C55: Consumibles de producción | D55: Pedro Domecq | E55: Factura o ticket | F55: 7.41 | G55: =IF($D55="Pedro Domecq",$F55,0) -> 7.41 | H55: =IF($D55="Nicolás Bustamante",$F55,0) -> 0 | I55: =IF($D55="Domingo de Guzmán",$F55,0) -> 0
A56: 46147 | B56: Honorarios de la inmobiliaria (alquiler del local) | C56: Constitución y local | D56: Pedro Domecq (repartido entre los tres) | E56: Factura o ticket | F56: 635.25 | G56: 211.75 | H56: 211.75 | I56: 211.75
A57: 46147 | B57: Anthropic (Claude), desarrollo del ERP | C57: Software y web | D57: Pedro Domecq | E57: Factura o ticket | F57: 5 | G57: =IF($D57="Pedro Domecq",$F57,0) -> 5 | H57: =IF($D57="Nicolás Bustamante",$F57,0) -> 0 | I57: =IF($D57="Domingo de Guzmán",$F57,0) -> 0
A58: 46147 | B58: Anthropic (Claude), desarrollo del ERP | C58: Software y web | D58: Pedro Domecq | E58: Factura o ticket | F58: 5 | G58: =IF($D58="Pedro Domecq",$F58,0) -> 5 | H58: =IF($D58="Nicolás Bustamante",$F58,0) -> 0 | I58: =IF($D58="Domingo de Guzmán",$F58,0) -> 0
A59: 46148 | B59: Anthropic (Claude), desarrollo del ERP | C59: Software y web | D59: Pedro Domecq | E59: Factura o ticket | F59: 5 | G59: =IF($D59="Pedro Domecq",$F59,0) -> 5 | H59: =IF($D59="Nicolás Bustamante",$F59,0) -> 0 | I59: =IF($D59="Domingo de Guzmán",$F59,0) -> 0
A60: 46149 | B60: Cable USB impresora | C60: Equipamiento y material | D60: Pedro Domecq | E60: Factura o ticket | F60: 4.26 | G60: =IF($D60="Pedro Domecq",$F60,0) -> 4.26 | H60: =IF($D60="Nicolás Bustamante",$F60,0) -> 0 | I60: =IF($D60="Domingo de Guzmán",$F60,0) -> 0
A61: 46149 | B61: Cartucho impresora | C61: Equipamiento y material | D61: Pedro Domecq | E61: Factura o ticket | F61: 10.5 | G61: =IF($D61="Pedro Domecq",$F61,0) -> 10.5 | H61: =IF($D61="Nicolás Bustamante",$F61,0) -> 0 | I61: =IF($D61="Domingo de Guzmán",$F61,0) -> 0
A62: 46149 | B62: Luces LED | C62: Equipamiento y material | D62: Nicolás Bustamante | E62: Factura o ticket | F62: 127.36 | G62: =IF($D62="Pedro Domecq",$F62,0) -> 0 | H62: =IF($D62="Nicolás Bustamante",$F62,0) -> 127.36 | I62: =IF($D62="Domingo de Guzmán",$F62,0) -> 0
A63: 46155 | B63: Cajas verdes plegables | C63: Equipamiento y material | D63: Nicolás Bustamante | E63: Factura o ticket | F63: 126.28 | G63: =IF($D63="Pedro Domecq",$F63,0) -> 0 | H63: =IF($D63="Nicolás Bustamante",$F63,0) -> 126.28 | I63: =IF($D63="Domingo de Guzmán",$F63,0) -> 0
A64: 46155 | B64: Anthropic (Claude), desarrollo del ERP | C64: Software y web | D64: Pedro Domecq | E64: Factura o ticket | F64: 5 | G64: =IF($D64="Pedro Domecq",$F64,0) -> 5 | H64: =IF($D64="Nicolás Bustamante",$F64,0) -> 0 | I64: =IF($D64="Domingo de Guzmán",$F64,0) -> 0
A65: 46155 | B65: Registro de la propiedad - certificado | C65: Constitución y local | D65: Pedro Domecq | E65: Factura o ticket | F65: 34.18 | G65: =IF($D65="Pedro Domecq",$F65,0) -> 34.18 | H65: =IF($D65="Nicolás Bustamante",$F65,0) -> 0 | I65: =IF($D65="Domingo de Guzmán",$F65,0) -> 0
...

Sheet Aportaciones socios
A1: Rootflow Hydroponics — Aportaciones en efectivo de los socios
A2: Transferencias de los socios a la cuenta de la sociedad, según el ERP a 07/10/2026. Su tratamiento (fondos propios o préstamo) se elige en la hoja Resumen.
A4: Fecha | B4: Socio | C4: Importe | D4: Concepto (ERP)
A5: 46154 | B5: Domingo de Guzmán | C5: 500
A6: 46154 | B6: Pedro Domecq | C6: 500
A7: 46160 | B7: Nicolás Bustamante | C7: 500
A8: 46171 | B8: Nicolás Bustamante | C8: 500
A9: 46171 | B9: Pedro Domecq | C9: 500
A10: 46182 | B10: Domingo de Guzmán | C10: 500
A11: 46206 | B11: Pedro Domecq | C11: 400 | D11: Para pagar el alquiler
A12: 46206 | B12: Nicolás Bustamante | C12: 400
A13: 46220 | B13: Domingo de Guzmán | C13: 150
A14: 46220 | B14: Pedro Domecq | C14: 150 | D14: Para pagar impuestos
A15: 46237 | B15: Pedro Domecq | C15: 300
A16: 46237 | B16: Domingo de Guzmán | C16: 150
A17: 46243 | B17: Domingo de Guzmán | C17: 150
A18: 46265 | B18: Pedro Domecq | C18: 426 | D18: Pago del alquiler de septiembre
A19: 46265 | B19: Domingo de Guzmán | C19: 400
A20: 46296 | B20: Domingo de Guzmán | C20: 400
A21: 46300 | B21: Domingo de Guzmán | C21: 100
A22: 46300 | B22: Pedro Domecq | C22: 500 | D22: Aportación de socios a fondos propios
B23: TOTAL | C23: =SUM(C5:C22) -> 6526
B25: Pedro Domecq | C25: =SUMIFS($C$5:$C$22,$B$5:$B$22,B25) -> 2776
B26: Nicolás Bustamante | C26: =SUMIFS($C$5:$C$22,$B$5:$B$22,B26) -> 1400
B27: Domingo de Guzmán | C27: =SUMIFS($C$5:$C$22,$B$5:$B$22,B27) -> 2350

Sheet Proveedores y Hacienda
A1: Rootflow Hydroponics — Facturas pendientes de pago y obligaciones con Hacienda
A2: Según el ERP a 07/10/2026. Las retenciones son una estimación a partir de las facturas del arrendador: confirmar con la gestoría.
A4: Fecha | B4: Acreedor | C4: Concepto | D4: Importe | E4: Vencimiento | F4: Nota
A5: 46295 | B5: Bellbro Renting and Development, S.L. | C5: Alquiler del local, octubre 2026 | D5: 535.5 | E5: 46300 | F5: 525,00 € + IVA − retención IRPF
A6: 46295 | B6: Bellbro Renting and Development, S.L. | C6: Luz repercutida, 15/07 a 15/09/2026 | D6: 137.51 | E6: 46300 | F6: 134,82 € + IVA − retención IRPF
A7: 46295 | B7: Bellbro Renting and Development, S.L. | C7: Agua, 10/07 a 08/09/2026 | D7: 30.71 | E7: 46300
C8: Total facturas de proveedores pendientes de pago | D8: =SUM(D5:D7) -> 703.72
F9: Vencimiento: primeros días del mes (pago domiciliado habitual).
A11: HACIENDA — retenciones de IRPF del alquiler (modelo 115) pendientes de ingresar
A12: Fecha factura | B12: Arrendador | C12: Factura | D12: Retención 19 % | E12: A ingresar hasta | F12: Nota
A13: 46231 | B13: Bellbro Renting and Development, S.L. | C13: Alquiler agosto | D13: 99.75 | E13: 46315 | F13: 3T: alquiler pagado en el trimestre.
A14: 46265 | B14: Bellbro Renting and Development, S.L. | C14: Alquiler septiembre | D14: 99.75 | E14: 46315 | F14: 3T: alquiler pagado en el trimestre.
A15: 46295 | B15: Bellbro Renting and Development, S.L. | C15: Alquiler octubre | D15: 99.75 | E15: 46407 | F15: 4T: factura del 30/09 aún sin pagar; la retención se ingresa al pagarla.
A16: 46295 | B16: Bellbro Renting and Development, S.L. | C16: Luz repercutida 15/07–15/09 | D16: 25.62 | E16: 46407 | F16: 4T: factura del 30/09 aún sin pagar; la retención se ingresa al pagarla.
C17: Total retenciones pendientes de ingresar (estimado) | D17: =SUM(D13:D16) -> 324.87
A19: IVA: en 2026 el IVA soportado (21 % en compras y alquiler) supera al repercutido (4 % en ventas), así que la sociedad tiene saldo a compensar o devolver, no deuda. Impuesto sobre Sociedades: sin cuota (pérdidas). Seguridad Social: la sociedad no tiene empleados.
