Workbook

Sheet Portada
B2: ROOTFLOW HYDROPONICS S.L.
B3: Modelo financiero V17 — Ronda: inversor privado (capital) + ENISA
B4: Microbrotes y flores comestibles · Madrid · DOS líneas de negocio: distribución + restaurantes
B6: Qué hay dentro
B7: · PRODUCTO: rendimiento, ciclos y coste bottom-up por variedad; TARIFAS REALES por canal (mayorista, tienda, restaurante).
B8: · TARIFAS: hoja para cargar el export del ERP (no alimenta todavía el modelo).
B9: · RESTAURANTES: la palanca (% de la nave para restaurantes), ticket, riders, microhub, lanzadera, captación, agosto y techo de mercado con el censo municipal.
B10: · PIPELINE: clientes de distribución identificados. Alimentan la demanda de la línea de distribución.
B11: · HIPÓTESIS: escenarios, nóminas, financiación y estructura del inversor (capital 10 %, suelo 1,5×, salida año 4).
B12: · LOGÍSTICA: distribución con furgo propia en Madrid y Athos fuera. CAPEX: nave, automatización, microhub y fianzas.
B13: · MODELO_MENSUAL (escenario activo) y Esc_* (los tres casos, 84 meses). Bloque de líneas de negocio en filas 168-217.
B14: · LINEAS_NEGOCIO: cuenta de resultados por línea (distribución, restaurantes y costes comunes), cuadrada con el EBITDA.
... B37: V17 · Octubre 2026

Sheet Resumen
A1: ROOTFLOW — Resumen para ENISA e inversores
A2: Cuadro de mando. Portfolio real + demanda identificada + capital stack.
A4: COMPARATIVA DE ESCENARIOS — se recalcula sola al cambiar cualquier variable del modelo
A5: Palanca / resultado | C5: CONSERVADOR | D5: BASE | E5: OPTIMISTA
A6: LO QUE SE MODIFICA EN CADA CASO
A7: Minutos por bandeja | C7: =Producto!$D$8 -> 4 | D7: =Producto!$D$9 -> 3 | E7: =Producto!$D$10 -> 2
A8: Precio — línea distribución (índice sobre tarifa actual) | C8: =Hipótesis!$C$16 -> 0.9 | D8: =Hipótesis!$D$16 -> 1 | E8: =Hipótesis!$E$16 -> 1.1
A9: Coste de producto (índice sobre el coste bottom-up) | C9: =Hipótesis!$C$18 -> 1.05 | D9: =Hipótesis!$D$18 -> 1 | E9: =Hipótesis!$E$18 -> 0.9
A10: Inversión en automatización (€) | C10: =CAPEX!$E$10 -> 0 | D10: =CAPEX!$F$10 -> 10000 | E10: =CAPEX!$G$10 -> 35000
A11: Inversión total = necesidad de financiación (€) | C11: =CAPEX!$E$26 -> 161048 | D11: =CAPEX!$F$26 -> 173048 | E11: =CAPEX!$G$26 -> 196598
A12: PLANTILLA (se calcula sola según los minutos)
A13: Operarios de cultivo en régimen (nº) | C13: =Esc_Conservador!$CH$30 -> 6 | D13: =Esc_Base!$CH$30 -> 4 | E13: =Esc_Optimista!$CH$30 -> 2
A14: Plantilla TOTAL en régimen (nº) | C14: =Esc_Conservador!$CH$31 -> 11 | D14: =Esc_Base!$CH$31 -> 9 | E14: =Esc_Optimista!$CH$31 -> 7
A15: Coste de nóminas en régimen (€/mes) | C15: =-Esc_Conservador!$CH$51 -> 46141.316 | D15: =-Esc_Base!$CH$51 -> 40782.41 | E15: =-Esc_Optimista!$CH$51 -> 35423.503
A16: RESULTADO EN RÉGIMEN (año 5)
A17: Ingresos (€) | C17: =SUM(Esc_Conservador!$AY$36:$BJ$36) -> 1452128.7 | D17: =SUM(Esc_Base!$AY$36:$BJ$36) -> 1720250.3 | E17: =SUM(Esc_Optimista!$AY$36:$BJ$36) -> 1980363.9
A18: EBITDA (€) | C18: =SUM(Esc_Conservador!$AY$56:$BJ$56) -> 388642.64 | D18: =SUM(Esc_Base!$AY$56:$BJ$56) -> 713969.37 | E18: =SUM(Esc_Optimista!$AY$56:$BJ$56) -> 1051015.8
A19: Margen EBITDA (%) | C19: =IFERROR(SUM(Esc_Conservador!$AY$56:$BJ$56)/SUM(Esc_Conservador!$AY$36:$BJ$36),0) -> 0.2676365 | D19: =IFERROR(SUM(Esc_Base!$AY$56:$BJ$56)/SUM(Esc_Base!$AY$36:$BJ$36),0) -> 0.41503807 | E19: =IFERROR(SUM(Esc_Optimista!$AY$56:$BJ$56)/SUM(Esc_Optimista!$AY$36:$BJ$36),0) -> 0.53071854
A20: Producción (kg/mes) | C20: =Esc_Conservador!$CH$26 -> 2970.9393 | D20: =Esc_Base!$CH$26 -> 3128.4564 | E20: =Esc_Optimista!$CH$26 -> 3246.5942
A21: RESULTADO DE LA OPERACIÓN
A22: Ingresos año 1 (€) | C22: =Esc_Conservador!$C$147 -> 193490.03 | D22: =Esc_Base!$C$147 -> 248408.39 | E22: =Esc_Optimista!$C$147 -> 311861.83
A23: Caja mínima del plan (€) | C23: =Esc_Conservador!$C$146 -> 30000 | D23: =Esc_Base!$C$146 -> 30000 | E23: =Esc_Optimista!$C$146 -> 30000
A24: DSCR mínimo (años 2-7) | C24: =Esc_Conservador!$C$145 -> 9.5465253 | D24: =Esc_Base!$C$145 -> 15.940181 | E24: =Esc_Optimista!$C$145 -> 20.439219
A25: TIR del inversor (TAE) | C25: =IFERROR(Esc_Conservador!$C$128,0) -> 0.28212158 | D25: =IFERROR(Esc_Base!$C$128,0) -> 0.50716006 | E25: =IFERROR(Esc_Optimista!$C$128,0) -> 0.66568722
A26: MOIC (múltiplo) | C26: =Esc_Conservador!$C$129 -> 2.702196 | D26: =Esc_Base!$C$129 -> 5.1598551 | E26: =Esc_Optimista!$C$129 -> 7.6979274
A27: Payback del inversor (meses) | C27: =Esc_Conservador!$C$130 -> 48 | D27: =Esc_Base!$C$130 -> 48 | E27: =Esc_Optimista!$C$130 -> 48
A28: Financiación levantada (€) | C28: =Hipótesis!$D$122 -> 200000 | D28: =Hipótesis!$D$122 -> 200000 | E28: =Hipótesis!$D$122 -> 200000
A29: Póliza de crédito — máximo dispuesto (€) | C29: =Esc_Conservador!$C$150 -> 29593.795 | D29: =Esc_Base!$C$150 -> 15580.848 | E29: =Esc_Optimista!$C$150 -> 10049.702
A30: LO QUE SE LLEVA CADA SOCIO (30% cada uno)
A31: Neto €/mes en el año 3 (sueldo) | C31: =Esc_Conservador!$E$149 -> 2800 | D31: =Esc_Base!$E$149 -> 2800 | E31: =Esc_Optimista!$E$149 -> 2800
A32: Neto €/mes en el año 5 (sueldo + dividendo) | C32: =Esc_Conservador!$G$149 -> 3500 | D32: =Esc_Base!$G$149 -> 3500 | E32: =Esc_Optimista!$G$149 -> 3500
A33: Neto €/mes en el año 7 (sueldo + dividendo) | C33: =Esc_Conservador!$I$149 -> 4200 | D33: =Esc_Base!$I$149 -> 4200 | E33: =Esc_Optimista!$I$149 -> 4200
A34: Dividendos cobrados por socio en 7 años (neto) | C34: =SUM(Esc_Conservador!$C$117:$CH$117) -> 0 | D34: =SUM(Esc_Base!$C$117:$CH$117) -> 0 | E34: =SUM(Esc_Optimista!$C$117:$CH$117) -> 0
A35: Fondo Hito 4 acumulado (€) | C35: =Esc_Conservador!$CH$115 -> 408483.29 | D35: =Esc_Base!$CH$115 -> 789076.66 | E35: =Esc_Optimista!$CH$115 -> 1180015.9
A36: Caja + fondo Hito 4 en la empresa (año 7) | C36: =Esc_Conservador!$CH$86+Esc_Conservador!$CH$115 -> 1131856.2 | D36: =Esc_Base!$CH$86+Esc_Base!$CH$115 -> 2484862.8 | E36: =Esc_Optimista!$CH$86+Esc_Optimista!$CH$115 -> 3878963.6
A37: · de eso, le corresponde a CADA socio (30%) | C37: =(Esc_Conservador!$CH$86+Esc_Conservador!$CH$115)*Hipótesis!$D$82 -> 339556.86 | D37: =(Esc_Base!$CH$86+Esc_Base!$CH$115)*Hipótesis!$D$82 -> 745458.85 | E37: =(Esc_Optimista!$CH$86+Esc_Optimista!$CH$115)*Hipótesis!$D$82 -> 1163689.1
A38: Valor de su 30% al múltiplo de salida | C38: =Esc_Conservador!$C$133*Hipótesis!$D$82 -> 810658.79 | D38: =Esc_Base!$C$133*Hipótesis!$D$82 -> 1547956.5 | E38: =Esc_Optimista!$C$133*Hipótesis!$D$82 -> 2309378.2
A40: ¿La financiación CUBRE la necesidad? | C40: =IF(Hipótesis!$D$122>=CAPEX!$E$26,"SÍ","NO — faltan "&TEXT(CAPEX!$E$26-Hipótesis!$D$122,"#,##0")&" €") -> SÍ | D40: =IF(Hipótesis!$D$122>=CAPEX!$F$26,"SÍ","NO — faltan "&TEXT(CAPEX!$F$26-Hipótesis!$D$122,"#,##0")&" €") -> SÍ | E40: =IF(Hipótesis!$D$122>=CAPEX!$G$26,"SÍ","NO — faltan "&TEXT(CAPEX!$G$26-Hipótesis!$D$122,"#,##0")&" €") -> SÍ
A41: Todo lo de arriba son FÓRMULAS: cambia precios, minutos, SUELDOS, circulante o CAPEX y los tres casos se actualizan a la vez.
A42: El circulante (clientes a 30 días) se financia con la póliza, no con la ronda de la caja. El fondo Hito 4 aparta dinero para la siguiente ampliación.
...

Sheet Producto
A1: ROOTFLOW — Portfolio de producto y COGS reales
A2: Coste real por bandeja (semilla + sustrato + envase, sin IVA). Solo se produce lo ACTIVO. El % de luz de las activas debe sumar 100%.
A4: Parámetros globales
A5: (obsoleto desde V17) Ratio precio DIRECTO ÷ DISTRIBUCIÓN — los precios por canal están en las columnas de tarifas | D5: 1.3
A6: Días medios por mes (365/12) | D6: 30.42
A7: Días muertos entre ciclos (limpieza/resiembra) | D7: 0 | F7: INPUT. Ciclos/mes = 30,42 ÷ (días de luz + días muertos). Con 1 día muerto, un rábano de 3 días de luz pasa de 10,1 a 7,6 ciclos/mes.
A8: Minutos por bandeja — CONSERVADOR (a mano, sin automatización) | D8: 4 | F8: CLAVE: el tiempo por bandeja es LA variable del negocio y define cuántos operarios hacen falta. Cada nivel de minutos se consigue con la automatización del CAPEX (ver hoja CAPEX).
A9: Minutos por bandeja — BASE (lavadora + cinta/cosecha asistida) | D9: 3
A10: Minutos por bandeja — OPTIMISTA (+ sembradora automática) | D10: 2
A11: MINUTOS POR BANDEJA — según escenario activo | D11: =CHOOSE(Hipótesis!$C$4,D8,D9,D10) -> 3
A12: Coste envase tarrina PEQUEÑA (5-15 g), sin IVA | D12: 0.1 | F12: COSTES_ROOTFLOW.xlsx · hoja 1
A13: Coste envase tarrina GRANDE (30-100 g), sin IVA | D13: 0.17 | F13: COSTES_ROOTFLOW.xlsx · hoja 1
A14: Sustrato por bandeja, sin IVA (saco 100 L a 18 € con IVA; 2,5 L por bandeja) | D14: =(18/1.21)*(2.5/100) -> 0.37190083 | F14: COSTES_ROOTFLOW.xlsx · hoja 1
A15: Variedad | B15: Estado dato | C15: Activo (1/0) | D15: % luz (bandejas) | E15: Formato MAYORISTA (g) | F15: Precio MAYORISTA €/tarrina | G15: €/kg MAYORISTA | H15: Días luz | I15: Días germ. | J15: Ciclos/mes — calc | K15: Rendim. (g/band) | L15: Tarrinas/band mayorista | M15: kg/band /mes — calc | N15: Semilla €/band | O15: Sustrato €/band | P15: Envase €/tarrina (may.) | Q15: Envase €/band — calc | R15: COGS €/band /ciclo (may.) | S15: COGS MAYOR. €/band/mes | T15: Ingreso MAYOR. €/band/mes | U15: MB % | V15: MARGEN €/hora trabajo | W15: Formato RESTAUR. (g) | X15: Precio RESTAUR. €/tarrina | Y15: €/kg RESTAUR. | Z15: Tarrinas/band restaur. | AA15: Envase rest. €/tarrina | AB15: Ingreso RESTAUR. €/band/mes | AC15: COGS RESTAUR. €/band/mes | AD15: Formato TIENDA (g) | AE15: Precio TIENDA €/tarrina | AF15: €/kg TIENDA | AG15: Tarrinas/band tienda | AH15: Envase tienda €/tarrina | AI15: Ingreso TIENDA €/band/mes | AJ15: COGS TIENDA €/band/mes
A16: Micromezclum (mix 7 var.) | B16: PROVISIONAL | C16: 1 | D16: 0.4 | E16: 100 | F16: 3 | G16: =F16/E16*1000 -> 30 | H16: 3.7 | I16: 3.7 | J16: =Producto!$D$6/(H16+Producto!$D$7) -> 8.2216216 | K16: 170 | L16: =K16/E16 -> 1.7 | M16: =J16*K16/1000 -> 1.3976757 | N16: 0.3144 | O16: =Producto!$D$14 -> 0.37190083 | P16: =IF(E16<=15,Producto!$D$12,Producto!$D$13) -> 0.17 | Q16: =L16*P16 -> 0.289 | R16: =N16+O16+Q16 -> 0.97530083 | S16: =R16*J16 -> 8.0185544 | T16: =L16*F16*J16 -> 41.93027 | U16: =IFERROR((T16-S16)/T16,0) -> 0.80876454 | V16: =IFERROR((T16-S16)/(J16*Producto!$D$11/60),0) -> 82.493983 | W16: 50 | X16: 5.5 | Y16: =IFERROR(X16/W16*1000,0) -> 110 | Z16: =IFERROR(K16/W16,0) -> 3.4 | AA16: =IF(W16<=15,Producto!$D$12,Producto!$D$13) -> 0.17 | AB16: =Z16*X16*J16 -> 153.74432 | AC16: =(N16+O16+Z16*AA16)*J16 -> 10.394603 | AD16: 50 | AE16: 3 | AF16: =IFERROR(AE16/AD16*1000,0) -> 60 | AG16: =IFERROR(K16/AD16,0) -> 3.4 | AH16: =IF(AD16<=15,Producto!$D$12,Producto!$D$13) -> 0.17 | AI16: =AG16*AE16*J16 -> 83.860541 | AJ16: =(N16+O16+AG16*AH16)*J16 -> 10.394603
A17: Cilantro split | B17: CONFIRMADO | C17: 1 | D17: 0.15 | E17: 30 | F17: 2.5 | G17: =F17/E17*1000 -> 83.333333 | H17: 10 | I17: 5 | J17: =Producto!$D$6/(H17+Producto!$D$7) -> 3.042 | K17: 145 | L17: =K17/E17 -> 4.8333333 | M17: =J17*K17/1000 -> 0.44109 | N17: 0.225 | O17: =Producto!$D$14 -> 0.37190083 | P17: =IF(E17<=15,Producto!$D$12,Producto!$D$13) -> 0.17 | Q17: =L17*P17 -> 0.82166667 | R17: =N17+O17+Q17 -> 1.4185675 | S17: =R17*J17 -> 4.3152823 | T17: =L17*F17*J17 -> 36.7575 | U17: =IFERROR((T17-S17)/T17,0) -> 0.88260131 | V17: =IFERROR((T17-S17)/(J17*Producto!$D$11/60),0) -> 213.29532 | W17: 30 | X17: 7.85 | Y17: =IFERROR(X17/W17*1000,0) -> 261.66667 | Z17: =IFERROR(K17/W17,0) -> 4.8333333 | AA17: =IF(W17<=15,Producto!$D$12,Producto!$D$13) -> 0.17 | AB17: =Z17*X17*J17 -> 115.41855 | AC17: =(N17+O17+Z17*AA17)*J17 -> 4.3152823 | AD17: 15 | AE17: 1.75 | AF17: =IFERROR(AE17/AD17*1000,0) -> 116.66667 | AG17: =IFERROR(K17/AD17,0) -> 9.6666667 | AH17: =IF(AD17<=15,Producto!$D$12,Producto!$D$13) -> 0.1 | AI17: =AG17*AE17*J17 -> 51.4605 | AJ17: =(N17+O17+AG17*AH17)*J17 -> 4.7563723
A18: Albahaca genovesa | B18: CONFIRMADO | C18: 1 | D18: 0.1 | E18: 30 | F18: 2.5 | G18: =F18/E18*1000 -> 83.333333 | H18: 13 | I18: 5 | J18: =Producto!$D$6/(H18+Producto!$D$7) -> 2.34 | K18: 90 | L18: =K18/E18 -> 3 | M18: =J18*K18/1000 -> 0.2106 | N18: 0.333 | O18: =Producto!$D$14 -> 0.37190083 | P18: =IF(E18<=15,Producto!$D$12,Producto!$D$13) -> 0.17 | Q18: =L18*P18 -> 0.51 | R18: =N18+O18+Q18 -> 1.2149008 | S18: =R18*J18 -> 2.8428679 | T18: =L18*F18*J18 -> 17.55 | U18: =IFERROR((T18-S18)/T18,0) -> 0.83801322 | V18: =IFERROR((T18-S18)/(J18*Producto!$D$11/60),0) -> 125.70198 | W18: 30 | X18: 9.3 | Y18: =IFERROR(X18/W18*1000,0) -> 310 | Z18: =IFERROR(K18/W18,0) -> 3 | AA18: =IF(W18<=15,Producto!$D$12,Producto!$D$13) -> 0.17 | AB18: =Z18*X18*J18 -> 65.286 | AC18: =(N18+O18+Z18*AA18)*J18 -> 2.8428679 | AD18: 15 | AE18: 1.65 | AF18: =IFERROR(AE18/AD18*1000,0) -> 110 | AG18: =IFERROR(K18/AD18,0) -> 6 | AH18: =IF(AD18<=15,Producto!$D$12,Producto!$D$13) -> 0.1 | AI18: =AG18*AE18*J18 -> 23.166 | AJ18: =(N18+O18+AG18*AH18)*J18 -> 3.0534679
A19: Rábano daikon | B19: PROVISIONAL | C19: 1 | D19: 0.08 | E19: 30 | F19: 1.5 | G19: =F19/E19*1000 -> 50 | H19: 3 | I19: 3 | J19: =Producto!$D$6/(H19+Producto!$D$7) -> 10.14 | K19: 245 | L19: =K19/E19 -> 8.1666667 | M19: =J19*K19/1000 -> 2.4843 | N19: 0.34 | O19: =Producto!$D$14 -> 0.37190083 | P19: =IF(E19<=15,Producto!$D$12,Producto!$D$13) -> 0.17 | Q19: =L19*P19 -> 1.3883333 | R19: =N19+O19+Q19 -> 2.1002342 | S19: =R19*J19 -> 21.296374 | T19: =L19*F19*J19 -> 124.215 | U19: =IFERROR((T19-S19)/T19,0) -> 0.82855231 | V19: =IFERROR((T19-S19)/(J19*Producto!$D$11/60),0) -> 202.99532 | W19: 30 | X19: 5.95 | Y19: =IFERROR(X19/W19*1000,0) -> 198.33333 | Z19: =IFERROR(K19/W19,0) -> 8.1666667 | AA19: =IF(W19<=15,Producto!$D$12,Producto!$D$13) -> 0.17 | AB19: =Z19*X19*J19 -> 492.7195 | AC19: =(N19+O19+Z19*AA19)*J19 -> 21.296374 | AD19: 15 | AE19: 1.85 | AF19: =IFERROR(AE19/AD19*1000,0) -> 123.33333 | AG19: =IFERROR(K19/AD19,0) -> 16.333333 | AH19: =IF(AD19<=15,Producto!$D$12,Producto!$D$13) -> 0.1 | AI19: =AG19*AE19*J19 -> 306.397 | AJ19: =(N19+O19+AG19*AH19)*J19 -> 23.780674
A20: Rúcula rocket | B20: PROVISIONAL | C20: 1 | D20: 0.08 | E20: 30 | F20: 1.5 | G20: =F20/E20*1000 -> 50 | H20: 4 | I20: 3 | J20: =Producto!$D$6/(H20+Producto!$D$7) -> 7.605 | K20: 170 | L20: =K20/E20 -> 5.6666667 | M20: =J20*K20/1000 -> 1.29285 | N20: 0.165 | O20: =Producto!$D$14 -> 0.37190083 | P20: =IF(E20<=15,Producto!$D$12,Producto!$D$13) -> 0.17 | Q20: =L20*P20 -> 0.96333333 | R20: =N20+O20+Q20 -> 1.5002342 | S20: =R20*J20 -> 11.409281 | T20: =L20*F20*J20 -> 64.6425 | U20: =IFERROR((T20-S20)/T20,0) -> 0.82350186 | V20: =IFERROR((T20-S20)/(J20*Producto!$D$11/60),0) -> 139.99532 | W20: 30 | X20: 6.8 | Y20: =IFERROR(X20/W20*1000,0) -> 226.66667 | Z20: =IFERROR(K20/W20,0) -> 5.6666667 | AA20: =IF(W20<=15,Producto!$D$12,Producto!$D$13) -> 0.17 | AB20: =Z20*X20*J20 -> 293.046 | AC20: =(N20+O20+Z20*AA20)*J20 -> 11.409281 | AD20: 15 | AE20: 1.6 | AF20: =IFERROR(AE20/AD20*1000,0) -> 106.66667 | AG20: =IFERROR(K20/AD20,0) -> 11.333333 | AH20: =IF(AD20<=15,Producto!$D$12,Producto!$D$13) -> 0.1 | AI20: =AG20*AE20*J20 -> 137.904 | AJ20: =(N20+O20+AG20*AH20)*J20 -> 12.702131
A21: Rábano rose | B21: PROVISIONAL | C21: 1 | D21: 0.07 | E21: 30 | F21: 1.5 | G21: =F21/E21*1000 -> 50 | H21: 3 | I21: 3 | J21: =Producto!$D$6/(H21+Producto!$D$7) -> 10.14 | K21: 245 | L21: =K21/E21 -> 8.1666667 | M21: =J21*K21/1000 -> 2.4843 | N21: 0.3366 | O21: =Producto!$D$14 -> 0.37190083 | P21: =IF(E21<=15,Producto!$D$12,Producto!$D$13) -> 0.17 | Q21: =L21*P21 -> 1.3883333 | R21: =N21+O21+Q21 -> 2.0968342 | S21: =R21*J21 -> 21.261898 | T21: =L21*F21*J21 -> 124.215 | U21: =IFERROR((T21-S21)/T21,0) -> 0.82882986 | V21: =IFERROR((T21-S21)/(J21*Producto!$D$11/60),0) -> 203.06332 | W21: 30 | X21: 6.2 | Y21: =IFERROR(X21/W21*1000,0) -> 206.66667 | Z21: =IFERROR(K21/W21,0) -> 8.1666667 | AA21: =IF(W21<=15,Producto!$D$12,Producto!$D$13) -> 0.17 | AB21: =Z21*X21*J21 -> 513.422 | AC21: =(N21+O21+Z21*AA21)*J21 -> 21.261898 | AD21: 15 | AE21: 1.85 | AF21: =IFERROR(AE21/AD21*1000,0) -> 123.33333 | AG21: =IFERROR(K21/AD21,0) -> 16.333333 | AH21: =IF(AD21<=15,Producto!$D$12,Producto!$D$13) -> 0.1 | AI21: =AG21*AE21*J21 -> 306.397 | AJ21: =(N21+O21+AG21*AH21)*J21 -> 23.746198
A22: Mostaza Red Giant | B22: PROVISIONAL | C22: 1 | D22: 0.05 | E22: 30 | F22: 1.5 | G22: =F22/E22*1000 -> 50 | H22: 4 | I22: 3 | J22: =Producto!$D$6/(H22+Producto!$D$7) -> 7.605 | K22: 160 | L22: =K22/E22 -> 5.3333333 | M22: =J22*K22/1000 -> 1.2168 | N22: 0.44 | O22: =Producto!$D$14 -> 0.37190083 | P22: =IF(E22<=15,Producto!$D$12,Producto!$D$13) -> 0.17 | Q22: =L22*P22 -> 0.90666667 | R22: =N22+O22+Q22 -> 1.7185675 | S22: =R22*J22 -> 13.069706 | T22: =L22*F22*J22 -> 60.84 | U22: =IFERROR((T22-S22)/T22,0) -> 0.78517906 | V22: =IFERROR((T22-S22)/(J22*Producto!$D$11/60),0) -> 125.62865 | W22: 30 | X22: 6.9 | Y22: =IFERROR(X22/W22*1000,0) -> 230 | Z22: =IFERROR(K22/W22,0) -> 5.3333333 | AA22: =IF(W22<=15,Producto!$D$12,Producto!$D$13) -> 0.17 | AB22: =Z22*X22*J22 -> 279.864 | AC22: =(N22+O22+Z22*AA22)*J22 -> 13.069706 | AD22: 15 | AE22: 1.55 | AF22: =IFERROR(AE22/AD22*1000,0) -> 103.33333 | AG22: =IFERROR(K22/AD22,0) -> 10.666667 | AH22: =IF(AD22<=15,Producto!$D$12,Producto!$D$13) -> 0.1 | AI22: =AG22*AE22*J22 -> 125.736 | AJ22: =(N22+O22+AG22*AH22)*J22 -> 14.286506
A23: Brócoli calabrese | B23: PROVISIONAL | C23: 1 | D23: 0.04 | E23: 30 | F23: 1.5 | G23: =F23/E23*1000 -> 50 | H23: 4 | I23: 3 | J23: =Producto!$D$6/(H23+Producto!$D$7) -> 7.605 | K23: 170 | L23: =K23/E23 -> 5.6666667 | M23: =J23*K23/1000 -> 1.29285 | N23: 0.484 | O23: =Producto!$D$14 -> 0.37190083 | P23: =IF(E23<=15,Producto!$D$12,Producto!$D$13) -> 0.17 | Q23: =L23*P23 -> 0.96333333 | R23: =N23+O23+Q23 -> 1.8192342 | S23: =R23*J23 -> 13.835276 | T23: =L23*F23*J23 -> 64.6425 | U23: =IFERROR((T23-S23)/T23,0) -> 0.78597245 | V23: =IFERROR((T23-S23)/(J23*Producto!$D$11/60),0) -> 133.61532 | W23: 15 | X23: 4 | Y23: =IFERROR(X23/W23*1000,0) -> 266.66667 | Z23: =IFERROR(K23/W23,0) -> 11.333333 | AA23: =IF(W23<=15,Producto!$D$12,Producto!$D$13) -> 0.1 | AB23: =Z23*X23*J23 -> 344.76 | AC23: =(N23+O23+Z23*AA23)*J23 -> 15.128126 | AD23: 15 | AE23: 1.85 | AF23: =IFERROR(AE23/AD23*1000,0) -> 123.33333 | AG23: =IFERROR(K23/AD23,0) -> 11.333333 | AH23: =IF(AD23<=15,Producto!$D$12,Producto!$D$13) -> 0.1 | AI23: =AG23*AE23*J23 -> 159.4515 | AJ23: =(N23+O23+AG23*AH23)*J23 -> 15.128126
A24: Amaranto rojo | B24: PROVISIONAL | C24: 1 | D24: 0.03 | E24: 30 | F24: 3 | G24: =F24/E24*1000 -> 100 | H24: 9 | I24: 3 | J24: =Producto!$D$6/(H24+Producto!$D$7) -> 3.38 | K24: 80 | L24: =K24/E24 -> 2.6666667 | M24: =J24*K24/1000 -> 0.2704 | N24: 0.45 | O24: =Producto!$D$14 -> 0.37190083 | P24: =IF(E24<=15,Producto!$D$12,Producto!$D$13) -> 0.17 | Q24: =L24*P24 -> 0.45333333 | R24: =N24+O24+Q24 -> 1.2752342 | S24: =R24*J24 -> 4.3102915 | T24: =L24*F24*J24 -> 27.04 | U24: =IFERROR((T24-S24)/T24,0) -> 0.84059573 | V24: =IFERROR((T24-S24)/(J24*Producto!$D$11/60),0) -> 134.49532 | W24: 30 | X24: 10.8 | Y24: =IFERROR(X24/W24*1000,0) -> 360 | Z24: =IFERROR(K24/W24,0) -> 2.6666667 | AA24: =IF(W24<=15,Producto!$D$12,Producto!$D$13) -> 0.17 | AB24: =Z24*X24*J24 -> 97.344 | AC24: =(N24+O24+Z24*AA24)*J24 -> 4.3102915 | AD24: 15 | AE24: 1.65 | AF24: =IFERROR(AE24/AD24*1000,0) -> 110 | AG24: =IFERROR(K24/AD24,0) -> 5.3333333 | AH24: =IF(AD24<=15,Producto!$D$12,Producto!$D$13) -> 0.1 | AI24: =AG24*AE24*J24 -> 29.744 | AJ24: =(N24+O24+AG24*AH24)*J24 -> 4.5806915
A25: Rábano red | B25: INACTIVO | C25: 0 | D25: 0 | E25: 30 | F25: 1.3 | G25: =F25/E25*1000 -> 43.333333 | H25: 2 | I25: 3 | J25: =Producto!$D$6/(H25+Producto!$D$7) -> 15.21 | K25: 200 | L25: =K25/E25 -> 6.6666667 | M25: =J25*K25/1000 -> 3.042 | N25: 0.3 | O25: =Producto!$D$14 -> 0.37190083 | P25: =IF(E25<=15,Producto!$D$12,Producto!$D$13) -> 0.17 | Q25: =L25*P25 -> 1.1333333 | R25: =N25+O25+Q25 -> 1.8052342 | S25: =R25*J25 -> 27.457612 | T25: =L25*F25*J25 -> 131.82 | U25: =IFERROR((T25-S25)/T25,0) -> 0.79170375 | V25: =IFERROR((T25-S25)/(J25*Producto!$D$11/60),0) -> 137.22865 | W25: 30 | X25: 6.2 | Y25: =IFERROR(X25/W25*1000,0) -> 206.66667 | Z25: =IFERROR(K25/W25,0) -> 6.6666667 | AA25: =IF(W25<=15,Producto!$D$12,Producto!$D$13) -> 0.17 | AB25: =Z25*X25*J25 -> 628.68 | AC25: =(N25+O25+Z25*AA25)*J25 -> 27.457612 | AD25: =E25 -> 30 | AE25: =F25 -> 1.3 | AF25: =IFERROR(AE25/AD25*1000,0) -> 43.333333 | AG25: =IFERROR(K25/AD25,0) -> 6.6666667 | AH25: =IF(AD25<=15,Producto!$D$12,Producto!$D$13) -> 0.17 | AI25: =AG25*AE25*J25 -> 131.82 | AJ25: =(N25+O25+AG25*AH25)*J25 -> 27.457612
A26: Guisante (pea shoots) | B26: INACTIVO | C26: 0 | D26: 0 | E26: 30 | F26: 1.44 | G26: =F26/E26*1000 -> 48 | H26: 8 | I26: 3 | J26: =Producto!$D$6/(H26+Producto!$D$7) -> 3.8025 | K26: 220 | L26: =K26/E26 -> 7.3333333 | M26: =J26*K26/1000 -> 0.83655 | N26: 1.5 | O26: =Producto!$D$14 -> 0.37190083 | P26: =IF(E26<=15,Producto!$D$12,Producto!$D$13) -> 0.17 | Q26: =L26*P26 -> 1.2466667 | R26: =N26+O26+Q26 -> 3.1185675 | S26: =R26*J26 -> 11.858353 | T26: =L26*F26*J26 -> 40.1544 | U26: =IFERROR((T26-S26)/T26,0) -> 0.70468111 | V26: =IFERROR((T26-S26)/(J26*Producto!$D$11/60),0) -> 148.82865 | W26: 30 | X26: 6 | Y26: =IFERROR(X26/W26*1000,0) -> 200 | Z26: =IFERROR(K26/W26,0) -> 7.3333333 | AA26: =IF(W26<=15,Producto!$D$12,Producto!$D$13) -> 0.17 | AB26: =Z26*X26*J26 -> 167.31 | AC26: =(N26+O26+Z26*AA26)*J26 -> 11.858353 | AD26: =E26 -> 30 | AE26: =F26 -> 1.44 | AF26: =IFERROR(AE26/AD26*1000,0) -> 48 | AG26: =IFERROR(K26/AD26,0) -> 7.3333333 | AH26: =IF(AD26<=15,Producto!$D$12,Producto!$D$13) -> 0.17 | AI26: =AG26*AE26*J26 -> 40.1544 | AJ26: =(N26+O26+AG26*AH26)*J26 -> 11.858353
A27: Remolacha roja | B27: INACTIVO | C27: 0 | D27: 0 | E27: 30 | F27: 1.8 | G27: =F27/E27*1000 -> 60 | H27: 8 | I27: 4 | J27: =Producto!$D$6/(H27+Producto!$D$7) -> 3.8025 | K27: 150 | L27: =K27/E27 -> 5 | M27: =J27*K27/1000 -> 0.570375 | N27: 0.6 | O27: =Producto!$D$14 -> 0.37190083 | P27: =IF(E27<=15,Producto!$D$12,Producto!$D$13) -> 0.17 | Q27: =L27*P27 -> 0.85 | R27: =N27+O27+Q27 -> 1.8219008 | S27: =R27*J27 -> 6.9277779 | T27: =L27*F27*J27 -> 34.2225 | U27: =IFERROR((T27-S27)/T27,0) -> 0.79756657 | V27: =IFERROR((T27-S27)/(J27*Producto!$D$11/60),0) -> 143.56198 | W27: 30 | X27: 8.05 | Y27: =IFERROR(X27/W27*1000,0) -> 268.33333 | Z27: =IFERROR(K27/W27,0) -> 5 | AA27: =IF(W27<=15,Producto!$D$12,Producto!$D$13) -> 0.17 | AB27: =Z27*X27*J27 -> 153.05062 | AC27: =(N27+O27+Z27*AA27)*J27 -> 6.9277779 | AD27: =E27 -> 30 | AE27: =F27 -> 1.8 | AF27: =IFERROR(AE27/AD27*1000,0) -> 60 | AG27: =IFERROR(K27/AD27,0) -> 5 | AH27: =IF(AD27<=15,Producto!$D$12,Producto!$D$13) -> 0.17 | AI27: =AG27*AE27*J27 -> 34.2225 | AJ27: =(N27+O27+AG27*AH27)*J27 -> 6.9277779
A28: Remolacha amarilla | B28: INACTIVO | C28: 0 | D28: 0 | E28: 30 | F28: 1.8 | G28: =F28/E28*1000 -> 60 | H28: 8 | I28: 4 | J28: =Producto!$D$6/(H28+Producto!$D$7) -> 3.8025 | K28: 115 | L28: =K28/E28 -> 3.8333333 | M28: =J28*K28/1000 -> 0.4372875 | N28: 0.6 | O28: =Producto!$D$14 -> 0.37190083 | P28: =IF(E28<=15,Producto!$D$12,Producto!$D$13) -> 0.17 | Q28: =L28*P28 -> 0.65166667 | R28: =N28+O28+Q28 -> 1.6235675 | S28: =R28*J28 -> 6.1736154 | T28: =L28*F28*J28 -> 26.23725 | U28: =IFERROR((T28-S28)/T28,0) -> 0.76470036 | V28: =IFERROR((T28-S28)/(J28*Producto!$D$11/60),0) -> 105.52865 | W28: 30 | X28: 8.05 | Y28: =IFERROR(X28/W28*1000,0) -> 268.33333 | Z28: =IFERROR(K28/W28,0) -> 3.8333333 | AA28: =IF(W28<=15,Producto!$D$12,Producto!$D$13) -> 0.17 | AB28: =Z28*X28*J28 -> 117.33881 | AC28: =(N28+O28+Z28*AA28)*J28 -> 6.1736154 | AD28: =E28 -> 30 | AE28: =F28 -> 1.8 | AF28: =IFERROR(AE28/AD28*1000,0) -> 60 | AG28: =IFERROR(K28/AD28,0) -> 3.8333333 | AH28: =IF(AD28<=15,Producto!$D$12,Producto!$D$13) -> 0.17 | AI28: =AG28*AE28*J28 -> 26.23725 | AJ28: =(N28+O28+AG28*AH28)*J28 -> 6.1736154
A29: Hinojo | B29: INACTIVO | C29: 0 | D29: 0 | E29: 30 | F29: 2.6 | G29: =F29/E29*1000 -> 86.666667 | H29: 12 | I29: 5 | J29: =Producto!$D$6/(H29+Producto!$D$7) -> 2.535 | K29: 90 | L29: =K29/E29 -> 3 | M29: =J29*K29/1000 -> 0.22815 | N29: 0.5 | O29: =Producto!$D$14 -> 0.37190083 | P29: =IF(E29<=15,Producto!$D$12,Producto!$D$13) -> 0.17 | Q29: =L29*P29 -> 0.51 | R29: =N29+O29+Q29 -> 1.3819008 | S29: =R29*J29 -> 3.5031186 | T29: =L29*F29*J29 -> 19.773 | U29: =IFERROR((T29-S29)/T29,0) -> 0.82283323 | V29: =IFERROR((T29-S29)/(J29*Producto!$D$11/60),0) -> 128.36198 | W29: 30 | X29: 9.3 | Y29: =IFERROR(X29/W29*1000,0) -> 310 | Z29: =IFERROR(K29/W29,0) -> 3 | AA29: =IF(W29<=15,Producto!$D$12,Producto!$D$13) -> 0.17 | AB29: =Z29*X29*J29 -> 70.7265 | AC29: =(N29+O29+Z29*AA29)*J29 -> 3.5031186 | AD29: =E29 -> 30 | AE29: =F29 -> 2.6 | AF29: =IFERROR(AE29/AD29*1000,0) -> 86.666667 | AG29: =IFERROR(K29/AD29,0) -> 3 | AH29: =IF(AD29<=15,Producto!$D$12,Producto!$D$13) -> 0.17 | AI29: =AG29*AE29*J29 -> 19.773 | AJ29: =(N29+O29+AG29*AH29)*J29 -> 3.5031186
A30: Cebolla Barbra | B30: INACTIVO | C30: 0 | D30: 0 | E30: 30 | F30: 2.4 | G30: =F30/E30*1000 -> 80 | H30: 12 | I30: 6 | J30: =Producto!$D$6/(H30+Producto!$D$7) -> 2.535 | K30: 75 | L30: =K30/E30 -> 2.5 | M30: =J30*K30/1000 -> 0.190125 | N30: 0.6 | O30: =Producto!$D$14 -> 0.37190083 | P30: =IF(E30<=15,Producto!$D$12,Producto!$D$13) -> 0.17 | Q30: =L30*P30 -> 0.425 | R30: =N30+O30+Q30 -> 1.3969008 | S30: =R30*J30 -> 3.5411436 | T30: =L30*F30*J30 -> 15.21 | U30: =IFERROR((T30-S30)/T30,0) -> 0.7671832 | V30: =IFERROR((T30-S30)/(J30*Producto!$D$11/60),0) -> 92.061983 | W30: 30 | X30: 9.3 | Y30: =IFERROR(X30/W30*1000,0) -> 310 | Z30: =IFERROR(K30/W30,0) -> 2.5 | AA30: =IF(W30<=15,Producto!$D$12,Producto!$D$13) -> 0.17 | AB30: =Z30*X30*J30 -> 58.93875 | AC30: =(N30+O30+Z30*AA30)*J30 -> 3.5411436 | AD30: =E30 -> 30 | AE30: =F30 -> 2.4 | AF30: =IFERROR(AE30/AD30*1000,0) -> 80 | AG30: =IFERROR(K30/AD30,0) -> 2.5 | AH30: =IF(AD30<=15,Producto!$D$12,Producto!$D$13) -> 0.17 | AI30: =AG30*AE30*J30 -> 15.21 | AJ30: =(N30+O30+AG30*AH30)*J30 -> 3.5411436
A31: Cebollino chino | B31: INACTIVO | C31: 0 | D31: 0 | E31: 30 | F31: 2.6 | G31: =F31/E31*1000 -> 86.666667 | H31: 14 | I31: 6 | J31: =Producto!$D$6/(H31+Producto!$D$7) -> 2.1728571 | K31: 70 | L31: =K31/E31 -> 2.3333333 | M31: =J31*K31/1000 -> 0.1521 | N31: 0.7 | O31: =Producto!$D$14 -> 0.37190083 | P31: =IF(E31<=15,Producto!$D$12,Producto!$D$13) -> 0.17 | Q31: =L31*P31 -> 0.39666667 | R31: =N31+O31+Q31 -> 1.4685675 | S31: =R31*J31 -> 3.1909874 | T31: =L31*F31*J31 -> 13.182 | U31: =IFERROR((T31-S31)/T31,0) -> 0.75792844 | V31: =IFERROR((T31-S31)/(J31*Producto!$D$11/60),0) -> 91.961983 | W31: 30 | X31: 10.15 | Y31: =IFERROR(X31/W31*1000,0) -> 338.33333 | Z31: =IFERROR(K31/W31,0) -> 2.3333333 | AA31: =IF(W31<=15,Producto!$D$12,Producto!$D$13) -> 0.17 | AB31: =Z31*X31*J31 -> 51.4605 | AC31: =(N31+O31+Z31*AA31)*J31 -> 3.1909874 | AD31: =E31 -> 30 | AE31: =F31 -> 2.6 | AF31: =IFERROR(AE31/AD31*1000,0) -> 86.666667 | AG31: =IFERROR(K31/AD31,0) -> 2.3333333 | AH31: =IF(AD31<=15,Producto!$D$12,Producto!$D$13) -> 0.17 | AI31: =AG31*AE31*J31 -> 13.182 | AJ31: =(N31+O31+AG31*AH31)*J31 -> 3.1909874
A32: PORTFOLIO ACTIVO (media ponderada por % de luz) | D32: =SUMPRODUCT(C16:C31,D16:D31) -> 1 | J32: =SUMPRODUCT(C16:C31,D16:D31,J16:J31) -> 6.8941986 | M32: =SUMPRODUCT(C16:C31,D16:D31,M16:M31) -> 1.2430328 | S32: =SUMPRODUCT(C16:C31,D16:D31,S16:S31) -> 9.5799912 | T32: =SUMPRODUCT(C16:C31,D16:D31,T16:T31) -> 54.283283 | U32: =IFERROR((T32-S32)/T32,0) -> 0.82351857 | V32: =IFERROR((T32-S32)/(J32*Producto!$D$11/60),0) -> 129.68379 | AB32: =SUMPRODUCT(C16:C31,D16:D31,AB16:AB31) -> 214.84381 | AC32: =SUMPRODUCT(C16:C31,D16:D31,AC16:AC31) -> 10.582125 | AI32: =SUMPRODUCT(C16:C31,D16:D31,AI16:AI31) -> 114.12894 | AJ32: =SUMPRODUCT(C16:C31,D16:D31,AJ16:AJ31) -> 11.214373
A34: Comprobación: % de luz de las ACTIVAS suma | D34: =IF(ABS(D32-1)<0.001,"OK — 100%","REVISAR: "&TEXT(D32,"0%")) -> OK — 100% | F34: MARGEN €/HORA de trabajo: la métrica que manda cuando la mano de obra es el cuello de botella. Compárala con el coste/hora cargado (~14 €/h).
A35: Precio medio ponderado MAYORISTA (€/kg) | D35: =IFERROR(T32/M32,0) -> 43.670034
A36: Margen bruto del portfolio (s/ ingreso directo) | D36: =U32 -> 0.82351857
A38: REVISIÓN OPERATIVA (socio de producción) — 23/09/2026
A39: Rendimientos actualizados: cilantro 120→145 g · albahaca 100→90 g · rábano daikon y rose 175→245 g (solo los ACTIVOS).
A40: PENDIENTE DE CONFIRMAR: 'Rábano red' (INACTIVO) sigue en 200 g y 'Micromezclum' (mix de 7 variedades) sigue en 170 g. Si el mix lleva rábano, su rendimiento sube también — revisar con producción.
A41: OJO: los rábanos ACTIVOS tienen 3 días de luz (10,1 ciclos/mes). El 'rábano de ciclo corto' del deck (2 días de luz, 15 ciclos/mes) es el rábano red, que está INACTIVO.
A43: PRECIO MEDIO PONDERADO POR CANAL (tarifa, sin índice de escenario)
A44: Mayorista (distribución, Mercamadrid) | D44: =IFERROR(T32/M32,0) -> 43.670034
...

Sheet Tarifas
A1: ROOTFLOW — Tarifas reales por cliente, variedad y formato
A2: Pega aquí el export del ERP. El precio medio ponderado por variedad se calcula solo y se copia a mano en Producto!F (Precio DIR €/tarrina). NADA de esta hoja alimenta el modelo todavía: primero hay que revisar los datos.
A4: Cliente | B4: Variedad | C4: Canal (DIR/DIST) | D4: Formato (g/tarrina) | E4: Precio €/tarrina | F4: Tarrinas/mes | G4: €/mes — calc | H4: kg/mes — calc | I4: €/kg — calc | K4: RESUMEN POR VARIEDAD (se rellena solo desde la tabla)
G5: =IF(N(E5)*N(F5)=0,"",E5*F5) | H5: =IF(N(D5)*N(F5)=0,"",D5*F5/1000) | I5: =IFERROR(G5/H5,"") | K5: Variedad | L5: €/mes | M5: kg/mes | N5: €/kg ponderado | O5: €/tarrina medio
G6: =IF(N(E6)*N(F6)=0,"",E6*F6) | H6: =IF(N(D6)*N(F6)=0,"",D6*F6/1000) | I6: =IFERROR(G6/H6,"") | K6: =Producto!A16 -> Micromezclum (mix 7 var.) | L6: =SUMIF($B$5:$B$204,$K6,$G$5:$G$204) -> 0 | M6: =SUMIF($B$5:$B$204,$K6,$H$5:$H$204) -> 0 | N6: =IFERROR(L6/M6,"") | O6: =IFERROR(SUMIF($B$5:$B$204,$K6,$G$5:$G$204)/SUMIF($B$5:$B$204,$K6,$F$5:$F$204),"")
G7: =IF(N(E7)*N(F7)=0,"",E7*F7) | H7: =IF(N(D7)*N(F7)=0,"",D7*F7/1000) | I7: =IFERROR(G7/H7,"") | K7: =Producto!A17 -> Cilantro split | L7: =SUMIF($B$5:$B$204,$K7,$G$5:$G$204) -> 0 | M7: =SUMIF($B$5:$B$204,$K7,$H$5:$H$204) -> 0 | N7: =IFERROR(L7/M7,"") | O7: =IFERROR(SUMIF($B$5:$B$204,$K7,$G$5:$G$204)/SUMIF($B$5:$B$204,$K7,$F$5:$F$204),"")
G8: =IF(N(E8)*N(F8)=0,"",E8*F8) | H8: =IF(N(D8)*N(F8)=0,"",D8*F8/1000) | I8: =IFERROR(G8/H8,"") | K8: =Producto!A18 -> Albahaca genovesa | L8: =SUMIF($B$5:$B$204,$K8,$G$5:$G$204) -> 0 | M8: =SUMIF($B$5:$B$204,$K8,$H$5:$H$204) -> 0 | N8: =IFERROR(L8/M8,"") | O8: =IFERROR(SUMIF($B$5:$B$204,$K8,$G$5:$G$204)/SUMIF($B$5:$B$204,$K8,$F$5:$F$204),"")
G9: =IF(N(E9)*N(F9)=0,"",E9*F9) | H9: =IF(N(D9)*N(F9)=0,"",D9*F9/1000) | I9: =IFERROR(G9/H9,"") | K9: =Producto!A19 -> Rábano daikon | L9: =SUMIF($B$5:$B$204,$K9,$G$5:$G$204) -> 0 | M9: =SUMIF($B$5:$B$204,$K9,$H$5:$H$204) -> 0 | N9: =IFERROR(L9/M9,"") | O9: =IFERROR(SUMIF($B$5:$B$204,$K9,$G$5:$G$204)/SUMIF($B$5:$B$204,$K9,$F$5:$F$204),"")
G10: =IF(N(E10)*N(F10)=0,"",E10*F10) | H10: =IF(N(D10)*N(F10)=0,"",D10*F10/1000) | I10: =IFERROR(G10/H10,"") | K10: =Producto!A20 -> Rúcula rocket | L10: =SUMIF($B$5:$B$204,$K10,$G$5:$G$204) -> 0 | M10: =SUMIF($B$5:$B$204,$K10,$H$5:$H$204) -> 0 | N10: =IFERROR(L10/M10,"") | O10: =IFERROR(SUMIF($B$5:$B$204,$K10,$G$5:$G$204)/SUMIF($B$5:$B$204,$K10,$F$5:$F$204),"")
G11: =IF(N(E11)*N(F11)=0,"",E11*F11) | H11: =IF(N(D11)*N(F11)=0,"",D11*F11/1000) | I11: =IFERROR(G11/H11,"") | K11: =Producto!A21 -> Rábano rose | L11: =SUMIF($B$5:$B$204,$K11,$G$5:$G$204) -> 0 | M11: =SUMIF($B$5:$B$204,$K11,$H$5:$H$204) -> 0 | N11: =IFERROR(L11/M11,"") | O11: =IFERROR(SUMIF($B$5:$B$204,$K11,$G$5:$G$204)/SUMIF($B$5:$B$204,$K11,$F$5:$F$204),"")
G12: =IF(N(E12)*N(F12)=0,"",E12*F12) | H12: =IF(N(D12)*N(F12)=0,"",D12*F12/1000) | I12: =IFERROR(G12/H12,"") | K12: =Producto!A22 -> Mostaza Red Giant | L12: =SUMIF($B$5:$B$204,$K12,$G$5:$G$204) -> 0 | M12: =SUMIF($B$5:$B$204,$K12,$H$5:$H$204) -> 0 | N12: =IFERROR(L12/M12,"") | O12: =IFERROR(SUMIF($B$5:$B$204,$K12,$G$5:$G$204)/SUMIF($B$5:$B$204,$K12,$F$5:$F$204),"")
G13: =IF(N(E13)*N(F13)=0,"",E13*F13) | H13: =IF(N(D13)*N(F13)=0,"",D13*F13/1000) | I13: =IFERROR(G13/H13,"") | K13: =Producto!A23 -> Brócoli calabrese | L13: =SUMIF($B$5:$B$204,$K13,$G$5:$G$204) -> 0 | M13: =SUMIF($B$5:$B$204,$K13,$H$5:$H$204) -> 0 | N13: =IFERROR(L13/M13,"") | O13: =IFERROR(SUMIF($B$5:$B$204,$K13,$G$5:$G$204)/SUMIF($B$5:$B$204,$K13,$F$5:$F$204),"")
G14: =IF(N(E14)*N(F14)=0,"",E14*F14) | H14: =IF(N(D14)*N(F14)=0,"",D14*F14/1000) | I14: =IFERROR(G14/H14,"") | K14: =Producto!A24 -> Amaranto rojo | L14: =SUMIF($B$5:$B$204,$K14,$G$5:$G$204) -> 0 | M14: =SUMIF($B$5:$B$204,$K14,$H$5:$H$204) -> 0 | N14: =IFERROR(L14/M14,"") | O14: =IFERROR(SUMIF($B$5:$B$204,$K14,$G$5:$G$204)/SUMIF($B$5:$B$204,$K14,$F$5:$F$204),"")
G15: =IF(N(E15)*N(F15)=0,"",E15*F15) | H15: =IF(N(D15)*N(F15)=0,"",D15*F15/1000) | I15: =IFERROR(G15/H15,"") | K15: =Producto!A25 -> Rábano red | L15: =SUMIF($B$5:$B$204,$K15,$G$5:$G$204) -> 0 | M15: =SUMIF($B$5:$B$204,$K15,$H$5:$H$204) -> 0 | N15: =IFERROR(L15/M15,"") | O15: =IFERROR(SUMIF($B$5:$B$204,$K15,$G$5:$G$204)/SUMIF($B$5:$B$204,$K15,$F$5:$F$204),"")
G16: =IF(N(E16)*N(F16)=0,"",E16*F16) | H16: =IF(N(D16)*N(F16)=0,"",D16*F16/1000) | I16: =IFERROR(G16/H16,"") | K16: =Producto!A26 -> Guisante (pea shoots) | L16: =SUMIF($B$5:$B$204,$K16,$G$5:$G$204) -> 0 | M16: =SUMIF($B$5:$B$204,$K16,$H$5:$H$204) -> 0 | N16: =IFERROR(L16/M16,"") | O16: =IFERROR(SUMIF($B$5:$B$204,$K16,$G$5:$G$204)/SUMIF($B$5:$B$204,$K16,$F$5:$F$204),"")
G17: =IF(N(E17)*N(F17)=0,"",E17*F17) | H17: =IF(N(D17)*N(F17)=0,"",D17*F17/1000) | I17: =IFERROR(G17/H17,"") | K17: =Producto!A27 -> Remolacha roja | L17: =SUMIF($B$5:$B$204,$K17,$G$5:$G$204) -> 0 | M17: =SUMIF($B$5:$B$204,$K17,$H$5:$H$204) -> 0 | N17: =IFERROR(L17/M17,"") | O17: =IFERROR(SUMIF($B$5:$B$204,$K17,$G$5:$G$204)/SUMIF($B$5:$B$204,$K17,$F$5:$F$204),"")
... G21: =IF(N(E21)*N(F21)=0,"",E21*F21) | H21: =IF(N(D21)*N(F21)=0,"",D21*F21/1000) | I21: =IFERROR(G21/H21,"") | K21: =Producto!A31 -> Cebollino chino | L21: =SUMIF($B$5:$B$204,$K21,$G$5:$G$204) -> 0 | M21: =SUMIF($B$5:$B$204,$K21,$H$5:$H$204) -> 0 | N21: =IFERROR(L21/M21,"") | O21: =IFERROR(SUMIF($B$5:$B$204,$K21,$G$5:$G$204)/SUMIF($B$5:$B$204,$K21,$F$5:$F$204),"")
G22: =IF(N(E22)*N(F22)=0,"",E22*F22) | H22: =IF(N(D22)*N(F22)=0,"",D22*F22/1000) | I22: =IFERROR(G22/H22,"")
G23: =IF(N(E23)*N(F23)=0,"",E23*F23) | H23: =IF(N(D23)*N(F23)=0,"",D23*F23/1000) | I23: =IFERROR(G23/H23,"") | K23: TOTAL / PONDERADO | L23: =SUM(L6:L21) -> 0 | M23: =SUM(M6:M21) -> 0 | N23: =IFERROR(L23/M23,"")
G24: =IF(N(E24)*N(F24)=0,"",E24*F24) | H24: =IF(N(D24)*N(F24)=0,"",D24*F24/1000) | I24: =IFERROR(G24/H24,"")
G25: =IF(N(E25)*N(F25)=0,"",E25*F25) | H25: =IF(N(D25)*N(F25)=0,"",D25*F25/1000) | I25: =IFERROR(G25/H25,"") | K25: Precio medio ponderado que usa HOY el modelo (Producto!D35): | N25: =Producto!D35 -> 43.670034
G26: =IF(N(E26)*N(F26)=0,"",E26*F26) | H26: =IF(N(D26)*N(F26)=0,"",D26*F26/1000) | I26: =IFERROR(G26/H26,"") | K26: Diferencia vs. tarifas reales (€/kg): | N26: =IFERROR(N23-N25,"")
G27: =IF(N(E27)*N(F27)=0,"",E27*F27) | H27: =IF(N(D27)*N(F27)=0,"",D27*F27/1000) | I27: =IFERROR(G27/H27,"")
G28: =IF(N(E28)*N(F28)=0,"",E28*F28) | H28: =IF(N(D28)*N(F28)=0,"",D28*F28/1000) | I28: =IFERROR(G28/H28,"")
G29: =IF(N(E29)*N(F29)=0,"",E29*F29) | H29: =IF(N(D29)*N(F29)=0,"",D29*F29/1000) | I29: =IFERROR(G29/H29,"")
G30: =IF(N(E30)*N(F30)=0,"",E30*F30) | H30: =IF(N(D30)*N(F30)=0,"",D30*F30/1000) | I30: =IFERROR(G30/H30,"")
G31: =IF(N(E31)*N(F31)=0,"",E31*F31) | H31: =IF(N(D31)*N(F31)=0,"",D31*F31/1000) | I31: =IFERROR(G31/H31,"")
G32: =IF(N(E32)*N(F32)=0,"",E32*F32) | H32: =IF(N(D32)*N(F32)=0,"",D32*F32/1000) | I32: =IFERROR(G32/H32,"")
G33: =IF(N(E33)*N(F33)=0,"",E33*F33) | H33: =IF(N(D33)*N(F33)=0,"",D33*F33/1000) | I33: =IFERROR(G33/H33,"")
G34: =IF(N(E34)*N(F34)=0,"",E34*F34) | H34: =IF(N(D34)*N(F34)=0,"",D34*F34/1000) | I34: =IFERROR(G34/H34,"")
G35: =IF(N(E35)*N(F35)=0,"",E35*F35) | H35: =IF(N(D35)*N(F35)=0,"",D35*F35/1000) | I35: =IFERROR(G35/H35,"")
G36: =IF(N(E36)*N(F36)=0,"",E36*F36) | H36: =IF(N(D36)*N(F36)=0,"",D36*F36/1000) | I36: =IFERROR(G36/H36,"")
G37: =IF(N(E37)*N(F37)=0,"",E37*F37) | H37: =IF(N(D37)*N(F37)=0,"",D37*F37/1000) | I37: =IFERROR(G37/H37,"")
G38: =IF(N(E38)*N(F38)=0,"",E38*F38) | H38: =IF(N(D38)*N(F38)=0,"",D38*F38/1000) | I38: =IFERROR(G38/H38,"")
... G204: =IF(N(E204)*N(F204)=0,"",E204*F204) | H204: =IF(N(D204)*N(F204)=0,"",D204*F204/1000) | I204: =IFERROR(G204/H204,"")

Sheet Restaurantes
A1: ROOTFLOW — Línea RESTAURANTES (reparto propio con riders desde un microhub)
A2: Segunda línea de negocio. La nave produce; una parte se reserva para restaurantes de las 8 zonas calientes, que reciben dos pedidos por semana con riders desde una cámara refrigerada alquilada. Celdas amarillas = inputs. El resto se calcula. La columna F sigue al selector de escenario (Hipótesis!C4).
A4: Concepto | B4: Unidad | C4: Conservador | D4: Base | E4: Optimista | F4: Activo | G4: Fuente / nota
A6: 1 · CUÁNTO DE LA NAVE VA A RESTAURANTES — la palanca del modelo
A7: % de la capacidad de la nave que se destina a restaurantes (objetivo) | B7: % | D7: 0.05 | G7: LA PALANCA. Sale de la distribución: la ocupación total no sube, cambia a quién se vende. 0 % = solo distribución. 5 % = reparto de COSTES_ROOTFLOW (5 % restaurante).
A8: Mes de lanzamiento de la línea | B8: mes | D8: 1 | G8: Mes del modelo en que arrancan microhub, riders y lanzadera.
A9: Meses de rampa hasta alcanzar el objetivo | B9: meses | C9: 36 | D9: 24 | E9: 18 | F9: =CHOOSE(Hipótesis!$C$4,C9,D9,E9) -> 24 | G9: Ritmo comercial. Base: 24 meses (~5 restaurantes netos nuevos al mes). Conservador más lento.
A10: ¿Limitar al mercado real de las zonas? (1 = sí) | B10: 1/0 | D10: 1 | G10: Con 1, nunca se vende a más restaurantes de los que el techo de abajo permite.
A11: Restaurantes abiertos en las 8 zonas (censo municipal) | B11: nº | D11: =D83 -> 585 | G11: Enlazado a la tabla de zonas (sección 7).
A12: Penetración máxima alcanzable | B12: % | D12: 0.3 | G12: Supuesto prudente: 3 de cada 10 restaurantes de la zona. Validar con los primeros meses.
A13: TECHO de restaurantes alcanzables | B13: nº | D13: =D11*D12 -> 175.5
A15: 2 · TICKET, FRECUENCIA Y PRECIO (modelo MICROHUB_COSTES · hoja Facturación)
A16: Cliente MÍNIMO — % de restaurantes | B16: % | D16: 0.55 | G16: MICROHUB_COSTES.xlsx
A17: Cliente MÍNIMO — ticket por pedido | B17: € | D17: 18.5
A18: Cliente MEDIO — % de restaurantes | B18: % | D18: 0.3
A19: Cliente MEDIO — ticket por pedido | B19: € | D19: 30
A20: Cliente PREMIUM — % de restaurantes | B20: % | D20: 0.15
A21: Cliente PREMIUM — ticket por pedido | B21: € | D21: 65
A22: TICKET MEDIO PONDERADO por pedido | B22: € | D22: =D16*D17+D18*D19+D20*D21 -> 28.925 | G22: 28,93 € con el mix de MICROHUB.
A23: Comprobación del mix (debe sumar 100 %) | D23: =IF(ABS(D16+D18+D20-1)<0.0001,"OK","REVISAR") -> OK
A24: Pedidos por semana y restaurante | B24: nº | D24: 2 | G24: Dos pedidos para tenerlo siempre fresco.
A25: Semanas por mes | B25: nº | D25: =Producto!$D$6/7 -> 4.3457143
A26: Ajuste de PRECIO restaurantes (índice sobre la tarifa de 30 g) | B26: índice | C26: 0.9 | D26: 1 | E26: 1.1 | F26: =CHOOSE(Hipótesis!$C$4,C26,D26,E26) -> 1 | G26: La tarifa de 30 g es la de MENOR €/g. Conservador = descuento de captación; optimista = más 15 g y 5 g.
A27: Merma + impagados restaurantes | B27: % | D27: 0.1 | G27: Igual que distribución.
A28: Días de cobro restaurantes | B28: días | D28: 30 | G28: Prudente. Sin factoring: son facturas pequeñas.
A29: Porte cobrado a pedidos pequeños (0 = no se cobra) | B29: €/pedido | D29: 0 | G29: Palanca de upside: la tarifa de referencia cobra 12 € a pedidos <35 €. Desactivado.
A30: % de pedidos que pagarían porte | B30: % | D30: =D16 -> 0.55 | G30: El segmento 'mínimo'.
A31: Estacionalidad: demanda de restaurantes en AGOSTO (factor) | B31: x | D31: 0.15 | G31: -85 % en agosto (MICROHUB). Esa producción no se siembra.
A32: Mes natural en que arranca el modelo (mes 1) | B32: 1-12 | D32: 4 | G32: Abril de 2027 (nave tras cerrar la financiación). Solo sirve para ubicar agosto.
A34: 3 · REPARTO CON RIDERS (autónomos, bici/moto, tipo Glovo)
A35: Días de reparto al mes | B35: días | D35: 25 | G35: MICROHUB_COSTES.xlsx
A36: Entregas por hora y rider (salida con la bolsa llena) | B36: entregas/h | C36: 5 | D36: 7 | E36: 8 | F36: =CHOOSE(Hipótesis!$C$4,C36,D36,E36) -> 7 | G36: 7-8 por salida de una hora (dato de producción). Conservador = 5.
A37: Coste rider (coste empresa) | B37: €/h | D37: 16 | G37: Cobran 12-13 €/h brutos; 16 €/h coste empresa.
A38: Ventana de reparto por rider y día | B38: h/día | D38: 5 | G38: Mañana antes del servicio + tarde antes de cenas. Fija cuándo hace falta el 2º rider.
A39: Horas mínimas pagadas por rider activo y día | B39: h/día | D39: 2 | G39: Prudente: con pocos pedidos se paga igualmente un turno mínimo.
A40: Kit por rider: mochila isotérmica + acumuladores (CAPEX) | B40: €/rider | D40: 150
A41: Riders previstos para el kit (CAPEX) | B41: nº | D41: 2
A43: 4 · MICROHUB (cámara refrigerada alquilada en la zona de reparto)
A44: Alquiler del microhub con cámaras refrigeradas | B44: €/mes | D44: 500 | G44: MICROHUB_COSTES.xlsx
A45: Suministros del microhub (luz de cámaras, si no van incluidos) | B45: €/mes | D45: 100 | G45: Supuesto.
...

Sheet Pipeline
A1: ROOTFLOW — Pipeline comercial: demanda identificada por cliente y variedad
A2: Esta hoja ALIMENTA el modelo: cada cliente pide tarrinas/semana de variedades concretas. El modelo sirve primero esta demanda y añade encima la capa de nuevas cuentas.
A4: Semanas por mes (365/7/12) | D4: 4.35
A6: Parámetros por variedad (enlazados de Producto — no tocar) | G6: Micromez. | H6: Cilantro | I6: Albahaca | J6: R. daikon | K6: Rúcula | L6: R. rose | M6: Mostaza | N6: Brócoli | O6: Amaranto
A7: Precio MAYORISTA €/tarrina | G7: =Producto!F16 -> 3 | H7: =Producto!F17 -> 2.5 | I7: =Producto!F18 -> 2.5 | J7: =Producto!F19 -> 1.5 | K7: =Producto!F20 -> 1.5 | L7: =Producto!F21 -> 1.5 | M7: =Producto!F22 -> 1.5 | N7: =Producto!F23 -> 1.5 | O7: =Producto!F24 -> 3
A8: Tarrinas por bandeja | G8: =Producto!L16 -> 1.7 | H8: =Producto!L17 -> 4.8333333 | I8: =Producto!L18 -> 3 | J8: =Producto!L19 -> 8.1666667 | K8: =Producto!L20 -> 5.6666667 | L8: =Producto!L21 -> 8.1666667 | M8: =Producto!L22 -> 5.3333333 | N8: =Producto!L23 -> 5.6666667 | O8: =Producto!L24 -> 2.6666667
A9: Ciclos/mes | G9: =Producto!J16 -> 8.2216216 | H9: =Producto!J17 -> 3.042 | I9: =Producto!J18 -> 2.34 | J9: =Producto!J19 -> 10.14 | K9: =Producto!J20 -> 7.605 | L9: =Producto!J21 -> 10.14 | M9: =Producto!J22 -> 7.605 | N9: =Producto!J23 -> 7.605 | O9: =Producto!J24 -> 3.38
A10: COGS €/tarrina | G10: =Producto!R16/Producto!L16 -> 0.57370637 | H10: =Producto!R17/Producto!L17 -> 0.29349672 | I10: =Producto!R18/Producto!L18 -> 0.40496694 | J10: =Producto!R19/Producto!L19 -> 0.25717153 | K10: =Producto!R20/Producto!L20 -> 0.2647472 | L10: =Producto!R21/Producto!L21 -> 0.2567552 | M10: =Producto!R22/Producto!L22 -> 0.3222314 | N10: =Producto!R23/Producto!L23 -> 0.32104132 | O10: =Producto!R24/Producto!L24 -> 0.47821281
A11: Peso tarrina (g) | G11: =Producto!E16 -> 100 | H11: =Producto!E17 -> 30 | I11: =Producto!E18 -> 30 | J11: =Producto!E19 -> 30 | K11: =Producto!E20 -> 30 | L11: =Producto!E21 -> 30 | M11: =Producto!E22 -> 30 | N11: =Producto!E23 -> 30 | O11: =Producto!E24 -> 30
A12: Posiciones por tarrina·mes | G12: =1/(G8*G9) -> 0.071547357 | H12: =1/(H8*H9) -> 0.068013331 | I12: =1/(I8*I9) -> 0.14245014 | J12: =1/(J8*J9) -> 0.012075836 | K12: =1/(K8*K9) -> 0.023204548 | L12: =1/(L8*L9) -> 0.012075836 | M12: =1/(M8*M9) -> 0.024654832 | N12: =1/(N8*N9) -> 0.023204548 | O12: =1/(O8*O9) -> 0.11094675
A13: Bandejas por tarrina | G13: =1/G8 -> 0.58823529 | H13: =1/H8 -> 0.20689655 | I13: =1/I8 -> 0.33333333 | J13: =1/J8 -> 0.12244898 | K13: =1/K8 -> 0.17647059 | L13: =1/L8 -> 0.12244898 | M13: =1/M8 -> 0.1875 | N13: =1/N8 -> 0.17647059 | O13: =1/O8 -> 0.375
G14: tarrinas por SEMANA que pide cada cliente, por variedad
A15: Cliente | B15: Estado | C15: Desc. canal | D15: Prob. | E15: Mes inicio | F15: Rampa (meses) | G15: Micromez. | H15: Cilantro | I15: Albahaca | J15: R. daikon | K15: Rúcula | L15: R. rose | M15: Mostaza | N15: Brócoli | O15: Amaranto | P15: Tarrinas /mes | Q15: €/mes POTENCIAL | R15: €/mes PONDERADO | S15: kg/mes | T15: Bandejas /mes | U15: Posic. de luz | V15: % de la nave | W15: COGS €/mes | X15: Notas / próximos pasos
A16: Frutería La Huerta de Aranjuez | B16: ACTIVO | C16: 0 | D16: 0.95 | E16: 1 | F16: 3 | G16: 0 | H16: 200 | I16: 100 | J16: 0 | K16: 0 | L16: 0 | M16: 0 | N16: 0 | O16: 0 | P16: =SUM(G16:O16)*Pipeline!$D$4 -> 1305 | Q16: =SUMPRODUCT(G$7:O$7,G16:O16)*Pipeline!$D$4*(1-C16) -> 3262.5 | R16: =Q16*D16 -> 3099.375 | S16: =SUMPRODUCT(G$11:O$11,G16:O16)*Pipeline!$D$4/1000 -> 39.15 | T16: =SUMPRODUCT(G$13:O$13,G16:O16)*Pipeline!$D$4 -> 325 | U16: =SUMPRODUCT(G$12:O$12,G16:O16)*Pipeline!$D$4 -> 121.13741 | V16: =IFERROR(U16/(Hipótesis!$F$26*Hipótesis!$D$13),0) -> 0.042061601 | W16: =SUMPRODUCT(G$10:O$10,G16:O16)*Pipeline!$D$4 -> 431.50277 | X16: Cliente actual — crece gradual en nave nueva
A17: Sushita | B17: EN CONVERSACIÓN | C17: 0 | D17: 0.6 | E17: 2 | F17: 3 | G17: 30 | H17: 0 | I17: 0 | J17: 0 | K17: 0 | L17: 0 | M17: 0 | N17: 0 | O17: 0 | P17: =SUM(G17:O17)*Pipeline!$D$4 -> 130.5 | Q17: =SUMPRODUCT(G$7:O$7,G17:O17)*Pipeline!$D$4*(1-C17) -> 391.5 | R17: =Q17*D17 -> 234.9 | S17: =SUMPRODUCT(G$11:O$11,G17:O17)*Pipeline!$D$4/1000 -> 13.05 | T17: =SUMPRODUCT(G$13:O$13,G17:O17)*Pipeline!$D$4 -> 76.764706 | U17: =SUMPRODUCT(G$12:O$12,G17:O17)*Pipeline!$D$4 -> 9.33693 | V17: =IFERROR(U17/(Hipótesis!$F$26*Hipótesis!$D$13),0) -> 0.0032419896 | W17: =SUMPRODUCT(G$10:O$10,G17:O17)*Pipeline!$D$4 -> 74.868681 | X17: Cuenta HORECA pequeña — cerrar ya
A18: Frutas Eloy | B18: EN CONVERSACIÓN | C18: 0 | D18: 0.85 | E18: 3 | F18: 8 | G18: 600 | H18: 100 | I18: 100 | J18: 200 | K18: 0 | L18: 0 | M18: 0 | N18: 0 | O18: 0 | P18: =SUM(G18:O18)*Pipeline!$D$4 -> 4350 | Q18: =SUMPRODUCT(G$7:O$7,G18:O18)*Pipeline!$D$4*(1-C18) -> 11310 | R18: =Q18*D18 -> 9613.5 | S18: =SUMPRODUCT(G$11:O$11,G18:O18)*Pipeline!$D$4/1000 -> 313.2 | T18: =SUMPRODUCT(G$13:O$13,G18:O18)*Pipeline!$D$4 -> 1876.8247 | U18: =SUMPRODUCT(G$12:O$12,G18:O18)*Pipeline!$D$4 -> 288.79619 | V18: =IFERROR(U18/(Hipótesis!$F$26*Hipótesis!$D$13),0) -> 0.10027645 | W18: =SUMPRODUCT(G$10:O$10,G18:O18)*Pipeline!$D$4 -> 2024.9445 | X18: Cliente recurrente — sube despacio a micromezclum
A19: Mercamadrid (asentadores) | B19: POR ABRIR | C19: 0.2 | D19: 0.55 | E19: 6 | F19: 8 | G19: 1000 | H19: 0 | I19: 0 | J19: 0 | K19: 0 | L19: 0 | M19: 0 | N19: 0 | O19: 0 | P19: =SUM(G19:O19)*Pipeline!$D$4 -> 4350 | Q19: =SUMPRODUCT(G$7:O$7,G19:O19)*Pipeline!$D$4*(1-C19) -> 10440 | R19: =Q19*D19 -> 5742 | S19: =SUMPRODUCT(G$11:O$11,G19:O19)*Pipeline!$D$4/1000 -> 435 | T19: =SUMPRODUCT(G$13:O$13,G19:O19)*Pipeline!$D$4 -> 2558.8235 | U19: =SUMPRODUCT(G$12:O$12,G19:O19)*Pipeline!$D$4 -> 311.231 | V19: =IFERROR(U19/(Hipótesis!$F$26*Hipótesis!$D$13),0) -> 0.10806632 | W19: =SUMPRODUCT(G$10:O$10,G19:O19)*Pipeline!$D$4 -> 2495.6227 | X19: Micromezclum a granel — rampa larga de distribuidor
A20: Makro (cash & carry) | B20: EN CONVERSACIÓN | C20: 0.25 | D20: 0.25 | E20: 12 | F20: 10 | G20: 4000 | H20: 0 | I20: 0 | J20: 0 | K20: 0 | L20: 0 | M20: 0 | N20: 0 | O20: 0 | P20: =SUM(G20:O20)*Pipeline!$D$4 -> 17400 | Q20: =SUMPRODUCT(G$7:O$7,G20:O20)*Pipeline!$D$4*(1-C20) -> 39150 | R20: =Q20*D20 -> 9787.5 | S20: =SUMPRODUCT(G$11:O$11,G20:O20)*Pipeline!$D$4/1000 -> 1740 | T20: =SUMPRODUCT(G$13:O$13,G20:O20)*Pipeline!$D$4 -> 10235.294 | U20: =SUMPRODUCT(G$12:O$12,G20:O20)*Pipeline!$D$4 -> 1244.924 | V20: =IFERROR(U20/(Hipótesis!$F$26*Hipótesis!$D$13),0) -> 0.43226528 | W20: =SUMPRODUCT(G$10:O$10,G20:O20)*Pipeline!$D$4 -> 9982.4908 | X20: Gran cuenta: NO antes de capacidad probada. PENDIENTE LLAMADA
A21: Primaflor | B21: EN CONVERSACIÓN | C21: 0.3 | D21: 0.2 | E21: 14 | F21: 10 | G21: 2000 | H21: 0 | I21: 0 | J21: 0 | K21: 0 | L21: 0 | M21: 0 | N21: 0 | O21: 0 | P21: =SUM(G21:O21)*Pipeline!$D$4 -> 8700 | Q21: =SUMPRODUCT(G$7:O$7,G21:O21)*Pipeline!$D$4*(1-C21) -> 18270 | R21: =Q21*D21 -> 3654 | S21: =SUMPRODUCT(G$11:O$11,G21:O21)*Pipeline!$D$4/1000 -> 870 | T21: =SUMPRODUCT(G$13:O$13,G21:O21)*Pipeline!$D$4 -> 5117.6471 | U21: =SUMPRODUCT(G$12:O$12,G21:O21)*Pipeline!$D$4 -> 622.462 | V21: =IFERROR(U21/(Hipótesis!$F$26*Hipótesis!$D$13),0) -> 0.21613264 | W21: =SUMPRODUCT(G$10:O$10,G21:O21)*Pipeline!$D$4 -> 4991.2454 | X21: Co-packing: entra en año 2. PENDIENTE LLAMADA
A22: — hueco nueva cuenta — | C22: 0 | D22: 0 | E22: 1 | F22: 1 | G22: 0 | H22: 0 | I22: 0 | J22: 0 | K22: 0 | L22: 0 | M22: 0 | N22: 0 | O22: 0 | P22: =SUM(G22:O22)*Pipeline!$D$4 -> 0 | Q22: =SUMPRODUCT(G$7:O$7,G22:O22)*Pipeline!$D$4*(1-C22) -> 0 | R22: =Q22*D22 -> 0 | S22: =SUMPRODUCT(G$11:O$11,G22:O22)*Pipeline!$D$4/1000 -> 0 | T22: =SUMPRODUCT(G$13:O$13,G22:O22)*Pipeline!$D$4 -> 0 | U22: =SUMPRODUCT(G$12:O$12,G22:O22)*Pipeline!$D$4 -> 0 | V22: =IFERROR(U22/(Hipótesis!$F$26*Hipótesis!$D$13),0) -> 0 | W22: =SUMPRODUCT(G$10:O$10,G22:O22)*Pipeline!$D$4 -> 0
A23: TOTAL PIPELINE | P23: =SUM(P16:P22) -> 36235.5 | Q23: =SUM(Q16:Q22) -> 82824 | R23: =SUM(R16:R22) -> 32131.275 | S23: =SUM(S16:S22) -> 3410.4 | T23: =SUM(T16:T22) -> 20190.354 | U23: =SUM(U16:U22) -> 2597.8875 | V23: =IFERROR(U23/(Hipótesis!$F$26*Hipótesis!$D$13),0) -> 0.90204428 | W23: =SUM(W16:W22) -> 20000.675
A25: MIX QUE PIDE LA DEMANDA — posiciones de luz ponderadas (guía de siembra)
A26: Posiciones ponderadas | G26: =SUMPRODUCT($D$16:$D$22,G16:G22)*Pipeline!$D$4*G12 -> 771.23042 | H26: =SUMPRODUCT($D$16:$D$22,H16:H22)*Pipeline!$D$4*H12 -> 81.360947 | I26: =SUMPRODUCT($D$16:$D$22,I16:I22)*Pipeline!$D$4*I12 -> 111.53846 | J26: =SUMPRODUCT($D$16:$D$22,J16:J22)*Pipeline!$D$4*J12 -> 8.9300809 | K26: =SUMPRODUCT($D$16:$D$22,K16:K22)*Pipeline!$D$4*K12 -> 0 | L26: =SUMPRODUCT($D$16:$D$22,L16:L22)*Pipeline!$D$4*L12 -> 0 | M26: =SUMPRODUCT($D$16:$D$22,M16:M22)*Pipeline!$D$4*M12 -> 0 | N26: =SUMPRODUCT($D$16:$D$22,N16:N22)*Pipeline!$D$4*N12 -> 0 | O26: =SUMPRODUCT($D$16:$D$22,O16:O22)*Pipeline!$D$4*O12 -> 0
A27: % del mix demandado | G27: =IFERROR(G26/SUM($G$26:$O$26),0) -> 0.79258267 | H27: =IFERROR(H26/SUM($G$26:$O$26),0) -> 0.083613502 | I27: =IFERROR(I26/SUM($G$26:$O$26),0) -> 0.11462651 | J27: =IFERROR(J26/SUM($G$26:$O$26),0) -> 0.0091773187 | K27: =IFERROR(K26/SUM($G$26:$O$26),0) -> 0 | L27: =IFERROR(L26/SUM($G$26:$O$26),0) -> 0 | M27: =IFERROR(M26/SUM($G$26:$O$26),0) -> 0 | N27: =IFERROR(N26/SUM($G$26:$O$26),0) -> 0 | O27: =IFERROR(O26/SUM($G$26:$O$26),0) -> 0

Sheet Logistica
A1: ROOTFLOW — Logística: Madrid propio + resto de España (Athos)
A2: En Madrid repartimos con nuestras furgos (coste propio). Fuera de Madrid lo hace Athos: tarifa por CCAA y tramo de peso por envío. Ajusta el % de ventas fuera de Madrid y su reparto por CCAA.
A4: PARÁMETROS GENERALES
A5: % de las ventas (kg) que va FUERA de Madrid | B5: 0.35 | D5: El resto se reparte en Madrid con furgo propia
A6: Peso medio por ENVÍO fuera de Madrid (kg) | B6: 80 | D6: Determina el tramo de tarifa (0-25 / 26-50 / 51-100 / 101-150 / 151-200 / 201-299)
A7: Coste furgo PROPIA en Madrid (€/kg) | B7: 0.18 | D7: Combustible + amortización furgo + parte de reparto (no nómina de reparto, que ya está en OPEX)
A8: Recargo Athos (recogida 3€/pedido, seguro, etc.) % | B8: 0.05
A10: TARIFA ATHOS POR CCAA Y TRAMO DE PESO (€ por ENVÍO) — editable
A11: Comunidad Autónoma | B11: 0-25 kg | C11: 26-50 kg | D11: 51-100 kg | E11: 101-150 kg | F11: 151-200 kg | G11: 201-299 kg | H11: % de ventas fuera | I11: €/kg equivalente | J11: kg/mes régimen | K11: Coste/mes régimen
A12: Andalucía | B12: 29.05 | C12: 42.97 | D12: 59.17 | E12: 73.92 | F12: 84.56 | G12: 98.96 | H12: 0.12 | I12: =(IF($B$6<=25,B12,IF($B$6<=50,C12,IF($B$6<=100,D12,IF($B$6<=150,E12,IF($B$6<=200,F12,G12))))))/$B$6*(1+$B$8) -> 0.77660625 | J12: =$B$31*H12 -> 123.87731 | K12: =I12*J12 -> 96.203891
A13: Aragón | B13: 34.76 | C13: 46.14 | D13: 68.79 | E13: 77.41 | F13: 86.13 | G13: 94.68 | H13: 0.05 | I13: =(IF($B$6<=25,B13,IF($B$6<=50,C13,IF($B$6<=100,D13,IF($B$6<=150,E13,IF($B$6<=200,F13,G13))))))/$B$6*(1+$B$8) -> 0.90286875 | J13: =$B$31*H13 -> 51.615545 | K13: =I13*J13 -> 46.602062
A14: Asturias | B14: 27.08 | C14: 37.11 | D14: 48.64 | E14: 68.89 | F14: 83.48 | G14: 98.02 | H14: 0.03 | I14: =(IF($B$6<=25,B14,IF($B$6<=50,C14,IF($B$6<=100,D14,IF($B$6<=150,E14,IF($B$6<=200,F14,G14))))))/$B$6*(1+$B$8) -> 0.6384 | J14: =$B$31*H14 -> 30.969327 | K14: =I14*J14 -> 19.770818
A15: Cantabria | B15: 35.5 | C15: 43.1 | D15: 53.65 | E15: 68.71 | F15: 80.85 | G15: 99.06 | H15: 0.02 | I15: =(IF($B$6<=25,B15,IF($B$6<=50,C15,IF($B$6<=100,D15,IF($B$6<=150,E15,IF($B$6<=200,F15,G15))))))/$B$6*(1+$B$8) -> 0.70415625 | J15: =$B$31*H15 -> 20.646218 | K15: =I15*J15 -> 14.538163
A16: Castilla y León | B16: 37.7 | C16: 49.44 | D16: 61.97 | E16: 75.31 | F16: 90.68 | G16: 100.84 | H16: 0.1 | I16: =(IF($B$6<=25,B16,IF($B$6<=50,C16,IF($B$6<=100,D16,IF($B$6<=150,E16,IF($B$6<=200,F16,G16))))))/$B$6*(1+$B$8) -> 0.81335625 | J16: =$B$31*H16 -> 103.23109 | K16: =I16*J16 -> 83.963652
A17: Castilla-La Mancha | B17: 30.81 | C17: 40.86 | D17: 51.93 | E17: 65.67 | F17: 75.28 | G17: 87.47 | H17: 0.14 | I17: =(IF($B$6<=25,B17,IF($B$6<=50,C17,IF($B$6<=100,D17,IF($B$6<=150,E17,IF($B$6<=200,F17,G17))))))/$B$6*(1+$B$8) -> 0.68158125 | J17: =$B$31*H17 -> 144.52352 | K17: =I17*J17 -> 98.504525
A18: Cataluña | B18: 29.42 | C18: 42.71 | D18: 54.18 | E18: 66.64 | F18: 77.35 | G18: 91.02 | H18: 0.2 | I18: =(IF($B$6<=25,B18,IF($B$6<=50,C18,IF($B$6<=100,D18,IF($B$6<=150,E18,IF($B$6<=200,F18,G18))))))/$B$6*(1+$B$8) -> 0.7111125 | J18: =$B$31*H18 -> 206.46218 | K18: =I18*J18 -> 146.81784
A19: C. Valenciana | B19: 31.15 | C19: 41.35 | D19: 61.65 | E19: 69.37 | F19: 77.2 | G19: 84.84 | H19: 0.12 | I19: =(IF($B$6<=25,B19,IF($B$6<=50,C19,IF($B$6<=100,D19,IF($B$6<=150,E19,IF($B$6<=200,F19,G19))))))/$B$6*(1+$B$8) -> 0.80915625 | J19: =$B$31*H19 -> 123.87731 | K19: =I19*J19 -> 100.2361
A20: Extremadura | B20: 28.39 | C20: 42.97 | D20: 59.11 | E20: 73.62 | F20: 85.18 | G20: 98.3 | H20: 0.03 | I20: =(IF($B$6<=25,B20,IF($B$6<=50,C20,IF($B$6<=100,D20,IF($B$6<=150,E20,IF($B$6<=200,F20,G20))))))/$B$6*(1+$B$8) -> 0.77581875 | J20: =$B$31*H20 -> 30.969327 | K20: =I20*J20 -> 24.026584
A21: Galicia | B21: 28.39 | C21: 42.97 | D21: 59.11 | E21: 73.62 | F21: 85.18 | G21: 98.3 | H21: 0.05 | I21: =(IF($B$6<=25,B21,IF($B$6<=50,C21,IF($B$6<=100,D21,IF($B$6<=150,E21,IF($B$6<=200,F21,G21))))))/$B$6*(1+$B$8) -> 0.77581875 | J21: =$B$31*H21 -> 51.615545 | K21: =I21*J21 -> 40.044307
A22: La Rioja | B22: 36.87 | C22: 48.96 | D22: 73.02 | E22: 82.15 | F22: 91.44 | G22: 100.49 | H22: 0.02 | I22: =(IF($B$6<=25,B22,IF($B$6<=50,C22,IF($B$6<=100,D22,IF($B$6<=150,E22,IF($B$6<=200,F22,G22))))))/$B$6*(1+$B$8) -> 0.9583875 | J22: =$B$31*H22 -> 20.646218 | K22: =I22*J22 -> 19.787077
A23: Murcia | B23: 35.9 | C23: 47.66 | D23: 71.08 | E23: 79.96 | F23: 88.98 | G23: 97.8 | H23: 0.04 | I23: =(IF($B$6<=25,B23,IF($B$6<=50,C23,IF($B$6<=100,D23,IF($B$6<=150,E23,IF($B$6<=200,F23,G23))))))/$B$6*(1+$B$8) -> 0.932925 | J23: =$B$31*H23 -> 41.292436 | K23: =I23*J23 -> 38.522746
... A25: País Vasco | B25: 35.36 | C25: 42.9 | D25: 53.41 | E25: 68.41 | F25: 80.5 | G25: 98.63 | H25: 0.06 | I25: =(IF($B$6<=25,B25,IF($B$6<=50,C25,IF($B$6<=100,D25,IF($B$6<=150,E25,IF($B$6<=200,F25,G25))))))/$B$6*(1+$B$8) -> 0.70100625 | J25: =$B$31*H25 -> 61.938653 | K25: =I25*J25 -> 43.419383
A26: TOTAL FUERA DE MADRID | H26: =SUM(H12:H25) -> 1 | J26: =SUM(J12:J25) -> 1032.3109 | K26: =SUM(K12:K25) -> 792.22422
A28: REPARTO DE LA PRODUCCIÓN (régimen, mes 84)
A29: Producción que va a DISTRIBUCIÓN (kg/mes, régimen) | B29: =Modelo_Mensual!$CH$182 -> 2949.4597
A30: kg/mes en Madrid (furgo propia) | B30: =$B$29*(1-$B$5) -> 1917.1488
A31: kg/mes fuera de Madrid (Athos) | B31: =$B$29*$B$5 -> 1032.3109
A32: Coste logístico Madrid (€/mes) | B32: =$B$30*$B$7 -> 345.08678
A33: Coste logístico fuera Madrid (€/mes) | B33: =K26 -> 792.22422
A34: COSTE LOGÍSTICO TOTAL (€/mes régimen) | B34: =$B$32+$B$33 -> 1137.311
A35: Coste logístico medio (€/kg) | B35: =IFERROR($B$34/$B$29,0) -> 0.38559978
A36: Coste logístico de distribución como % de sus ingresos | B36: =IFERROR($B$34/Modelo_Mensual!$CH$34,0) -> 0.0099234792
A37: Nota: Athos cobra por ENVÍO según peso; agrupar pedidos de una misma CCAA en un envío mayor abarata mucho el €/kg (mira cómo baja al subir el peso medio por envío). Devoluciones +15%, aeropuerto +30€.
A39: €/kg medio ponderado FUERA (para el modelo mensual) | B39: =IFERROR(SUMPRODUCT(H12:H25,I12:I25)/SUM(H12:H25),0) -> 0.76742794

Sheet Hipótesis
A1: ROOTFLOW — Hipótesis del modelo
A2: Celdas azules = inputs. El selector de escenario reescribe la columna "Activo".
A4: ESCENARIO ACTIVO (1 = Conservador · 2 = Base · 3 = Optimista) | C4: 2 | D4: =CHOOSE($C$4,"CONSERVADOR","BASE","OPTIMISTA") -> BASE
A6: Concepto | B6: Unidad | C6: Conservador | D6: Base | E6: Optimista | F6: Activo
A7: GEOMETRÍA DEL RACK
A8: Rack ANTIGUO — bandejas por rack | B8: bandejas | D8: 32
A9: Rack NUEVO — superficie de cultivo POR NIVEL | B9: m²/nivel | D9: 24
A10: Rack NUEVO — nº de niveles | B10: niveles | D10: 6
A11: Superficie ocupada por bandeja | B11: m²/band | D11: 0.15
A12: Bandejas por nivel — CALCULADO | B12: bandejas | D12: =ROUNDDOWN(D9/D11,0) -> 160
A13: BANDEJAS POR RACK NUEVO — CALCULADO | B13: bandejas | D13: =D12*D10 -> 960
A14: Superficie de cultivo por rack — CALCULADO | B14: m² | D14: =D9*D10 -> 144
A15: AJUSTE POR ESCENARIO (flexiona la economía de Producto)
A16: Ajuste de PRECIO — línea DISTRIBUCIÓN (índice sobre la tarifa mayorista/tienda actual) | B16: % | C16: 0.9 | D16: 1 | E16: 1.1 | F16: =CHOOSE($C$4,C16,D16,E16) -> 1
A17: Ajuste de RENDIMIENTO / kg | B17: % | C17: 0.92 | D17: 1 | E17: 1.06 | F17: =CHOOSE($C$4,C17,D17,E17) -> 1
A18: Ajuste de COSTE de producto (índice sobre el coste bottom-up) | B18: % | C18: 1.05 | D18: 1 | E18: 0.9 | F18: =CHOOSE($C$4,C18,D18,E18) -> 1
A19: ECONOMÍA POR BANDEJA (Producto × escenario)
A20: Ingreso por bandeja — DISTRIBUCIÓN, nuevas cuentas (mezcla mayorista/tienda × índices) | B20: €/band/mes | C20: =((1-Hipótesis!$C$30)*Producto!$T$32+Hipótesis!$C$30*Producto!$AI$32)*Hipótesis!$C$16*Hipótesis!$C$17 -> 47.424169 | D20: =((1-Hipótesis!$D$30)*Producto!$T$32+Hipótesis!$D$30*Producto!$AI$32)*Hipótesis!$D$16*Hipótesis!$D$17 -> 57.275566 | E20: =((1-Hipótesis!$E$30)*Producto!$T$32+Hipótesis!$E$30*Producto!$AI$32)*Hipótesis!$E$16*Hipótesis!$E$17 -> 66.78331 | F20: =CHOOSE($C$4,C20,D20,E20) -> 57.275566
A21: Ingreso por bandeja — RESTAURANTES (tarifa 30 g × índice de precio restaurantes) | B21: €/band/mes | C21: =Producto!$AB$32*Restaurantes!$C$26*Hipótesis!$C$17 -> 177.89068 | D21: =Producto!$AB$32*Restaurantes!$D$26*Hipótesis!$D$17 -> 214.84381 | E21: =Producto!$AB$32*Restaurantes!$E$26*Hipótesis!$E$17 -> 250.50789 | F21: =CHOOSE($C$4,C21,D21,E21) -> 214.84381
A22: COGS por bandeja — DISTRIBUCIÓN (mezcla mayorista/tienda × índice de coste) | B22: €/band/mes | C22: =((1-Hipótesis!$C$30)*Producto!$S$32+Hipótesis!$C$30*Producto!$AJ$32)*Hipótesis!$C$18 -> 10.144796 | D22: =((1-Hipótesis!$D$30)*Producto!$S$32+Hipótesis!$D$30*Producto!$AJ$32)*Hipótesis!$D$18 -> 9.6617103 | E22: =((1-Hipótesis!$E$30)*Producto!$S$32+Hipótesis!$E$30*Producto!$AJ$32)*Hipótesis!$E$18 -> 8.6955393 | F22: =CHOOSE($C$4,C22,D22,E22) -> 9.6617103
A23: Rendimiento por bandeja | B23: kg/band/mes | C23: =Producto!$M$32*Hipótesis!$C$17 -> 1.1435901 | D23: =Producto!$M$32*Hipótesis!$D$17 -> 1.2430328 | E23: =Producto!$M$32*Hipótesis!$E$17 -> 1.3176147 | F23: =CHOOSE($C$4,C23,D23,E23) -> 1.2430328
A24: Ciclos (siembras) por posición y mes | B24: ciclos/mes | C24: =Producto!$J$32 -> 6.8941986 | D24: =Producto!$J$32 -> 6.8941986 | E24: =Producto!$J$32 -> 6.8941986 | F24: =CHOOSE($C$4,C24,D24,E24) -> 6.8941986
A25: CAPACIDAD Y RAMPA
A26: Capacidad total de la nave (racks NUEVOS) ← manda sobre el CAPEX | B26: racks | C26: 3 | D26: 3 | E26: 3 | F26: =CHOOSE($C$4,C26,D26,E26) -> 3
