Workbook

Sheet Portada
B2: ROOTFLOW HYDROPONICS S.L.
B3: Modelo financiero — Ronda ENISA + Inversor privado
B4: Microbrotes y flores comestibles · Canal HORECA premium · Madrid
B6: Qué hay dentro
B7: · PRODUCTO: COGS reales por variedad (semilla + sustrato + envase, sin IVA). Solo se produce lo activo.
B8: · PIPELINE: matriz cliente × variedad. La demanda identificada ALIMENTA el modelo: se sirve primero.
B9: · HIPÓTESIS: escenarios, capa adicional de nuevas cuentas, NÓMINAS (12 líneas, socios con sueldo reducido) y capital stack.
B10: · LOGISTICA: Madrid con furgo propia; fuera de Madrid, Athos por CCAA y tramo de peso. Alimenta el OPEX.
B11: · MODELO_MENSUAL (84 meses) · RESUMEN · RESUMEN_ANUAL.
B13: Cómo tocar las nóminas (sin romper nada)
B14: Cada línea de nómina de "Hipótesis" alimenta SU PROPIA fila de OPEX en el modelo mensual.
B15: NO insertes filas: usa las líneas "(libre)" que ya están puestas y cámbiales el nombre, el bruto y el mes de alta.
... B37: DIVIDENDOS: bloqueados hasta que TODA la deuda esté pagada (condición ENISA). Antes de eso, la retribución es vía nómina.

Sheet Resumen
A1: ROOTFLOW — Resumen para ENISA e inversores
A2: Cuadro de mando. Portfolio real + demanda identificada + capital stack.
A4: COMPARATIVA DE ESCENARIOS — se recalcula sola al cambiar cualquier variable del modelo
A5: Palanca / resultado | C5: CONSERVADOR | D5: BASE | E5: OPTIMISTA
A6: LO QUE SE MODIFICA EN CADA CASO
A7: Minutos por bandeja | C7: =Producto!$D$8 -> 4 | D7: =Producto!$D$9 -> 3 | E7: =Producto!$D$10 -> 2
A8: Precio medio de venta (índice, Conservador=100%) | C8: =Hipótesis!$C$16 -> 1 | D8: =Hipótesis!$D$16 -> 1.2 | E8: =Hipótesis!$E$16 -> 1.35
A9: Coste de producto (índice, Conservador=100%) | C9: =Hipótesis!$C$18 -> 1 | D9: =Hipótesis!$D$18 -> 0.85 | E9: =Hipótesis!$E$18 -> 0.75
A10: Inversión en automatización (€) | C10: =CAPEX!$E$10 -> 0 | D10: =CAPEX!$F$10 -> 10000 | E10: =CAPEX!$G$10 -> 35000
A11: Inversión total = necesidad de financiación (€) | C11: =CAPEX!$E$26 -> 148778 | D11: =CAPEX!$F$26 -> 161278 | E11: =CAPEX!$G$26 -> 185228
A12: PLANTILLA (se calcula sola según los minutos)
A13: Operarios de cultivo en régimen (nº) | C13: =Esc_Conservador!$CH$30 -> 6 | D13: =Esc_Base!$CH$30 -> 4 | E13: =Esc_Optimista!$CH$30 -> 2
A14: Plantilla TOTAL en régimen (nº) | C14: =Esc_Conservador!$CH$31 -> 11 | D14: =Esc_Base!$CH$31 -> 9 | E14: =Esc_Optimista!$CH$31 -> 7
A15: Coste de nóminas en régimen (€/mes) | C15: =-Esc_Conservador!$CH$51 -> 46141.316 | D15: =-Esc_Base!$CH$51 -> 40782.41 | E15: =-Esc_Optimista!$CH$51 -> 35423.503
A16: RESULTADO EN RÉGIMEN (año 5)
A17: Ingresos (€) | C17: =SUM(Esc_Conservador!$AY$36:$BJ$36) -> 1029546.8 | D17: =SUM(Esc_Base!$AY$36:$BJ$36) -> 1302988.1 | E17: =SUM(Esc_Optimista!$AY$36:$BJ$36) -> 1522841.8
A18: EBITDA (€) | C18: =SUM(Esc_Conservador!$AY$56:$BJ$56) -> 114866.38 | D18: =SUM(Esc_Base!$AY$56:$BJ$56) -> 460200.87 | E18: =SUM(Esc_Optimista!$AY$56:$BJ$56) -> 756508.59
A19: Margen EBITDA (%) | C19: =IFERROR(SUM(Esc_Conservador!$AY$56:$BJ$56)/SUM(Esc_Conservador!$AY$36:$BJ$36),0) -> 0.11156985 | D19: =IFERROR(SUM(Esc_Base!$AY$56:$BJ$56)/SUM(Esc_Base!$AY$36:$BJ$36),0) -> 0.35318885 | E19: =IFERROR(SUM(Esc_Optimista!$AY$56:$BJ$56)/SUM(Esc_Optimista!$AY$36:$BJ$36),0) -> 0.49677426
A20: Producción (kg/mes) | C20: =Esc_Conservador!$CH$26 -> 2795.3147 | D20: =Esc_Base!$CH$26 -> 2937.5601 | E20: =Esc_Optimista!$CH$26 -> 3044.2442
A21: RESULTADO DE LA OPERACIÓN
A22: Ingresos año 1 (€) | C22: =Esc_Conservador!$C$147 -> 149355.01 | D22: =Esc_Base!$C$147 -> 182508.82 | E22: =Esc_Optimista!$C$147 -> 208092.29
A23: Caja mínima del plan (€) | C23: =Esc_Conservador!$C$146 -> 30000 | D23: =Esc_Base!$C$146 -> 30000 | E23: =Esc_Optimista!$C$146 -> 30000
A24: DSCR mínimo (años 2-7) | C24: =Esc_Conservador!$C$145 -> 2.4184632 | D24: =Esc_Base!$C$145 -> 11.431002 | E24: =Esc_Optimista!$C$145 -> 16.460253
A25: TIR del inversor (TAE) | C25: =IFERROR(Esc_Conservador!$C$128,0) -> 0.10668192 | D25: =IFERROR(Esc_Base!$C$128,0) -> 0.35078851 | E25: =IFERROR(Esc_Optimista!$C$128,0) -> 0.53225757
A26: MOIC (múltiplo) | C26: =Esc_Conservador!$C$129 -> 1.5 | D26: =Esc_Base!$C$129 -> 3.3292732 | E26: =Esc_Optimista!$C$129 -> 5.5122271
A27: Payback del inversor (meses) | C27: =Esc_Conservador!$C$130 -> 48 | D27: =Esc_Base!$C$130 -> 48 | E27: =Esc_Optimista!$C$130 -> 48
A28: Financiación levantada (€) | C28: =Hipótesis!$D$122 -> 200000 | D28: =Hipótesis!$D$122 -> 200000 | E28: =Hipótesis!$D$122 -> 200000
A29: Póliza de crédito — máximo dispuesto (€) | C29: =Esc_Conservador!$C$150 -> 34041.057 | D29: =Esc_Base!$C$150 -> 4694.5064 | E29: =Esc_Optimista!$C$150 -> 7280.3801
A30: LO QUE SE LLEVA CADA SOCIO (30% cada uno)
A31: Neto €/mes en el año 3 (sueldo) | C31: =Esc_Conservador!$E$149 -> 2800 | D31: =Esc_Base!$E$149 -> 2800 | E31: =Esc_Optimista!$E$149 -> 2800
A32: Neto €/mes en el año 5 (sueldo + dividendo) | C32: =Esc_Conservador!$G$149 -> 3500 | D32: =Esc_Base!$G$149 -> 3500 | E32: =Esc_Optimista!$G$149 -> 3500
A33: Neto €/mes en el año 7 (sueldo + dividendo) | C33: =Esc_Conservador!$I$149 -> 4200 | D33: =Esc_Base!$I$149 -> 4200 | E33: =Esc_Optimista!$I$149 -> 4200
A34: Dividendos cobrados por socio en 7 años (neto) | C34: =SUM(Esc_Conservador!$C$117:$CH$117) -> 0 | D34: =SUM(Esc_Base!$C$117:$CH$117) -> 0 | E34: =SUM(Esc_Optimista!$C$117:$CH$117) -> 0
A35: Fondo Hito 4 acumulado (€) | C35: =Esc_Conservador!$CH$115 -> 80536.642 | D35: =Esc_Base!$CH$115 -> 493306.88 | E35: =Esc_Optimista!$CH$115 -> 836437.56
A36: Caja + fondo Hito 4 en la empresa (año 7) | C36: =Esc_Conservador!$CH$86+Esc_Conservador!$CH$115 -> 155675.84 | D36: =Esc_Base!$CH$86+Esc_Base!$CH$115 -> 1535753.2 | E36: =Esc_Optimista!$CH$86+Esc_Optimista!$CH$115 -> 2715830.3
A37: · de eso, le corresponde a CADA socio (30%) | C37: =(Esc_Conservador!$CH$86+Esc_Conservador!$CH$115)*Hipótesis!$D$82 -> 46702.753 | D37: =(Esc_Base!$CH$86+Esc_Base!$CH$115)*Hipótesis!$D$82 -> 460725.97 | E37: =(Esc_Optimista!$CH$86+Esc_Optimista!$CH$115)*Hipótesis!$D$82 -> 814749.1
A38: Valor de su 30% al múltiplo de salida | C38: =Esc_Conservador!$C$133*Hipótesis!$D$82 -> 236375.94 | D38: =Esc_Base!$C$133*Hipótesis!$D$82 -> 998781.96 | E38: =Esc_Optimista!$C$133*Hipótesis!$D$82 -> 1653668.1
A40: ¿La financiación CUBRE la necesidad? | C40: =IF(Hipótesis!$D$122>=CAPEX!$E$26,"SÍ","NO — faltan "&TEXT(CAPEX!$E$26-Hipótesis!$D$122,"#,##0")&" €") -> SÍ | D40: =IF(Hipótesis!$D$122>=CAPEX!$F$26,"SÍ","NO — faltan "&TEXT(CAPEX!$F$26-Hipótesis!$D$122,"#,##0")&" €") -> SÍ | E40: =IF(Hipótesis!$D$122>=CAPEX!$G$26,"SÍ","NO — faltan "&TEXT(CAPEX!$G$26-Hipótesis!$D$122,"#,##0")&" €") -> SÍ
A41: Todo lo de arriba son FÓRMULAS: cambia precios, minutos, SUELDOS, circulante o CAPEX y los tres casos se actualizan a la vez.
A42: El circulante (clientes a 30 días) se financia con la póliza, no con la ronda de la caja. El fondo Hito 4 aparta dinero para la siguiente ampliación.
...

Sheet Producto
A1: ROOTFLOW — Portfolio de producto y COGS reales
A2: Coste real por bandeja (semilla + sustrato + envase, sin IVA). Solo se produce lo ACTIVO. El % de luz de las activas debe sumar 100%.
A4: Parámetros globales
A5: Ratio precio DIRECTO ÷ DISTRIBUIDOR | D5: 1.3
A6: Días medios por mes (365/12) | D6: 30.42
A7: Días muertos entre ciclos (limpieza/resiembra) | D7: 0
A8: Minutos por bandeja — CONSERVADOR (a mano, sin automatización) | D8: 4 | F8: CLAVE: el tiempo por bandeja es LA variable del negocio y define cuántos operarios hacen falta. Cada nivel de minutos se consigue con la automatización del CAPEX (ver hoja CAPEX).
A9: Minutos por bandeja — BASE (lavadora + cinta/cosecha asistida) | D9: 3
A10: Minutos por bandeja — OPTIMISTA (+ sembradora automática) | D10: 2
A11: MINUTOS POR BANDEJA — según escenario activo | D11: =CHOOSE(Hipótesis!$C$4,D8,D9,D10) -> 3
A15: Variedad | B15: Estado dato | C15: Activo (1/0) | D15: % luz (bandejas) | E15: Formato (g/tarrina) | F15: Precio DIR €/tarrina | G15: €/kg DIR — calc | H15: Días luz | I15: Días germ. | J15: Ciclos/mes — calc | K15: Rendim. (g/band) | L15: Tarrinas /band — calc | M15: kg/band /mes — calc | N15: Semilla €/band | O15: Sustrato €/band | P15: Envase €/tarrina | Q15: Envase €/band — calc | R15: COGS €/band /ciclo — calc | S15: COGS €/band /mes — calc | T15: Ingreso DIR €/band/mes | U15: MB % | V15: MARGEN €/hora trabajo
A16: Micromezclum (mix 7 var.) | B16: PROVISIONAL | C16: 1 | D16: 0.4 | E16: 100 | F16: 3 | G16: =F16/E16*1000 -> 30 | H16: 3.7 | I16: 3.7 | J16: =Producto!$D$6/(H16+Producto!$D$7) -> 8.2216216 | K16: 170 | L16: =K16/E16 -> 1.7 | M16: =J16*K16/1000 -> 1.3976757 | N16: 0.43 | O16: 0.3 | P16: 0.2 | Q16: =L16*P16 -> 0.34 | R16: =N16+O16+Q16 -> 1.07 | S16: =R16*J16 -> 8.7971351 | T16: =L16*F16*J16 -> 41.93027 | U16: =IFERROR((T16-S16)/T16,0) -> 0.79019608 | V16: =IFERROR((T16-S16)/(J16*Producto!$D$11/60),0) -> 80.6
A17: Cilantro split | B17: CONFIRMADO | C17: 1 | D17: 0.15 | E17: 30 | F17: 2.4 | G17: =F17/E17*1000 -> 80 | H17: 11 | I17: 5 | J17: =Producto!$D$6/(H17+Producto!$D$7) -> 2.7654545 | K17: 120 | L17: =K17/E17 -> 4 | M17: =J17*K17/1000 -> 0.33185455 | N17: 0.24 | O17: 0.3 | P17: 0.1 | Q17: =L17*P17 -> 0.4 | R17: =N17+O17+Q17 -> 0.94 | S17: =R17*J17 -> 2.5995273 | T17: =L17*F17*J17 -> 26.548364 | U17: =IFERROR((T17-S17)/T17,0) -> 0.90208333 | V17: =IFERROR((T17-S17)/(J17*Producto!$D$11/60),0) -> 173.2
A18: Albahaca genovesa | B18: CONFIRMADO | C18: 1 | D18: 0.1 | E18: 30 | F18: 2.5 | G18: =F18/E18*1000 -> 83.333333 | H18: 13 | I18: 5 | J18: =Producto!$D$6/(H18+Producto!$D$7) -> 2.34 | K18: 100 | L18: =K18/E18 -> 3.3333333 | M18: =J18*K18/1000 -> 0.234 | N18: 0.44 | O18: 0.3 | P18: 0.1 | Q18: =L18*P18 -> 0.33333333 | R18: =N18+O18+Q18 -> 1.0733333 | S18: =R18*J18 -> 2.5116 | T18: =L18*F18*J18 -> 19.5 | U18: =IFERROR((T18-S18)/T18,0) -> 0.8712 | V18: =IFERROR((T18-S18)/(J18*Producto!$D$11/60),0) -> 145.2
A19: Rábano daikon | B19: PROVISIONAL | C19: 1 | D19: 0.08 | E19: 30 | F19: 1.3 | G19: =F19/E19*1000 -> 43.333333 | H19: 3 | I19: 3 | J19: =Producto!$D$6/(H19+Producto!$D$7) -> 10.14 | K19: 175 | L19: =K19/E19 -> 5.8333333 | M19: =J19*K19/1000 -> 1.7745 | N19: 0.3 | O19: 0.3 | P19: 0.1 | Q19: =L19*P19 -> 0.58333333 | R19: =N19+O19+Q19 -> 1.1833333 | S19: =R19*J19 -> 11.999 | T19: =L19*F19*J19 -> 76.895 | U19: =IFERROR((T19-S19)/T19,0) -> 0.84395604 | V19: =IFERROR((T19-S19)/(J19*Producto!$D$11/60),0) -> 128
A20: Rúcula rocket | B20: PROVISIONAL | C20: 1 | D20: 0.08 | E20: 30 | F20: 1.3 | G20: =F20/E20*1000 -> 43.333333 | H20: 4 | I20: 3 | J20: =Producto!$D$6/(H20+Producto!$D$7) -> 7.605 | K20: 170 | L20: =K20/E20 -> 5.6666667 | M20: =J20*K20/1000 -> 1.29285 | N20: 0.17 | O20: 0.3 | P20: 0.1 | Q20: =L20*P20 -> 0.56666667 | R20: =N20+O20+Q20 -> 1.0366667 | S20: =R20*J20 -> 7.88385 | T20: =L20*F20*J20 -> 56.0235 | U20: =IFERROR((T20-S20)/T20,0) -> 0.85927602 | V20: =IFERROR((T20-S20)/(J20*Producto!$D$11/60),0) -> 126.6
A21: Rábano rose | B21: PROVISIONAL | C21: 1 | D21: 0.07 | E21: 30 | F21: 1.3 | G21: =F21/E21*1000 -> 43.333333 | H21: 3 | I21: 3 | J21: =Producto!$D$6/(H21+Producto!$D$7) -> 10.14 | K21: 175 | L21: =K21/E21 -> 5.8333333 | M21: =J21*K21/1000 -> 1.7745 | N21: 0.3 | O21: 0.3 | P21: 0.1 | Q21: =L21*P21 -> 0.58333333 | R21: =N21+O21+Q21 -> 1.1833333 | S21: =R21*J21 -> 11.999 | T21: =L21*F21*J21 -> 76.895 | U21: =IFERROR((T21-S21)/T21,0) -> 0.84395604 | V21: =IFERROR((T21-S21)/(J21*Producto!$D$11/60),0) -> 128
A22: Mostaza Red Giant | B22: PROVISIONAL | C22: 1 | D22: 0.05 | E22: 30 | F22: 1.3 | G22: =F22/E22*1000 -> 43.333333 | H22: 4 | I22: 3 | J22: =Producto!$D$6/(H22+Producto!$D$7) -> 7.605 | K22: 160 | L22: =K22/E22 -> 5.3333333 | M22: =J22*K22/1000 -> 1.2168 | N22: 0.53 | O22: 0.3 | P22: 0.1 | Q22: =L22*P22 -> 0.53333333 | R22: =N22+O22+Q22 -> 1.3633333 | S22: =R22*J22 -> 10.36815 | T22: =L22*F22*J22 -> 52.728 | U22: =IFERROR((T22-S22)/T22,0) -> 0.80336538 | V22: =IFERROR((T22-S22)/(J22*Producto!$D$11/60),0) -> 111.4
A23: Brócoli calabrese | B23: PROVISIONAL | C23: 1 | D23: 0.04 | E23: 30 | F23: 1.3 | G23: =F23/E23*1000 -> 43.333333 | H23: 4 | I23: 3 | J23: =Producto!$D$6/(H23+Producto!$D$7) -> 7.605 | K23: 170 | L23: =K23/E23 -> 5.6666667 | M23: =J23*K23/1000 -> 1.29285 | N23: 0.55 | O23: 0.3 | P23: 0.1 | Q23: =L23*P23 -> 0.56666667 | R23: =N23+O23+Q23 -> 1.4166667 | S23: =R23*J23 -> 10.77375 | T23: =L23*F23*J23 -> 56.0235 | U23: =IFERROR((T23-S23)/T23,0) -> 0.80769231 | V23: =IFERROR((T23-S23)/(J23*Producto!$D$11/60),0) -> 119
A24: Amaranto rojo | B24: PROVISIONAL | C24: 1 | D24: 0.03 | E24: 30 | F24: 2 | G24: =F24/E24*1000 -> 66.666667 | H24: 9 | I24: 3 | J24: =Producto!$D$6/(H24+Producto!$D$7) -> 3.38 | K24: 80 | L24: =K24/E24 -> 2.6666667 | M24: =J24*K24/1000 -> 0.2704 | N24: 0.75 | O24: 0.3 | P24: 0.1 | Q24: =L24*P24 -> 0.26666667 | R24: =N24+O24+Q24 -> 1.3166667 | S24: =R24*J24 -> 4.4503333 | T24: =L24*F24*J24 -> 18.026667 | U24: =IFERROR((T24-S24)/T24,0) -> 0.753125 | V24: =IFERROR((T24-S24)/(J24*Producto!$D$11/60),0) -> 80.333333
A25: Rábano red | B25: INACTIVO | C25: 0 | D25: 0 | E25: 30 | F25: 1.3 | G25: =F25/E25*1000 -> 43.333333 | H25: 2 | I25: 3 | J25: =Producto!$D$6/(H25+Producto!$D$7) -> 15.21 | K25: 200 | L25: =K25/E25 -> 6.6666667 | M25: =J25*K25/1000 -> 3.042 | N25: 0.3 | O25: 0.3 | P25: 0.1 | Q25: =L25*P25 -> 0.66666667 | R25: =N25+O25+Q25 -> 1.2666667 | S25: =R25*J25 -> 19.266 | T25: =L25*F25*J25 -> 131.82 | U25: =IFERROR((T25-S25)/T25,0) -> 0.85384615 | V25: =IFERROR((T25-S25)/(J25*Producto!$D$11/60),0) -> 148
A26: Guisante (pea shoots) | B26: INACTIVO | C26: 0 | D26: 0 | E26: 30 | F26: 1.44 | G26: =F26/E26*1000 -> 48 | H26: 8 | I26: 3 | J26: =Producto!$D$6/(H26+Producto!$D$7) -> 3.8025 | K26: 220 | L26: =K26/E26 -> 7.3333333 | M26: =J26*K26/1000 -> 0.83655 | N26: 1.5 | O26: 0.3 | P26: 0.1 | Q26: =L26*P26 -> 0.73333333 | R26: =N26+O26+Q26 -> 2.5333333 | S26: =R26*J26 -> 9.633 | T26: =L26*F26*J26 -> 40.1544 | U26: =IFERROR((T26-S26)/T26,0) -> 0.76010101 | V26: =IFERROR((T26-S26)/(J26*Producto!$D$11/60),0) -> 160.53333
A27: Remolacha roja | B27: INACTIVO | C27: 0 | D27: 0 | E27: 30 | F27: 1.8 | G27: =F27/E27*1000 -> 60 | H27: 8 | I27: 4 | J27: =Producto!$D$6/(H27+Producto!$D$7) -> 3.8025 | K27: 150 | L27: =K27/E27 -> 5 | M27: =J27*K27/1000 -> 0.570375 | N27: 0.6 | O27: 0.3 | P27: 0.1 | Q27: =L27*P27 -> 0.5 | R27: =N27+O27+Q27 -> 1.4 | S27: =R27*J27 -> 5.3235 | T27: =L27*F27*J27 -> 34.2225 | U27: =IFERROR((T27-S27)/T27,0) -> 0.84444444 | V27: =IFERROR((T27-S27)/(J27*Producto!$D$11/60),0) -> 152
... A31: Cebollino chino | B31: INACTIVO | C31: 0 | D31: 0 | E31: 30 | F31: 2.6 | G31: =F31/E31*1000 -> 86.666667 | H31: 14 | I31: 6 | J31: =Producto!$D$6/(H31+Producto!$D$7) -> 2.1728571 | K31: 70 | L31: =K31/E31 -> 2.3333333 | M31: =J31*K31/1000 -> 0.1521 | N31: 0.7 | O31: 0.3 | P31: 0.1 | Q31: =L31*P31 -> 0.23333333 | R31: =N31+O31+Q31 -> 1.2333333 | S31: =R31*J31 -> 2.6798571 | T31: =L31*F31*J31 -> 13.182 | U31: =IFERROR((T31-S31)/T31,0) -> 0.7967033 | V31: =IFERROR((T31-S31)/(J31*Producto!$D$11/60),0) -> 96.666667
A32: PORTFOLIO ACTIVO (media ponderada por % de luz) | D32: =SUMPRODUCT(C16:C31,D16:D31) -> 1 | J32: =SUMPRODUCT(C16:C31,D16:D31,J16:J31) -> 6.8527168 | M32: =SUMPRODUCT(C16:C31,D16:D31,M16:M31) -> 1.1225175 | S32: =SUMPRODUCT(C16:C31,D16:D31,S16:S31) -> 7.6733686 | T32: =SUMPRODUCT(C16:C31,D16:D31,T16:T31) -> 44.138633 | U32: =IFERROR((T32-S32)/T32,0) -> 0.82615301 | V32: =IFERROR((T32-S32)/(J32*Producto!$D$11/60),0) -> 106.42571
A34: Comprobación: % de luz de las ACTIVAS suma | D34: =IF(ABS(D32-1)<0.001,"OK — 100%","REVISAR: "&TEXT(D32,"0%")) -> OK — 100% | F34: MARGEN €/HORA de trabajo: la métrica que manda cuando la mano de obra es el cuello de botella. Compárala con el coste/hora cargado (~14 €/h).
A35: Precio medio ponderado del portfolio — DIRECTO (€/kg) | D35: =IFERROR(T32/M32,0) -> 39.32111
A36: Margen bruto del portfolio (s/ ingreso directo) | D36: =U32 -> 0.82615301

Sheet Pipeline
A1: ROOTFLOW — Pipeline comercial: demanda identificada por cliente y variedad
A2: Esta hoja ALIMENTA el modelo: cada cliente pide tarrinas/semana de variedades concretas. El modelo sirve primero esta demanda y añade encima la capa de nuevas cuentas.
A4: Semanas por mes (365/7/12) | D4: 4.35
A6: Parámetros por variedad (enlazados de Producto — no tocar) | G6: Micromez. | H6: Cilantro | I6: Albahaca | J6: R. daikon | K6: Rúcula | L6: R. rose | M6: Mostaza | N6: Brócoli | O6: Amaranto
A7: Precio directo €/tarrina | G7: =Producto!F16 -> 3 | H7: =Producto!F17 -> 2.4 | I7: =Producto!F18 -> 2.5 | J7: =Producto!F19 -> 1.3 | K7: =Producto!F20 -> 1.3 | L7: =Producto!F21 -> 1.3 | M7: =Producto!F22 -> 1.3 | N7: =Producto!F23 -> 1.3 | O7: =Producto!F24 -> 2
A8: Tarrinas por bandeja | G8: =Producto!L16 -> 1.7 | H8: =Producto!L17 -> 4 | I8: =Producto!L18 -> 3.3333333 | J8: =Producto!L19 -> 5.8333333 | K8: =Producto!L20 -> 5.6666667 | L8: =Producto!L21 -> 5.8333333 | M8: =Producto!L22 -> 5.3333333 | N8: =Producto!L23 -> 5.6666667 | O8: =Producto!L24 -> 2.6666667
A9: Ciclos/mes | G9: =Producto!J16 -> 8.2216216 | H9: =Producto!J17 -> 2.7654545 | I9: =Producto!J18 -> 2.34 | J9: =Producto!J19 -> 10.14 | K9: =Producto!J20 -> 7.605 | L9: =Producto!J21 -> 10.14 | M9: =Producto!J22 -> 7.605 | N9: =Producto!J23 -> 7.605 | O9: =Producto!J24 -> 3.38
A10: COGS €/tarrina | G10: =Producto!R16/Producto!L16 -> 0.62941176 | H10: =Producto!R17/Producto!L17 -> 0.235 | I10: =Producto!R18/Producto!L18 -> 0.322 | J10: =Producto!R19/Producto!L19 -> 0.20285714 | K10: =Producto!R20/Producto!L20 -> 0.18294118 | L10: =Producto!R21/Producto!L21 -> 0.20285714 | M10: =Producto!R22/Producto!L22 -> 0.255625 | N10: =Producto!R23/Producto!L23 -> 0.25 | O10: =Producto!R24/Producto!L24 -> 0.49375
A11: Peso tarrina (g) | G11: =Producto!E16 -> 100 | H11: =Producto!E17 -> 30 | I11: =Producto!E18 -> 30 | J11: =Producto!E19 -> 30 | K11: =Producto!E20 -> 30 | L11: =Producto!E21 -> 30 | M11: =Producto!E22 -> 30 | N11: =Producto!E23 -> 30 | O11: =Producto!E24 -> 30
A12: Posiciones por tarrina·mes | G12: =1/(G8*G9) -> 0.071547357 | H12: =1/(H8*H9) -> 0.090401052 | I12: =1/(I8*I9) -> 0.12820513 | J12: =1/(J8*J9) -> 0.016906171 | K12: =1/(K8*K9) -> 0.023204548 | L12: =1/(L8*L9) -> 0.016906171 | M12: =1/(M8*M9) -> 0.024654832 | N12: =1/(N8*N9) -> 0.023204548 | O12: =1/(O8*O9) -> 0.11094675
A13: Bandejas por tarrina | G13: =1/G8 -> 0.58823529 | H13: =1/H8 -> 0.25 | I13: =1/I8 -> 0.3 | J13: =1/J8 -> 0.17142857 | K13: =1/K8 -> 0.17647059 | L13: =1/L8 -> 0.17142857 | M13: =1/M8 -> 0.1875 | N13: =1/N8 -> 0.17647059 | O13: =1/O8 -> 0.375
G14: tarrinas por SEMANA que pide cada cliente, por variedad
A15: Cliente | B15: Estado | C15: Desc. canal | D15: Prob. | E15: Mes inicio | F15: Rampa (meses) | G15: Micromez. | H15: Cilantro | I15: Albahaca | J15: R. daikon | K15: Rúcula | L15: R. rose | M15: Mostaza | N15: Brócoli | O15: Amaranto | P15: Tarrinas /mes | Q15: €/mes POTENCIAL | R15: €/mes PONDERADO | S15: kg/mes | T15: Bandejas /mes | U15: Posic. de luz | V15: % de la nave | W15: COGS €/mes | X15: Notas / próximos pasos
A16: Frutería La Huerta de Aranjuez | B16: ACTIVO | C16: 0 | D16: 0.95 | E16: 1 | F16: 3 | G16: 0 | H16: 200 | I16: 100 | J16: 0 | K16: 0 | L16: 0 | M16: 0 | N16: 0 | O16: 0 | P16: =SUM(G16:O16)*Pipeline!$D$4 -> 1305 | Q16: =SUMPRODUCT(G$7:O$7,G16:O16)*Pipeline!$D$4*(1-C16) -> 3175.5 | R16: =Q16*D16 -> 3016.725 | S16: =SUMPRODUCT(G$11:O$11,G16:O16)*Pipeline!$D$4/1000 -> 39.15 | T16: =SUMPRODUCT(G$13:O$13,G16:O16)*Pipeline!$D$4 -> 348 | U16: =SUMPRODUCT(G$12:O$12,G16:O16)*Pipeline!$D$4 -> 134.41815 | V16: =IFERROR(U16/(Hipótesis!$F$26*Hipótesis!$D$13),0) -> 0.046672967 | W16: =SUMPRODUCT(G$10:O$10,G16:O16)*Pipeline!$D$4 -> 344.52 | X16: Cliente actual — crece gradual en nave nueva
A17: Sushita | B17: EN CONVERSACIÓN | C17: 0 | D17: 0.6 | E17: 2 | F17: 3 | G17: 30 | H17: 0 | I17: 0 | J17: 0 | K17: 0 | L17: 0 | M17: 0 | N17: 0 | O17: 0 | P17: =SUM(G17:O17)*Pipeline!$D$4 -> 130.5 | Q17: =SUMPRODUCT(G$7:O$7,G17:O17)*Pipeline!$D$4*(1-C17) -> 391.5 | R17: =Q17*D17 -> 234.9 | S17: =SUMPRODUCT(G$11:O$11,G17:O17)*Pipeline!$D$4/1000 -> 13.05 | T17: =SUMPRODUCT(G$13:O$13,G17:O17)*Pipeline!$D$4 -> 76.764706 | U17: =SUMPRODUCT(G$12:O$12,G17:O17)*Pipeline!$D$4 -> 9.33693 | V17: =IFERROR(U17/(Hipótesis!$F$26*Hipótesis!$D$13),0) -> 0.0032419896 | W17: =SUMPRODUCT(G$10:O$10,G17:O17)*Pipeline!$D$4 -> 82.138235 | X17: Cuenta HORECA pequeña — cerrar ya
A18: Frutas Eloy | B18: EN CONVERSACIÓN | C18: 0 | D18: 0.85 | E18: 3 | F18: 8 | G18: 600 | H18: 100 | I18: 100 | J18: 200 | K18: 0 | L18: 0 | M18: 0 | N18: 0 | O18: 0 | P18: =SUM(G18:O18)*Pipeline!$D$4 -> 4350 | Q18: =SUMPRODUCT(G$7:O$7,G18:O18)*Pipeline!$D$4*(1-C18) -> 11092.5 | R18: =Q18*D18 -> 9428.625 | S18: =SUMPRODUCT(G$11:O$11,G18:O18)*Pipeline!$D$4/1000 -> 313.2 | T18: =SUMPRODUCT(G$13:O$13,G18:O18)*Pipeline!$D$4 -> 1923.687 | U18: =SUMPRODUCT(G$12:O$12,G18:O18)*Pipeline!$D$4 -> 296.54066 | V18: =IFERROR(U18/(Hipótesis!$F$26*Hipótesis!$D$13),0) -> 0.10296551 | W18: =SUMPRODUCT(G$10:O$10,G18:O18)*Pipeline!$D$4 -> 2061.5454 | X18: Cliente recurrente — sube despacio a micromezclum
A19: Mercamadrid (asentadores) | B19: POR ABRIR | C19: 0.2 | D19: 0.55 | E19: 6 | F19: 8 | G19: 1000 | H19: 0 | I19: 0 | J19: 0 | K19: 0 | L19: 0 | M19: 0 | N19: 0 | O19: 0 | P19: =SUM(G19:O19)*Pipeline!$D$4 -> 4350 | Q19: =SUMPRODUCT(G$7:O$7,G19:O19)*Pipeline!$D$4*(1-C19) -> 10440 | R19: =Q19*D19 -> 5742 | S19: =SUMPRODUCT(G$11:O$11,G19:O19)*Pipeline!$D$4/1000 -> 435 | T19: =SUMPRODUCT(G$13:O$13,G19:O19)*Pipeline!$D$4 -> 2558.8235 | U19: =SUMPRODUCT(G$12:O$12,G19:O19)*Pipeline!$D$4 -> 311.231 | V19: =IFERROR(U19/(Hipótesis!$F$26*Hipótesis!$D$13),0) -> 0.10806632 | W19: =SUMPRODUCT(G$10:O$10,G19:O19)*Pipeline!$D$4 -> 2737.9412 | X19: Micromezclum a granel — rampa larga de distribuidor
A20: Makro (cash & carry) | B20: EN CONVERSACIÓN | C20: 0.25 | D20: 0.25 | E20: 12 | F20: 10 | G20: 4000 | H20: 0 | I20: 0 | J20: 0 | K20: 0 | L20: 0 | M20: 0 | N20: 0 | O20: 0 | P20: =SUM(G20:O20)*Pipeline!$D$4 -> 17400 | Q20: =SUMPRODUCT(G$7:O$7,G20:O20)*Pipeline!$D$4*(1-C20) -> 39150 | R20: =Q20*D20 -> 9787.5 | S20: =SUMPRODUCT(G$11:O$11,G20:O20)*Pipeline!$D$4/1000 -> 1740 | T20: =SUMPRODUCT(G$13:O$13,G20:O20)*Pipeline!$D$4 -> 10235.294 | U20: =SUMPRODUCT(G$12:O$12,G20:O20)*Pipeline!$D$4 -> 1244.924 | V20: =IFERROR(U20/(Hipótesis!$F$26*Hipótesis!$D$13),0) -> 0.43226528 | W20: =SUMPRODUCT(G$10:O$10,G20:O20)*Pipeline!$D$4 -> 10951.765 | X20: Gran cuenta: NO antes de capacidad probada. PENDIENTE LLAMADA
A21: Primaflor | B21: EN CONVERSACIÓN | C21: 0.3 | D21: 0.2 | E21: 14 | F21: 10 | G21: 2000 | H21: 0 | I21: 0 | J21: 0 | K21: 0 | L21: 0 | M21: 0 | N21: 0 | O21: 0 | P21: =SUM(G21:O21)*Pipeline!$D$4 -> 8700 | Q21: =SUMPRODUCT(G$7:O$7,G21:O21)*Pipeline!$D$4*(1-C21) -> 18270 | R21: =Q21*D21 -> 3654 | S21: =SUMPRODUCT(G$11:O$11,G21:O21)*Pipeline!$D$4/1000 -> 870 | T21: =SUMPRODUCT(G$13:O$13,G21:O21)*Pipeline!$D$4 -> 5117.6471 | U21: =SUMPRODUCT(G$12:O$12,G21:O21)*Pipeline!$D$4 -> 622.462 | V21: =IFERROR(U21/(Hipótesis!$F$26*Hipótesis!$D$13),0) -> 0.21613264 | W21: =SUMPRODUCT(G$10:O$10,G21:O21)*Pipeline!$D$4 -> 5475.8824 | X21: Co-packing: entra en año 2. PENDIENTE LLAMADA
A22: — hueco nueva cuenta — | C22: 0 | D22: 0 | E22: 1 | F22: 1 | G22: 0 | H22: 0 | I22: 0 | J22: 0 | K22: 0 | L22: 0 | M22: 0 | N22: 0 | O22: 0 | P22: =SUM(G22:O22)*Pipeline!$D$4 -> 0 | Q22: =SUMPRODUCT(G$7:O$7,G22:O22)*Pipeline!$D$4*(1-C22) -> 0 | R22: =Q22*D22 -> 0 | S22: =SUMPRODUCT(G$11:O$11,G22:O22)*Pipeline!$D$4/1000 -> 0 | T22: =SUMPRODUCT(G$13:O$13,G22:O22)*Pipeline!$D$4 -> 0 | U22: =SUMPRODUCT(G$12:O$12,G22:O22)*Pipeline!$D$4 -> 0 | V22: =IFERROR(U22/(Hipótesis!$F$26*Hipótesis!$D$13),0) -> 0 | W22: =SUMPRODUCT(G$10:O$10,G22:O22)*Pipeline!$D$4 -> 0
A23: TOTAL PIPELINE | P23: =SUM(P16:P22) -> 36235.5 | Q23: =SUM(Q16:Q22) -> 82519.5 | R23: =SUM(R16:R22) -> 31863.75 | S23: =SUM(S16:S22) -> 3410.4 | T23: =SUM(T16:T22) -> 20260.216 | U23: =SUM(U16:U22) -> 2618.9127 | V23: =IFERROR(U23/(Hipótesis!$F$26*Hipótesis!$D$13),0) -> 0.9093447 | W23: =SUM(W16:W22) -> 21653.792
A25: MIX QUE PIDE LA DEMANDA — posiciones de luz ponderadas (guía de siembra)
A26: Posiciones ponderadas | G26: =SUMPRODUCT($D$16:$D$22,G16:G22)*Pipeline!$D$4*G12 -> 771.23042 | H26: =SUMPRODUCT($D$16:$D$22,H16:H22)*Pipeline!$D$4*H12 -> 108.14226 | I26: =SUMPRODUCT($D$16:$D$22,I16:I22)*Pipeline!$D$4*I12 -> 100.38462 | J26: =SUMPRODUCT($D$16:$D$22,J16:J22)*Pipeline!$D$4*J12 -> 12.502113 | K26: =SUMPRODUCT($D$16:$D$22,K16:K22)*Pipeline!$D$4*K12 -> 0 | L26: =SUMPRODUCT($D$16:$D$22,L16:L22)*Pipeline!$D$4*L12 -> 0 | M26: =SUMPRODUCT($D$16:$D$22,M16:M22)*Pipeline!$D$4*M12 -> 0 | N26: =SUMPRODUCT($D$16:$D$22,N16:N22)*Pipeline!$D$4*N12 -> 0 | O26: =SUMPRODUCT($D$16:$D$22,O16:O22)*Pipeline!$D$4*O12 -> 0
A27: % del mix demandado | G27: =IFERROR(G26/SUM($G$26:$O$26),0) -> 0.77724677 | H27: =IFERROR(H26/SUM($G$26:$O$26),0) -> 0.10898587 | I27: =IFERROR(I26/SUM($G$26:$O$26),0) -> 0.10116771 | J27: =IFERROR(J26/SUM($G$26:$O$26),0) -> 0.012599642 | K27: =IFERROR(K26/SUM($G$26:$O$26),0) -> 0 | L27: =IFERROR(L26/SUM($G$26:$O$26),0) -> 0 | M27: =IFERROR(M26/SUM($G$26:$O$26),0) -> 0 | N27: =IFERROR(N26/SUM($G$26:$O$26),0) -> 0 | O27: =IFERROR(O26/SUM($G$26:$O$26),0) -> 0

Sheet Logistica
A1: ROOTFLOW — Logística: Madrid propio + resto de España (Athos)
A2: En Madrid repartimos con nuestras furgos (coste propio). Fuera de Madrid lo hace Athos: tarifa por CCAA y tramo de peso por envío. Ajusta el % de ventas fuera de Madrid y su reparto por CCAA.
A4: PARÁMETROS GENERALES
A5: % de las ventas (kg) que va FUERA de Madrid | B5: 0.35 | D5: El resto se reparte en Madrid con furgo propia
A6: Peso medio por ENVÍO fuera de Madrid (kg) | B6: 80 | D6: Determina el tramo de tarifa (0-25 / 26-50 / 51-100 / 101-150 / 151-200 / 201-299)
A7: Coste furgo PROPIA en Madrid (€/kg) | B7: 0.18 | D7: Combustible + amortización furgo + parte de reparto (no nómina de reparto, que ya está en OPEX)
A8: Recargo Athos (recogida 3€/pedido, seguro, etc.) % | B8: 0.05
A10: TARIFA ATHOS POR CCAA Y TRAMO DE PESO (€ por ENVÍO) — editable
A11: Comunidad Autónoma | B11: 0-25 kg | C11: 26-50 kg | D11: 51-100 kg | E11: 101-150 kg | F11: 151-200 kg | G11: 201-299 kg | H11: % de ventas fuera | I11: €/kg equivalente | J11: kg/mes régimen | K11: Coste/mes régimen
A12: Andalucía | B12: 29.05 | C12: 42.97 | D12: 59.17 | E12: 73.92 | F12: 84.56 | G12: 98.96 | H12: 0.12 | I12: =(IF($B$6<=25,B12,IF($B$6<=50,C12,IF($B$6<=100,D12,IF($B$6<=150,E12,IF($B$6<=200,F12,G12))))))/$B$6*(1+$B$8) -> 0.77660625 | J12: =$B$31*H12 -> 123.37753 | K12: =I12*J12 -> 95.815758
A13: Aragón | B13: 34.76 | C13: 46.14 | D13: 68.79 | E13: 77.41 | F13: 86.13 | G13: 94.68 | H13: 0.05 | I13: =(IF($B$6<=25,B13,IF($B$6<=50,C13,IF($B$6<=100,D13,IF($B$6<=150,E13,IF($B$6<=200,F13,G13))))))/$B$6*(1+$B$8) -> 0.90286875 | J13: =$B$31*H13 -> 51.407303 | K13: =I13*J13 -> 46.414047
A14: Asturias | B14: 27.08 | C14: 37.11 | D14: 48.64 | E14: 68.89 | F14: 83.48 | G14: 98.02 | H14: 0.03 | I14: =(IF($B$6<=25,B14,IF($B$6<=50,C14,IF($B$6<=100,D14,IF($B$6<=150,E14,IF($B$6<=200,F14,G14))))))/$B$6*(1+$B$8) -> 0.6384 | J14: =$B$31*H14 -> 30.844382 | K14: =I14*J14 -> 19.691053
A15: Cantabria | B15: 35.5 | C15: 43.1 | D15: 53.65 | E15: 68.71 | F15: 80.85 | G15: 99.06 | H15: 0.02 | I15: =(IF($B$6<=25,B15,IF($B$6<=50,C15,IF($B$6<=100,D15,IF($B$6<=150,E15,IF($B$6<=200,F15,G15))))))/$B$6*(1+$B$8) -> 0.70415625 | J15: =$B$31*H15 -> 20.562921 | K15: =I15*J15 -> 14.479509
A16: Castilla y León | B16: 37.7 | C16: 49.44 | D16: 61.97 | E16: 75.31 | F16: 90.68 | G16: 100.84 | H16: 0.1 | I16: =(IF($B$6<=25,B16,IF($B$6<=50,C16,IF($B$6<=100,D16,IF($B$6<=150,E16,IF($B$6<=200,F16,G16))))))/$B$6*(1+$B$8) -> 0.81335625 | J16: =$B$31*H16 -> 102.81461 | K16: =I16*J16 -> 83.624902
A17: Castilla-La Mancha | B17: 30.81 | C17: 40.86 | D17: 51.93 | E17: 65.67 | F17: 75.28 | G17: 87.47 | H17: 0.14 | I17: =(IF($B$6<=25,B17,IF($B$6<=50,C17,IF($B$6<=100,D17,IF($B$6<=150,E17,IF($B$6<=200,F17,G17))))))/$B$6*(1+$B$8) -> 0.68158125 | J17: =$B$31*H17 -> 143.94045 | K17: =I17*J17 -> 98.10711
A18: Cataluña | B18: 29.42 | C18: 42.71 | D18: 54.18 | E18: 66.64 | F18: 77.35 | G18: 91.02 | H18: 0.2 | I18: =(IF($B$6<=25,B18,IF($B$6<=50,C18,IF($B$6<=100,D18,IF($B$6<=150,E18,IF($B$6<=200,F18,G18))))))/$B$6*(1+$B$8) -> 0.7111125 | J18: =$B$31*H18 -> 205.62921 | K18: =I18*J18 -> 146.2255
A19: C. Valenciana | B19: 31.15 | C19: 41.35 | D19: 61.65 | E19: 69.37 | F19: 77.2 | G19: 84.84 | H19: 0.12 | I19: =(IF($B$6<=25,B19,IF($B$6<=50,C19,IF($B$6<=100,D19,IF($B$6<=150,E19,IF($B$6<=200,F19,G19))))))/$B$6*(1+$B$8) -> 0.80915625 | J19: =$B$31*H19 -> 123.37753 | K19: =I19*J19 -> 99.831696
A20: Extremadura | B20: 28.39 | C20: 42.97 | D20: 59.11 | E20: 73.62 | F20: 85.18 | G20: 98.3 | H20: 0.03 | I20: =(IF($B$6<=25,B20,IF($B$6<=50,C20,IF($B$6<=100,D20,IF($B$6<=150,E20,IF($B$6<=200,F20,G20))))))/$B$6*(1+$B$8) -> 0.77581875 | J20: =$B$31*H20 -> 30.844382 | K20: =I20*J20 -> 23.92965
A21: Galicia | B21: 28.39 | C21: 42.97 | D21: 59.11 | E21: 73.62 | F21: 85.18 | G21: 98.3 | H21: 0.05 | I21: =(IF($B$6<=25,B21,IF($B$6<=50,C21,IF($B$6<=100,D21,IF($B$6<=150,E21,IF($B$6<=200,F21,G21))))))/$B$6*(1+$B$8) -> 0.77581875 | J21: =$B$31*H21 -> 51.407303 | K21: =I21*J21 -> 39.882749
A22: La Rioja | B22: 36.87 | C22: 48.96 | D22: 73.02 | E22: 82.15 | F22: 91.44 | G22: 100.49 | H22: 0.02 | I22: =(IF($B$6<=25,B22,IF($B$6<=50,C22,IF($B$6<=100,D22,IF($B$6<=150,E22,IF($B$6<=200,F22,G22))))))/$B$6*(1+$B$8) -> 0.9583875 | J22: =$B$31*H22 -> 20.562921 | K22: =I22*J22 -> 19.707246
A23: Murcia | B23: 35.9 | C23: 47.66 | D23: 71.08 | E23: 79.96 | F23: 88.98 | G23: 97.8 | H23: 0.04 | I23: =(IF($B$6<=25,B23,IF($B$6<=50,C23,IF($B$6<=100,D23,IF($B$6<=150,E23,IF($B$6<=200,F23,G23))))))/$B$6*(1+$B$8) -> 0.932925 | J23: =$B$31*H23 -> 41.125842 | K23: =I23*J23 -> 38.367326
... A25: País Vasco | B25: 35.36 | C25: 42.9 | D25: 53.41 | E25: 68.41 | F25: 80.5 | G25: 98.63 | H25: 0.06 | I25: =(IF($B$6<=25,B25,IF($B$6<=50,C25,IF($B$6<=100,D25,IF($B$6<=150,E25,IF($B$6<=200,F25,G25))))))/$B$6*(1+$B$8) -> 0.70100625 | J25: =$B$31*H25 -> 61.688763 | K25: =I25*J25 -> 43.244208
A26: TOTAL FUERA DE MADRID | H26: =SUM(H12:H25) -> 1 | J26: =SUM(J12:J25) -> 1028.1461 | K26: =SUM(K12:K25) -> 789.028
A28: REPARTO DE LA PRODUCCIÓN (régimen, mes 84)
A29: Producción total (kg/mes) | B29: =Modelo_Mensual!$CH$26 -> 2937.5601
A30: kg/mes en Madrid (furgo propia) | B30: =$B$29*(1-$B$5) -> 1909.4141
A31: kg/mes fuera de Madrid (Athos) | B31: =$B$29*$B$5 -> 1028.1461
A32: Coste logístico Madrid (€/mes) | B32: =$B$30*$B$7 -> 343.69454
A33: Coste logístico fuera Madrid (€/mes) | B33: =K26 -> 789.028
A34: COSTE LOGÍSTICO TOTAL (€/mes régimen) | B34: =$B$32+$B$33 -> 1132.7225
A35: Coste logístico medio (€/kg) | B35: =IFERROR($B$34/$B$29,0) -> 0.38559978
A36: Coste logístico total como % de ingresos | B36: =IFERROR($B$34/Modelo_Mensual!$CH$36,0) -> 0.010431922
A37: Nota: Athos cobra por ENVÍO según peso; agrupar pedidos de una misma CCAA en un envío mayor abarata mucho el €/kg (mira cómo baja al subir el peso medio por envío). Devoluciones +15%, aeropuerto +30€.
A39: €/kg medio ponderado FUERA (para el modelo mensual) | B39: =IFERROR(SUMPRODUCT(H12:H25,I12:I25)/SUM(H12:H25),0) -> 0.76742794

Sheet Hipótesis
A1: ROOTFLOW — Hipótesis del modelo
A2: Celdas azules = inputs. El selector de escenario reescribe la columna "Activo".
A4: ESCENARIO ACTIVO (1 = Conservador · 2 = Base · 3 = Optimista) | C4: 2 | D4: =CHOOSE($C$4,"CONSERVADOR","BASE","OPTIMISTA") -> BASE
A6: Concepto | B6: Unidad | C6: Conservador | D6: Base | E6: Optimista | F6: Activo
A7: GEOMETRÍA DEL RACK
A8: Rack ANTIGUO — bandejas por rack | B8: bandejas | D8: 32
A9: Rack NUEVO — superficie de cultivo POR NIVEL | B9: m²/nivel | D9: 24
A10: Rack NUEVO — nº de niveles | B10: niveles | D10: 6
A11: Superficie ocupada por bandeja | B11: m²/band | D11: 0.15
A12: Bandejas por nivel — CALCULADO | B12: bandejas | D12: =ROUNDDOWN(D9/D11,0) -> 160
A13: BANDEJAS POR RACK NUEVO — CALCULADO | B13: bandejas | D13: =D12*D10 -> 960
A14: Superficie de cultivo por rack — CALCULADO | B14: m² | D14: =D9*D10 -> 144
A15: AJUSTE POR ESCENARIO (flexiona la economía de Producto)
A16: Ajuste de PRECIO de venta (Cons=actual · Base +20% · Opt +35%) | B16: % | C16: 1 | D16: 1.2 | E16: 1.35 | F16: =CHOOSE($C$4,C16,D16,E16) -> 1.2
A17: Ajuste de RENDIMIENTO / kg | B17: % | C17: 0.92 | D17: 1 | E17: 1.06 | F17: =CHOOSE($C$4,C17,D17,E17) -> 1
A18: Ajuste de COSTE de producto (Cons=actual · Base −15% · Opt −25%) | B18: % | C18: 1 | D18: 0.85 | E18: 0.75 | F18: =CHOOSE($C$4,C18,D18,E18) -> 0.85
A19: ECONOMÍA POR BANDEJA (Producto × escenario)
A20: Ingreso por bandeja — DIRECTO | B20: €/band/mes | C20: =Producto!$T$32*Hipótesis!$C$16*Hipótesis!$C$17 -> 40.607542 | D20: =Producto!$T$32*Hipótesis!$D$16*Hipótesis!$D$17 -> 52.966359 | E20: =Producto!$T$32*Hipótesis!$E$16*Hipótesis!$E$17 -> 63.162383 | F20: =CHOOSE($C$4,C20,D20,E20) -> 52.966359
A21: Ingreso por bandeja — DISTRIBUIDOR | B21: €/band/mes | C21: =Producto!$T$32/Producto!$D$5*Hipótesis!$C$16*Hipótesis!$C$17 -> 31.236571 | D21: =Producto!$T$32/Producto!$D$5*Hipótesis!$D$16*Hipótesis!$D$17 -> 40.743353 | E21: =Producto!$T$32/Producto!$D$5*Hipótesis!$E$16*Hipótesis!$E$17 -> 48.586449 | F21: =CHOOSE($C$4,C21,D21,E21) -> 40.743353
A22: COGS por bandeja | B22: €/band/mes | C22: =Producto!$S$32*Hipótesis!$C$18 -> 7.6733686 | D22: =Producto!$S$32*Hipótesis!$D$18 -> 6.5223633 | E22: =Producto!$S$32*Hipótesis!$E$18 -> 5.7550265 | F22: =CHOOSE($C$4,C22,D22,E22) -> 6.5223633
A23: Rendimiento por bandeja | B23: kg/band/mes | C23: =Producto!$M$32*Hipótesis!$C$17 -> 1.0327161 | D23: =Producto!$M$32*Hipótesis!$D$17 -> 1.1225175 | E23: =Producto!$M$32*Hipótesis!$E$17 -> 1.1898685 | F23: =CHOOSE($C$4,C23,D23,E23) -> 1.1225175
A24: Ciclos (siembras) por posición y mes | B24: ciclos/mes | C24: =Producto!$J$32 -> 6.8527168 | D24: =Producto!$J$32 -> 6.8527168 | E24: =Producto!$J$32 -> 6.8527168 | F24: =CHOOSE($C$4,C24,D24,E24) -> 6.8527168
A25: CAPACIDAD Y RAMPA
A26: Capacidad total de la nave (racks NUEVOS) ← manda sobre el CAPEX | B26: racks | C26: 3 | D26: 3 | E26: 3 | F26: =CHOOSE($C$4,C26,D26,E26) -> 3
A27: Racks operativos al abrir (mes 1) | B27: racks | C27: 1 | D27: 1 | E27: 1 | F27: =CHOOSE($C$4,C27,D27,E27) -> 1
A28: Ritmo de instalación de racks | B28: racks/mes | C28: 0.5 | D28: 0.5 | E28: 0.5 | F28: =CHOOSE($C$4,C28,D28,E28) -> 0.5
A29: Capa ADICIONAL: mes de inicio de captación de nuevas cuentas | B29: mes | C29: 6 | D29: 6 | E29: 6 | F29: =CHOOSE($C$4,C29,D29,E29) -> 6
A30: Capa adicional: % a cliente DIRECTO (igual en los 3) | B30: % | C30: 0.3 | D30: 0.3 | E30: 0.3 | F30: =CHOOSE($C$4,C30,D30,E30) -> 0.3
A31: Capa ADICIONAL (nuevas cuentas): utilización inicial | B31: % | C31: 0 | D31: 0 | E31: 0 | F31: =CHOOSE($C$4,C31,D31,E31) -> 0
A32: Capa ADICIONAL: techo de utilización (igual en los 3 casos) | B32: % | C32: 0.55 | D32: 0.55 | E32: 0.55 | F32: =CHOOSE($C$4,C32,D32,E32) -> 0.55
A33: Capa ADICIONAL: meses hasta el techo | B33: meses | C33: 36 | D33: 36 | E33: 36 | F33: =CHOOSE($C$4,C33,D33,E33) -> 36
A34: Merma + comercial + impagados (igual en los 3) | B34: % | C34: 0.1 | D34: 0.1 | E34: 0.1 | F34: =CHOOSE($C$4,C34,D34,E34) -> 0.1
A35: COSTES FIJOS (mensual, sin nóminas)
A36: Alquiler de la nave (350 m²) | B36: €/mes | C36: 2250 | D36: 2000 | E36: 1800 | F36: =CHOOSE($C$4,C36,D36,E36) -> 2000
A37: Suministros — parte fija | B37: €/mes | C37: 400 | D37: 1000 | E37: 300 | F37: =CHOOSE($C$4,C37,D37,E37) -> 1000
A38: Electricidad variable por posición iluminada | B38: €/pos/mes | C38: 0.75 | D38: 0.55 | E38: 0.55 | F38: =CHOOSE($C$4,C38,D38,E38) -> 0.55
A39: Vehículo de reparto — renting + combustible | B39: €/mes | C39: 700 | D39: 800 | E39: 500 | F39: =CHOOSE($C$4,C39,D39,E39) -> 800
A40: Otros opex (gestoría, seguros, software, marketing) | B40: €/mes | C40: 700 | D40: 500 | E40: 500 | F40: =CHOOSE($C$4,C40,D40,E40) -> 500
A41: NÓMINAS — cada línea alimenta SU PROPIA fila de OPEX
A42: Coste Seguridad Social empresa (% s/ bruto) | B42: % | D42: 0.32
...

Sheet Mano_de_obra
A1: ROOTFLOW — Mano de obra y dimensionamiento de plantilla
A2: La mano de obra es el coste real del negocio. Aquí se ve cuántas horas exige la producción y cuántas cubre la plantilla.
A4: MINUTOS POR BANDEJA (según escenario activo)
A5: Conservador (a mano) | B5: =Producto!$D$8 -> 4
A6: Base (lavadora + cinta/cosecha) | B6: =Producto!$D$9 -> 3
A7: Optimista (+ sembradora) | B7: =Producto!$D$10 -> 2
A8: MINUTOS/bandeja ACTIVO | B8: =Producto!$D$11 -> 3
A9: Escenario | B9: =CHOOSE(Hipótesis!$C$4,"Conservador","Base","Optimista") -> Base
A11: PLANTILLA (viene de Hipótesis) — horas de bandeja por persona
A12: Rol | B12: Activo | C12: Alta (mes) | D12: Horas bandeja/mes | E12: ¿Socio?
A13: =Hipótesis!A48 -> Pedro — socio (finanzas) | B13: =Hipótesis!B48 -> 1 | C13: =Hipótesis!D48 -> 1 | D13: =Hipótesis!F48 -> 0 | E13: =Hipótesis!G48 -> 1
A14: =Hipótesis!A49 -> Nico — socio (comercial) | B14: =Hipótesis!B49 -> 1 | C14: =Hipótesis!D49 -> 1 | D14: =Hipótesis!F49 -> 0 | E14: =Hipótesis!G49 -> 1
A15: =Hipótesis!A50 -> Guzmán — socio (producción) | B15: =Hipótesis!B50 -> 1 | C15: =Hipótesis!D50 -> 1 | D15: =Hipótesis!F50 -> 160 | E15: =Hipótesis!G50 -> 1
A16: =Hipótesis!A51 -> Encargado de producción | B16: =Hipótesis!B51 -> 1 | C16: =Hipótesis!D51 -> 1 | D16: =Hipótesis!F51 -> 160 | E16: =Hipótesis!G51 -> 0
A17: =Hipótesis!A52 -> Comercial / KAM | B17: =Hipótesis!B52 -> 1 | C17: =Hipótesis!D52 -> 20 | D17: =Hipótesis!F52 -> 0 | E17: =Hipótesis!G52 -> 0
A18: =Hipótesis!A53 -> (rol fijo libre) | B18: =Hipótesis!B53 -> 0 | C18: =Hipótesis!D53 -> 24 | D18: =Hipótesis!F53 -> 160 | E18: =Hipótesis!G53 -> 0
A19: Horas de bandeja disponibles en régimen (plantilla activa) | D19: =SUMPRODUCT(Hipótesis!$B$48:$B$53,Hipótesis!$F$48:$F$53) -> 320
A21: CARGA DE TRABAJO EN RÉGIMEN (mes 84)
A22: Bandejas sembradas/mes | B22: =Modelo_Mensual!$CH$27 -> 17856.202
A23: Horas de bandeja NECESARIAS/mes | B23: =Modelo_Mensual!$CH$28 -> 892.8101
A24: Horas de la plantilla FIJA (Guzmán + encargado) | B24: =Modelo_Mensual!$CH$29 -> 320
A25: OPERARIOS DE CULTIVO necesarios (nº) | B25: =Modelo_Mensual!$CH$30 -> 4
A26: Coste de esos operarios (€/mes) | B26: =-Modelo_Mensual!$CH$50 -> 10717.813
A27: PLANTILLA TOTAL (fijos + operarios) | B27: =Modelo_Mensual!$CH$31 -> 9
A28: Coste TOTAL de nóminas (€/mes) | B28: =-Modelo_Mensual!$CH$51 -> 40782.41
A30: Los operarios se calculan solos: a menos minutos por bandeja (más automatización), menos operarios. Por eso el Optimista tiene más CAPEX pero menos nómina.

Sheet CAPEX
A1: ROOTFLOW — Plan de inversión y necesidad de financiación
A2: Bottom-up de cuánto dinero hay que levantar para el salto a la nave.
A4: Concepto | C4: Importe (€) | D4: Nota | E4: CONSERVADOR | F4: BASE | G4: OPTIMISTA
A5: Adaptación de nave (clima, eléctrico trifásico, fontanería) | C5: 40000
A6: AUTOMATIZACIÓN (se activa según escenario):
A7: · Lavadora de bandejas | C7: 3000 | D7: Incluida en BASE y OPTIMISTA
A8: · Cinta / cosecha asistida | C8: 7000 | D8: Incluida en BASE y OPTIMISTA
A9: · Sembradora automática | C9: 25000 | D9: Incluida solo en OPTIMISTA
A10: Automatización incluida en el escenario ACTIVO | C10: =IF(Hipótesis!$C$4>=2,C7+C8,0)+IF(Hipótesis!$C$4=3,C9,0) -> 10000 | D10: Conservador=0 · Base=10.000 · Optimista=35.000 | E10: =0 -> 0 | F10: =C7+C8 -> 10000 | G10: =C7+C8+C9 -> 35000
A11: Coste de construcción por rack NUEVO | C11: 1600
A12: Nº de racks a construir | C12: =Hipótesis!$F$26 -> 3 | D12: ENLAZADO a la capacidad de Hipótesis (una sola fuente)
A13: Racks de cultivo (total) | C13: =C11*C12 -> 4800
A14: Instalación y montaje (mano de obra) | C14: 10000
A15: Vehículo de reparto (0 = renting) | C15: 0
A16: Mobiliario, utillaje, EPIs, varios | C16: 10000
A17: Licencias, proyecto técnico e ingeniería | C17: 6000
A18: Legal / estructuración (ENISA + inversor) | C18: 5000
A19: SUBTOTAL CAPEX | C19: =C5+C10+C13+SUM(C14:C18) -> 85800 | E19: =C5+E10+C13+SUM(C14:C18) -> 75800 | F19: =C5+F10+C13+SUM(C14:C18) -> 85800 | G19: =C5+G10+C13+SUM(C14:C18) -> 110800
A20: Contingencia (% s/ CAPEX) | C20: 0.15 | D20: Imprevistos de obra/equipo
A21: Contingencia (€) | C21: =C19*C20 -> 12870 | E21: =E19*C20 -> 11370 | F21: =F19*C20 -> 12870 | G21: =G19*C20 -> 16620
A22: CAPEX + Contingencia | C22: =C19+C21 -> 98670 | E22: =E19+E21 -> 87170 | F22: =F19+F21 -> 98670 | G22: =G19+G21 -> 127420
A23: Meses de colchón de arranque (pérdidas de la rampa) | C23: 4 | D23: El circulante va aparte, en su propia línea
A24: Coste fijo mensual al arrancar (€) | C24: =Hipótesis!$F$36+Hipótesis!$F$37+Hipótesis!$F$39+Hipótesis!$F$40+Hipótesis!$E$55 -> 15652 | D24: Alquiler + suministros + vehículo + otros + NÓMINAS FIJAS DEL MES 1 | E24: =Hipótesis!$C$36+Hipótesis!$C$37+Hipótesis!$C$39+Hipótesis!$C$40+Hipótesis!$E$55 -> 15402 | F24: =Hipótesis!$D$36+Hipótesis!$D$37+Hipótesis!$D$39+Hipótesis!$D$40+Hipótesis!$E$55 -> 15652 | G24: =Hipótesis!$E$36+Hipótesis!$E$37+Hipótesis!$E$39+Hipótesis!$E$40+Hipótesis!$E$55 -> 14452
A25: Colchón de circulante (€) | C25: =C23*C24 -> 62608 | E25: =C23*E24 -> 61608 | F25: =C23*F24 -> 62608 | G25: =C23*G24 -> 57808
A26: TOTAL INVERSIÓN = NECESIDAD DE FINANCIACIÓN | C26: =C22+C25 -> 161278 | E26: =E22+E25 -> 148778 | F26: =F22+F25 -> 161278 | G26: =G22+G25 -> 185228
A27: Circulante máximo (NOF) — NO se levanta: va a póliza de crédito | E27: =MAX(Esc_Conservador!$C$70:$CH$70) -> 21559.379 | F27: =MAX(Esc_Base!$C$70:$CH$70) -> 22410.526 | G27: =MAX(Esc_Optimista!$C$70:$CH$70) -> 15995.741
A28: Póliza máxima dispuesta en el plan (debe caber en el límite) | C28: Mes 1 | D28: Mes 2 | E28: =MAX(Esc_Conservador!$C$81:$CH$81) -> 34041.057 | F28: =MAX(Esc_Base!$C$81:$CH$81) -> 4694.5064 | G28: =MAX(Esc_Optimista!$C$81:$CH$81) -> 7280.3801 | H28: Mes 6 | I28: Mes 7 | J28: Mes 8 | K28: Mes 9 | L28: Mes 10 | M28: Mes 11 | N28: Mes 12
A29: % desplegado | C29: 0.3 | D29: 0.14 | E29: 0.1 | F29: 0.09 | G29: 0.08 | H29: 0.07 | I29: 0.06 | J29: 0.05 | K29: 0.04 | L29: 0.03 | M29: 0.02 | N29: 0.02
A30: Suma (debe ser 100%) | C30: =SUM(C29:N29) -> 1
A32: Las columnas Conservador/Base/Optimista calculan la inversión de cada caso a la vez (el Resumen las usa para comparar). La columna C es la del escenario ACTIVO.

Sheet Modelo_Mensual
A1: ROOTFLOW — Modelo mensual · ESCENARIO ACTIVO (84 meses)
A2: Sigue al selector de Hipótesis!C4. Para el detalle mensual del caso que estés mirando.
A3: Mes | C3: 1 | D3: 2 | E3: 3 | F3: 4 | G3: 5 | H3: 6 | I3: 7 | J3: 8 | K3: 9 | L3: 10 | M3: 11 | N3: 12 | O3: 13 | P3: 14 | Q3: 15 | R3: 16 | S3: 17 | T3: 18 | U3: 19 | V3: 20 | W3: 21 | X3: 22 | Y3: 23 | Z3: 24 | AA3: 25 | AB3: 26 | AC3: 27 | AD3: 28 | AE3: 29 | AF3: 30 | AG3: 31 | AH3: 32 | AI3: 33 | AJ3: 34 | AK3: 35 | AL3: 36 | AM3: 37 | AN3: 38 | AO3: 39 | AP3: 40 | AQ3: 41 | AR3: 42 | AS3: 43 | AT3: 44 | AU3: 45 | AV3: 46 | AW3: 47 | AX3: 48 | AY3: 49 | AZ3: 50 | BA3: 51 | BB3: 52 | BC3: 53 | BD3: 54 | BE3: 55 | BF3: 56 | BG3: 57 | BH3: 58 | BI3: 59 | BJ3: 60 | BK3: 61 | BL3: 62 | BM3: 63 | BN3: 64 | BO3: 65 | BP3: 66 | BQ3: 67 | BR3: 68 | BS3: 69 | BT3: 70 | BU3: 71 | BV3: 72 | BW3: 73 | BX3: 74 | BY3: 75 | BZ3: 76 | CA3: 77 | CB3: 78 | CC3: 79 | CD3: 80 | CE3: 81 | CF3: 82 | CG3: 83 | CH3: 84
A4: Año | C4: =INT((1-1)/12)+1 -> 1 | D4: =INT((2-1)/12)+1 -> 1 | E4: =INT((3-1)/12)+1 -> 1 | F4: =INT((4-1)/12)+1 -> 1 | G4: =INT((5-1)/12)+1 -> 1 | H4: =INT((6-1)/12)+1 -> 1 | I4: =INT((7-1)/12)+1 -> 1 | J4: =INT((8-1)/12)+1 -> 1 | K4: =INT((9-1)/12)+1 -> 1 | L4: =INT((10-1)/12)+1 -> 1 | M4: =INT((11-1)/12)+1 -> 1 | N4: =INT((12-1)/12)+1 -> 1 | O4: =INT((13-1)/12)+1 -> 2 | P4: =INT((14-1)/12)+1 -> 2 | Q4: =INT((15-1)/12)+1 -> 2 | R4: =INT((16-1)/12)+1 -> 2 | S4: =INT((17-1)/12)+1 -> 2 | T4: =INT((18-1)/12)+1 -> 2 | U4: =INT((19-1)/12)+1 -> 2 | V4: =INT((20-1)/12)+1 -> 2 | W4: =INT((21-1)/12)+1 -> 2 | X4: =INT((22-1)/12)+1 -> 2 | Y4: =INT((23-1)/12)+1 -> 2 | Z4: =INT((24-1)/12)+1 -> 2 | AA4: =INT((25-1)/12)+1 -> 3 | AB4: =INT((26-1)/12)+1 -> 3 | AC4: =INT((27-1)/12)+1 -> 3 | AD4: =INT((28-1)/12)+1 -> 3 | AE4: =INT((29-1)/12)+1 -> 3 | AF4: =INT((30-1)/12)+1 -> 3 | AG4: =INT((31-1)/12)+1 -> 3 | AH4: =INT((32-1)/12)+1 -> 3 | AI4: =INT((33-1)/12)+1 -> 3 | AJ4: =INT((34-1)/12)+1 -> 3 | AK4: =INT((35-1)/12)+1 -> 3 | AL4: =INT((36-1)/12)+1 -> 3 | AM4: =INT((37-1)/12)+1 -> 4 | AN4: =INT((38-1)/12)+1 -> 4 | AO4: =INT((39-1)/12)+1 -> 4 | AP4: =INT((40-1)/12)+1 -> 4 | AQ4: =INT((41-1)/12)+1 -> 4 | AR4: =INT((42-1)/12)+1 -> 4 | AS4: =INT((43-1)/12)+1 -> 4 | AT4: =INT((44-1)/12)+1 -> 4 | AU4: =INT((45-1)/12)+1 -> 4 | AV4: =INT((46-1)/12)+1 -> 4 | AW4: =INT((47-1)/12)+1 -> 4 | AX4: =INT((48-1)/12)+1 -> 4 | AY4: =INT((49-1)/12)+1 -> 5 | AZ4: =INT((50-1)/12)+1 -> 5 | BA4: =INT((51-1)/12)+1 -> 5 | BB4: =INT((52-1)/12)+1 -> 5 | BC4: =INT((53-1)/12)+1 -> 5 | BD4: =INT((54-1)/12)+1 -> 5 | BE4: =INT((55-1)/12)+1 -> 5 | BF4: =INT((56-1)/12)+1 -> 5 | BG4: =INT((57-1)/12)+1 -> 5 | BH4: =INT((58-1)/12)+1 -> 5 | BI4: =INT((59-1)/12)+1 -> 5 | BJ4: =INT((60-1)/12)+1 -> 5 | BK4: =INT((61-1)/12)+1 -> 6 | BL4: =INT((62-1)/12)+1 -> 6 | BM4: =INT((63-1)/12)+1 -> 6 | BN4: =INT((64-1)/12)+1 -> 6 | BO4: =INT((65-1)/12)+1 -> 6 | BP4: =INT((66-1)/12)+1 -> 6 | BQ4: =INT((67-1)/12)+1 -> 6 | BR4: =INT((68-1)/12)+1 -> 6 | BS4: =INT((69-1)/12)+1 -> 6 | BT4: =INT((70-1)/12)+1 -> 6 | BU4: =INT((71-1)/12)+1 -> 6 | BV4: =INT((72-1)/12)+1 -> 6 | BW4: =INT((73-1)/12)+1 -> 7 | BX4: =INT((74-1)/12)+1 -> 7 | BY4: =INT((75-1)/12)+1 -> 7 | BZ4: =INT((76-1)/12)+1 -> 7 | CA4: =INT((77-1)/12)+1 -> 7 | CB4: =INT((78-1)/12)+1 -> 7 | CC4: =INT((79-1)/12)+1 -> 7 | CD4: =INT((80-1)/12)+1 -> 7 | CE4: =INT((81-1)/12)+1 -> 7 | CF4: =INT((82-1)/12)+1 -> 7 | CG4: =INT((83-1)/12)+1 -> 7 | CH4: =INT((84-1)/12)+1 -> 7
A6: CAPACIDAD, DEMANDA IDENTIFICADA Y MANO DE OBRA
A7: Racks instalados | C7: =MIN(Hipótesis!$F$26,Hipótesis!$F$27+Hipótesis!$F$28*(1-1)) -> 1 | D7: =MIN(Hipótesis!$F$26,Hipótesis!$F$27+Hipótesis!$F$28*(2-1)) -> 1.5 | E7: =MIN(Hipótesis!$F$26,Hipótesis!$F$27+Hipótesis!$F$28*(3-1)) -> 2 | F7: =MIN(Hipótesis!$F$26,Hipótesis!$F$27+Hipótesis!$F$28*(4-1)) -> 2.5 | G7: =MIN(Hipótesis!$F$26,Hipótesis!$F$27+Hipótesis!$F$28*(5-1)) -> 3 | H7: =MIN(Hipótesis!$F$26,Hipótesis!$F$27+Hipótesis!$F$28*(6-1)) -> 3 | I7: =MIN(Hipótesis!$F$26,Hipótesis!$F$27+Hipótesis!$F$28*(7-1)) -> 3 | J7: =MIN(Hipótesis!$F$26,Hipótesis!$F$27+Hipótesis!$F$28*(8-1)) -> 3 | K7: =MIN(Hipótesis!$F$26,Hipótesis!$F$27+Hipótesis!$F$28*(9-1)) -> 3 | L7: =MIN(Hipótesis!$F$26,Hipótesis!$F$27+Hipótesis!$F$28*(10-1)) -> 3 | M7: =MIN(Hipótesis!$F$26,Hipótesis!$F$27+Hipótesis!$F$28*(11-1)) -> 3 | N7: =MIN(Hipótesis!$F$26,Hipótesis!$F$27+Hipótesis!$F$28*(12-1)) -> 3 | O7: =MIN(Hipótesis!$F$26,Hipótesis!$F$27+Hipótesis!$F$28*(13-1)) -> 3 | P7: =MIN(Hipótesis!$F$26,Hipótesis!$F$27+Hipótesis!$F$28*(14-1)) -> 3 | Q7: =MIN(Hipótesis!$F$26,Hipótesis!$F$27+Hipótesis!$F$28*(15-1)) -> 3 | R7: =MIN(Hipótesis!$F$26,Hipótesis!$F$27+Hipótesis!$F$28*(16-1)) -> 3 | S7: =MIN(Hipótesis!$F$26,Hipótesis!$F$27+Hipótesis!$F$28*(17-1)) -> 3 | T7: =MIN(Hipótesis!$F$26,Hipótesis!$F$27+Hipótesis!$F$28*(18-1)) -> 3 | U7: =MIN(Hipótesis!$F$26,Hipótesis!$F$27+Hipótesis!$F$28*(19-1)) -> 3 | V7: =MIN(Hipótesis!$F$26,Hipótesis!$F$27+Hipótesis!$F$28*(20-1)) -> 3 | W7: =MIN(Hipótesis!$F$26,Hipótesis!$F$27+Hipótesis!$F$28*(21-1)) -> 3 | X7: =MIN(Hipótesis!$F$26,Hipótesis!$F$27+Hipótesis!$F$28*(22-1)) -> 3 | Y7: =MIN(Hipótesis!$F$26,Hipótesis!$F$27+Hipótesis!$F$28*(23-1)) -> 3 | Z7: =MIN(Hipótesis!$F$26,Hipótesis!$F$27+Hipótesis!$F$28*(24-1)) -> 3 | AA7: =MIN(Hipótesis!$F$26,Hipótesis!$F$27+Hipótesis!$F$28*(25-1)) -> 3 | AB7: =MIN(Hipótesis!$F$26,Hipótesis!$F$27+Hipótesis!$F$28*(26-1)) -> 3 | AC7: =MIN(Hipótesis!$F$26,Hipótesis!$F$27+Hipótesis!$F$28*(27-1)) -> 3 | AD7: =MIN(Hipótesis!$F$26,Hipótesis!$F$27+Hipótesis!$F$28*(28-1)) -> 3 | AE7: =MIN(Hipótesis!$F$26,Hipótesis!$F$27+Hipótesis!$F$28*(29-1)) -> 3 | AF7: =MIN(Hipótesis!$F$26,Hipótesis!$F$27+Hipótesis!$F$28*(30-1)) -> 3 | AG7: =MIN(Hipótesis!$F$26,Hipótesis!$F$27+Hipótesis!$F$28*(31-1)) -> 3 | AH7: =MIN(Hipótesis!$F$26,Hipótesis!$F$27+Hipótesis!$F$28*(32-1)) -> 3 | AI7: =MIN(Hipótesis!$F$26,Hipótesis!$F$27+Hipótesis!$F$28*(33-1)) -> 3 | AJ7: =MIN(Hipótesis!$F$26,Hipótesis!$F$27+Hipótesis!$F$28*(34-1)) -> 3 | AK7: =MIN(Hipótesis!$F$26,Hipótesis!$F$27+Hipótesis!$F$28*(35-1)) -> 3 | AL7: =MIN(Hipótesis!$F$26,Hipótesis!$F$27+Hipótesis!$F$28*(36-1)) -> 3 | AM7: =MIN(Hipótesis!$F$26,Hipótesis!$F$27+Hipótesis!$F$28*(37-1)) -> 3 | AN7: =MIN(Hipótesis!$F$26,Hipótesis!$F$27+Hipótesis!$F$28*(38-1)) -> 3 | AO7: =MIN(Hipótesis!$F$26,Hipótesis!$F$27+Hipótesis!$F$28*(39-1)) -> 3 | AP7: =MIN(Hipótesis!$F$26,Hipótesis!$F$27+Hipótesis!$F$28*(40-1)) -> 3 | AQ7: =MIN(Hipótesis!$F$26,Hipótesis!$F$27+Hipótesis!$F$28*(41-1)) -> 3 | AR7: =MIN(Hipótesis!$F$26,Hipótesis!$F$27+Hipótesis!$F$28*(42-1)) -> 3 | AS7: =MIN(Hipótesis!$F$26,Hipótesis!$F$27+Hipótesis!$F$28*(43-1)) -> 3 | AT7: =MIN(Hipótesis!$F$26,Hipótesis!$F$27+Hipótesis!$F$28*(44-1)) -> 3 | AU7: =MIN(Hipótesis!$F$26,Hipótesis!$F$27+Hipótesis!$F$28*(45-1)) -> 3 | AV7: =MIN(Hipótesis!$F$26,Hipótesis!$F$27+Hipótesis!$F$28*(46-1)) -> 3 | AW7: =MIN(Hipótesis!$F$26,Hipótesis!$F$27+Hipótesis!$F$28*(47-1)) -> 3 | AX7: =MIN(Hipótesis!$F$26,Hipótesis!$F$27+Hipótesis!$F$28*(48-1)) -> 3 | AY7: =MIN(Hipótesis!$F$26,Hipótesis!$F$27+Hipótesis!$F$28*(49-1)) -> 3 | AZ7: =MIN(Hipótesis!$F$26,Hipótesis!$F$27+Hipótesis!$F$28*(50-1)) -> 3 | BA7: =MIN(Hipótesis!$F$26,Hipótesis!$F$27+Hipótesis!$F$28*(51-1)) -> 3 | BB7: =MIN(Hipótesis!$F$26,Hipótesis!$F$27+Hipótesis!$F$28*(52-1)) -> 3 | BC7: =MIN(Hipótesis!$F$26,Hipótesis!$F$27+Hipótesis!$F$28*(53-1)) -> 3 | BD7: =MIN(Hipótesis!$F$26,Hipótesis!$F$27+Hipótesis!$F$28*(54-1)) -> 3 | BE7: =MIN(Hipótesis!$F$26,Hipótesis!$F$27+Hipótesis!$F$28*(55-1)) -> 3 | BF7: =MIN(Hipótesis!$F$26,Hipótesis!$F$27+Hipótesis!$F$28*(56-1)) -> 3 | BG7: =MIN(Hipótesis!$F$26,Hipótesis!$F$27+Hipótesis!$F$28*(57-1)) -> 3 | BH7: =MIN(Hipótesis!$F$26,Hipótesis!$F$27+Hipótesis!$F$28*(58-1)) -> 3 | BI7: =MIN(Hipótesis!$F$26,Hipótesis!$F$27+Hipótesis!$F$28*(59-1)) -> 3 | BJ7: =MIN(Hipótesis!$F$26,Hipótesis!$F$27+Hipótesis!$F$28*(60-1)) -> 3 | BK7: =MIN(Hipótesis!$F$26,Hipótesis!$F$27+Hipótesis!$F$28*(61-1)) -> 3 | BL7: =MIN(Hipótesis!$F$26,Hipótesis!$F$27+Hipótesis!$F$28*(62-1)) -> 3 | BM7: =MIN(Hipótesis!$F$26,Hipótesis!$F$27+Hipótesis!$F$28*(63-1)) -> 3 | BN7: =MIN(Hipótesis!$F$26,Hipótesis!$F$27+Hipótesis!$F$28*(64-1)) -> 3 | BO7: =MIN(Hipótesis!$F$26,Hipótesis!$F$27+Hipótesis!$F$28*(65-1)) -> 3 | BP7: =MIN(Hipótesis!$F$26,Hipótesis!$F$27+Hipótesis!$F$28*(66-1)) -> 3 | BQ7: =MIN(Hipótesis!$F$26,Hipótesis!$F$27+Hipótesis!$F$28*(67-1)) -> 3 | BR7: =MIN(Hipótesis!$F$26,Hipótesis!$F$27+Hipótesis!$F$28*(68-1)) -> 3 | BS7: =MIN(Hipótesis!$F$26,Hipótesis!$F$27+Hipótesis!$F$28*(69-1)) -> 3 | BT7: =MIN(Hipótesis!$F$26,Hipótesis!$F$27+Hipótesis!$F$28*(70-1)) -> 3 | BU7: =MIN(Hipótesis!$F$26,Hipótesis!$F$27+Hipótesis!$F$28*(71-1)) -> 3 | BV7: =MIN(Hipótesis!$F$26,Hipótesis!$F$27+Hipótesis!$F$28*(72-1)) -> 3 | BW7: =MIN(Hipótesis!$F$26,Hipótesis!$F$27+Hipótesis!$F$28*(73-1)) -> 3 | BX7: =MIN(Hipótesis!$F$26,Hipótesis!$F$27+Hipótesis!$F$28*(74-1)) -> 3 | BY7: =MIN(Hipótesis!$F$26,Hipótesis!$F$27+Hipótesis!$F$28*(75-1)) -> 3 | BZ7: =MIN(Hipótesis!$F$26,Hipótesis!$F$27+Hipótesis!$F$28*(76-1)) -> 3 | CA7: =MIN(Hipótesis!$F$26,Hipótesis!$F$27+Hipótesis!$F$28*(77-1)) -> 3 | CB7: =MIN(Hipótesis!$F$26,Hipótesis!$F$27+Hipótesis!$F$28*(78-1)) -> 3 | CC7: =MIN(Hipótesis!$F$26,Hipótesis!$F$27+Hipótesis!$F$28*(79-1)) -> 3 | CD7: =MIN(Hipótesis!$F$26,Hipótesis!$F$27+Hipótesis!$F$28*(80-1)) -> 3 | CE7: =MIN(Hipótesis!$F$26,Hipótesis!$F$27+Hipótesis!$F$28*(81-1)) -> 3 | CF7: =MIN(Hipótesis!$F$26,Hipótesis!$F$27+Hipótesis!$F$28*(82-1)) -> 3 | CG7: =MIN(Hipótesis!$F$26,Hipótesis!$F$27+Hipótesis!$F$28*(83-1)) -> 3 | CH7: =MIN(Hipótesis!$F$26,Hipótesis!$F$27+Hipótesis!$F$28*(84-1)) -> 3
A8: Posiciones de luz instaladas | C8: =C7*Hipótesis!$D$13 -> 960 | D8: =D7*Hipótesis!$D$13 -> 1440 | E8: =E7*Hipótesis!$D$13 -> 1920 | F8: =F7*Hipótesis!$D$13 -> 2400 | G8: =G7*Hipótesis!$D$13 -> 2880 | H8: =H7*Hipótesis!$D$13 -> 2880 | I8: =I7*Hipótesis!$D$13 -> 2880 | J8: =J7*Hipótesis!$D$13 -> 2880 | ... CH8: =CH7*Hipótesis!$D$13 -> 2880
